Workbook

Sheet About
A1: Active state name: | B1: Iowa | C1: 46266 | F1: state_name | G1: state_abbr
A2: Active state code: | B2: =INDEX($G$2:$G$49,MATCH($B$1,$F$2:$F$49,0)) -> IA | F2: Alabama | G2: AL
F3: Arizona | G3: AZ
A4: BDCL — BAU Data Center Load by state (MWh), 2024–2050 | F4: Arkansas | G4: AR
F5: California | G5: CA
A6: Built: 2026-09-01 by outputs/BDCL/_build_bdcl_workbook.py | F6: Colorado | G6: CO
F7: Connecticut | G7: CT
F8: Delaware | G8: DE
A9: SOURCES | F9: Florida | G9: FL
A10: Trajectories (capacity + national energy): | B10: EPRI (February 2026), "Powering Intelligence 2026: Updated Scenarios of U.S. Data Center Electricity Use and Power Strategies," report 3002034696 (Blanford, Wilson, Bistline, Johnson). https://powering-intelligence.epri.com | F10: Georgia | G10: GA
B11: Table 2 staged verbatim: sources/raw/bdcl/epri_pi2026_state_capacity.csv -> EPRI_PI2026 tab. National energy anchors: 184 TWh (2024, p.15; range 177-192) and 383/596/793 TWh (2030 L/M/H, p.17). Beyond-2030 method: fn.19 p.21. Estimates INCLUDE cryptocurrency mining. | F11: Idaho | G11: ID
A12: 2023 DC magnitude (classification only): | B12: EPRI (May 2024), "Powering Intelligence: Analyzing Artificial Intelligence and Data Center Energy Consumption," report 3002028905 — per-state 2023 data-center load (MWh, % of state). https://www.epri.com/research/products/3002028905 | F12: Illinois | G12: IL
A13: Sector classification sales data: | B13: EIA-861 Annual Electric Power Industry Report, Sales to Ultimate Customers, 2018 & 2023 (Bundled + Energy service). https://www.eia.gov/electricity/data/eia861/ (staged: sources/raw/eia861/) | F13: Indiana | G13: IN
A14: Geography: | B14: config/geography/state_to_census_division.csv (48 contiguous states) | F14: Iowa | G14: IA
F15: Kansas | G15: KS
A16: OUTPUTS | F16: Kentucky | G16: KY
A17: BDCL-low / BDCL-mid / BDCL-high: | B17: active-state annual electricity (MWh) 2024-2050; the per-state EPS InputData BDCL CSVs are exported from these tabs. | F17: Louisiana | G17: LA
A18: Consumers: | B18: EPS BDCL input; start-year netting in BCEU commercial (Calcs STEP 7b) and BIFUbC industrial (STEP 12b-DC) via sources/raw/bdcl/bdcl_mid_by_state.csv (regenerate from the MED scenario after any change here). | F18: Maine | G18: ME
F19: Maryland | G19: MD
A20: Methodology: see the Methodology tab and docs/methodology/BDCL.md (§4b-ii). | F20: Massachusetts | G20: MA
A21: Scope: 48 contiguous states. West Virginia has no EPRI-reported data centers -> 0. | F21: Michigan | G21: MI
A22: Status: inputs for staff review — verify against primary sources before external use. | F22: Minnesota | G22: MN
F23: Mississippi | G23: MS
F24: Missouri | G24: MO
F25: Montana | G25: MT
F26: Nebraska | G26: NE
F27: Nevada | G27: NV
F28: New Hampshire | G28: NH
F29: New Jersey | G29: NJ
F30: New Mexico | G30: NM
F31: New York | G31: NY
F32: North Carolina | G32: NC
F33: North Dakota | G33: ND
F34: Ohio | G34: OH
... F49: Wyoming | G49: WY

Sheet Methodology
A1: Methodology
A3: BDCL = business-as-usual data-center electricity load by state and year (MWh), 2024-2050, three scenarios.
A5: 1. SINGLE 2024 BASE (staff decision 2026-07-31). 2024 is historical: all three scenarios share the EPRI
A6: PI-2026 Medium 2024 state capacity (Table 2). The published 2024 Low/High columns reflect variation
A7: across EPRI's data sources, not scenario divergence; they are retained on the raw tab but unused.
A8: Scenarios diverge from 2025 toward their published 2030 endpoints.
A9: 2. CAPACITY PATHS (Calcs STEP 2). Per state and scenario: geometric interpolation from the shared 2024
A10: base to the scenario 2030 endpoint; the implied 2025-2030 annual growth rate then declines by the
A11: Keys decay factor (4) each subsequent 5-year period through 2050 — EPRI's own extension (fn.19 p.21).
A12: 3. NATIONAL ENERGY (Calcs STEP 3). Anchored at 184e6 MWh in 2024 (all scenarios) and the published
A13: 383/596/793e6 MWh in 2030 (L/M/H); interpolated and extended by the same method. EPRI's energy
A14: estimates embed their PUE (1.32 in 2024, declining), 20%/yr capacity ramp, and observed load factors.
... A28: inputs for staff review; verify against the primary sources cited on About before external use.

Sheet Keys
A1: category | B1: key | C1: value | D1: description
A2: energy | B2: e2024_mwh | C2: 184000000 | D2: National DC energy 2024, ALL scenarios (EPRI PI-2026 p.15; central of 177-192 TWh)
A3: energy | B3: e2030_low_mwh | C3: 383000000 | D3: National DC energy 2030, Low (published, p.17)
A4: energy | B4: e2030_med_mwh | C4: 596000000 | D4: National DC energy 2030, Medium (published, p.17)
A5: energy | B5: e2030_high_mwh | C5: 793000000 | D5: National DC energy 2030, High (published, p.17)
A6: method | B6: interp_end_year | C6: 2030 | D6: Last year of the published-endpoint interpolation window (2024->2030)
A7: method | B7: decay_factor | C7: 4 | D7: EPRI fn.19: annual growth rate divides by this each period after interp_end_year
A8: method | B8: decay_period_years | C8: 5 | D8: Length of each post-2030 decay period (years)
A9: class | B9: decisiveness_ratio | C9: 1.3 | D9: DC_classification: industrial growth must exceed this x commercial growth
A10: class | B10: materiality_gate_pct | C10: 0.05 | D10: DC_classification: DC materiality gate, share of state electricity (2023)
A11: class | B11: materiality_gate_gwh | C11: 1000 | D11: DC_classification: DC materiality gate, absolute (GWh, 2023)

Sheet EPRI_PI2026
A1: state | B1: cap_2021_mw | C1: cap_2022_mw | D1: cap_2023_mw | E1: cap_2024_low_mw | F1: cap_2024_med_mw | G1: cap_2024_high_mw | H1: cap_2030_low_mw | I1: cap_2030_med_mw | J1: cap_2030_high_mw
A2: AL | B2: 17 | C2: 167 | D2: 170 | E2: 315 | F2: 353 | G2: 390 | H2: 454 | I2: 780 | J2: 981
A3: AK | B3: 0 | C3: 0 | D3: 0 | E3: 0 | F3: 0 | G3: 0 | H3: 0 | I3: 0 | J3: 0
A4: AR | B4: 0 | C4: 0 | D4: 0 | E4: 8 | F4: 11 | G4: 14 | H4: 8 | I4: 11 | J4: 14
A5: AZ | B5: 472 | C5: 652 | D5: 740 | E5: 1657 | F5: 1864 | G5: 2072 | H5: 2537 | I5: 3853 | J5: 5288
A6: CA | B6: 935 | C6: 1064 | D6: 1227 | E6: 1280 | F6: 1496 | G6: 1712 | H6: 1489 | I6: 2296 | J6: 3225
A7: CO | B7: 92 | C7: 248 | D7: 258 | E7: 170 | F7: 241 | G7: 313 | H7: 333 | I7: 404 | J7: 503
A8: CT | B8: 29 | C8: 30 | D8: 30 | E8: 28 | F8: 29 | G8: 30 | H8: 162 | I8: 243 | J8: 355
A9: DE | B9: 0 | C9: 0 | D9: 0 | E9: 10 | F9: 14 | G9: 17 | H9: 10 | I9: 14 | J9: 17
A10: FL | B10: 80 | C10: 97 | D10: 158 | E10: 184 | F10: 188 | G10: 193 | H10: 342 | I10: 524 | J10: 643
A11: GA | B11: 297 | C11: 789 | D11: 1174 | E11: 1505 | F11: 1774 | G11: 2043 | H11: 3014 | I11: 5358 | J11: 7466
A12: HI | B12: 1 | C12: 1 | D12: 1 | E12: 7 | F12: 8 | G12: 9 | H12: 7 | I12: 9 | J12: 10
A13: ID | B13: 15 | C13: 17 | D13: 17 | E13: 69 | F13: 89 | G13: 109 | H13: 290 | I13: 554 | J13: 689
... A51: US_TOTAL | B51: 10967 | C51: 16537 | D51: 25547 | E51: 35074 | F51: 39774 | G51: 44473 | H51: 56057 | I51: 95862 | J51: 132499
A53: Source: EPRI (February 2026), "Powering Intelligence 2026: Updated Scenarios of U.S. Data Center Electricity Use and Power Strategies," report 3002034696 (Blanford, Wilson, Bistline, Johnson). https://powering-intelligence.epri.com — Table 2, state nominal IT capacity (MW), verbatim; includes small- and large-scale DC and cryptocurrency mining. Transcription notes: IA 2024-High prints "1.866" in the PDF (= 1,866; confirmed by the column sum matching the printed U.S. total exactly); the printed 2023 column is internally inconsistent in the PDF (state cells sum 24,881 vs printed total 25,547; 2021/2022 match exactly) — 2023 is historical context only, not a calculation input. The 2024 LOW/HIGH columns reflect variation across EPRI's data sources and are NOT calculation inputs (single 2024 base = MEDIUM column; see Methodology).

Sheet EPRI_DC_2023
A1: state_name | B1: dc_mwh_2023 | C1: dc_pct_2023
A2: Alabama | B2: 1489200 | C2: 0.0171
A3: Arizona | B3: 6253280 | C3: 0.0743
A4: California | B4: 9313619 | C4: 0.037
A5: Colorado | B5: 1509640 | C5: 0.0266
A6: Connecticut | B6: 262800 | C6: 0.0095
A7: Florida | B7: 1384080 | C7: 0.0056
A8: Georgia | B8: 6175391 | C8: 0.0426
A9: Hawaii | B9: 8760 | C9: 0.0086
A10: Idaho | B10: 148920 | C10: 0.0057
A11: Illinois | B11: 7450176 | C11: 0.0548
A12: Indiana | B12: 192720 | C12: 0.0019
A13: Iowa | B13: 6193320 | C13: 0.1143
... A45: Wyoming | B45: 1857120 | C45: 0.1126
A47: Source: EPRI (May 2024), "Powering Intelligence: Analyzing Artificial Intelligence and Data Center Energy Consumption," report 3002028905 — per-state 2023 data-center load (MWh, % of state). https://www.epri.com/research/products/3002028905 — verbatim from sources/raw/bdcl/epri_dc_by_state_2023.csv. Used ONLY by DC_classification (2023 materiality) and as the historical reference the pre-2026-07-31 BDCL levels were built on. States absent (AR, DE, MS, VT, WV) have no EPRI-reported DC load.

Sheet EIA861_sales
A1: EIA-861 Annual Electric Power Industry Report, Sales to Ultimate Customers, 2018 & 2023 (Bundled + Energy service). https://www.eia.gov/electricity/data/eia861/ (staged: sources/raw/eia861/) — MWh aggregated to GWh by state and sector.
A3: state_abbr | B3: state_name | C3: comm_2018_GWh | D3: comm_2023_GWh | E3: ind_2018_GWh | F3: ind_2023_GWh
A4: AL | B4: Alabama | C4: 23483.1 | D4: 22213.5 | E4: 33717 | F4: 31257.2
A5: AZ | B5: Arizona | C5: 29683.5 | D5: 32619.7 | E5: 13637.7 | F5: 13920.4
A6: AR | B6: Arkansas | C6: 12278.3 | D6: 11694.1 | E6: 18064.8 | F6: 18581
A7: CA | B7: California | C7: 115786.5 | D7: 112935.6 | E7: 49491.4 | F7: 42998.6
A8: CO | B8: Colorado | C8: 21023.3 | D8: 20697.7 | E8: 16047.3 | F8: 14778.8
A9: CT | B9: Connecticut | C9: 12381.1 | D9: 11373.6 | E9: 3210 | F9: 2579.4
A10: DE | B10: Delaware | C10: 4342.3 | D10: 4148.5 | E10: 2360.6 | F10: 1440.3
A11: FL | B11: Florida | C11: 96265.3 | D11: 97255.4 | E11: 16689.1 | F11: 17808.6
A12: GA | B12: Georgia | C12: 47311.7 | D12: 51404.7 | E12: 32695.8 | F12: 32067.5
A13: ID | B13: Idaho | C13: 6436.9 | D13: 6842.1 | E13: 8889 | F13: 9038.6
A14: IL | B14: Illinois | C14: 50762.8 | D14: 45576.3 | E14: 44114.7 | F14: 41267.4
A15: IN | B15: Indiana | C15: 24305.2 | D15: 23016.4 | E15: 42775.4 | F15: 38807.9
... A51: WY | B51: Wyoming | C51: 3757.2 | D51: 5045.9 | E51: 10359.1 | F51: 8796.3

Sheet DC_classification
A1: Data-center sector classification (commercial vs industrial), by state
A2: Data centers are booked to whichever customer class the SERVING UTILITY uses, so SEDS/EIA-861 places DC load in COMMERCIAL (e.g. VA) or INDUSTRIAL (e.g. IA) depending on the state. This table classifies each state so the DC demand adjustment is routed to the matching sector. Rule (thresholds on Keys): INDUSTRIAL only where DC load is material (>= materiality gates, 2023) AND 2018-2023 industrial retail-sales growth is decisively larger (> decisiveness_ratio x) than commercial; every other state is COMMERCIAL (the EIA/CBECS default). The confidence column flags weak growth signals for manual review. Growth cannot isolate DC in restructured / declining-demand states (CA, IL, NY, NJ) or where non-DC industrial growth dominates (TX petrochem); verify those against utility customer-class filings. Inputs for staff review.
A6: state_name | B6: state_abbr | C6: DC_GWh_2023 | D6: DC_%_of_state | E6: comm_growth_18-23_GWh | F6: ind_growth_18-23_GWh | G6: classification | H6: confidence
A7: Alabama | B7: AL | C7: =IFERROR(INDEX(EPRI_DC_2023!$B$2:$B$45,MATCH($A7,EPRI_DC_2023!$A$2:$A$45,0))/1000,0) -> 1489.2 | D7: =IFERROR(INDEX(EPRI_DC_2023!$C$2:$C$45,MATCH($A7,EPRI_DC_2023!$A$2:$A$45,0)),0) -> 0.0171 | E7: =IFERROR(INDEX(EIA861_sales!$D$4:$D$51,MATCH($B7,EIA861_sales!$A$4:$A$51,0))-INDEX(EIA861_sales!$C$4:$C$51,MATCH($B7,EIA861_sales!$A$4:$A$51,0)),"") -> -1269.6 | F7: =IFERROR(INDEX(EIA861_sales!$F$4:$F$51,MATCH($B7,EIA861_sales!$A$4:$A$51,0))-INDEX(EIA861_sales!$E$4:$E$51,MATCH($B7,EIA861_sales!$A$4:$A$51,0)),"") -> -2459.8 | G7: =IFERROR(IF(AND(OR(D7>=Keys!$C$10,C7>=Keys!$C$11),AND(F7>0,F7>Keys!$C$9*E7)),"industrial","commercial"),"commercial") -> commercial | H7: =IF(ISNA(MATCH($A7,EPRI_DC_2023!$A$2:$A$45,0)),"n/a - missing DC data",IFERROR(IF(NOT(OR(D7>=Keys!$C$10,C7>=Keys!$C$11)),"n/a - immaterial",IF(OR(AND(E7>0,E7>Keys!$C$9*F7),AND(F7>0,F7>Keys!$C$9*E7)),"high","LOW - verify")),"n/a - missing DC data")) -> LOW - verify
A8: Arizona | B8: AZ | C8: =IFERROR(INDEX(EPRI_DC_2023!$B$2:$B$45,MATCH($A8,EPRI_DC_2023!$A$2:$A$45,0))/1000,0) -> 6253.28 | D8: =IFERROR(INDEX(EPRI_DC_2023!$C$2:$C$45,MATCH($A8,EPRI_DC_2023!$A$2:$A$45,0)),0) -> 0.0743 | E8: =IFERROR(INDEX(EIA861_sales!$D$4:$D$51,MATCH($B8,EIA861_sales!$A$4:$A$51,0))-INDEX(EIA861_sales!$C$4:$C$51,MATCH($B8,EIA861_sales!$A$4:$A$51,0)),"") -> 2936.2 | F8: =IFERROR(INDEX(EIA861_sales!$F$4:$F$51,MATCH($B8,EIA861_sales!$A$4:$A$51,0))-INDEX(EIA861_sales!$E$4:$E$51,MATCH($B8,EIA861_sales!$A$4:$A$51,0)),"") -> 282.7 | G8: =IFERROR(IF(AND(OR(D8>=Keys!$C$10,C8>=Keys!$C$11),AND(F8>0,F8>Keys!$C$9*E8)),"industrial","commercial"),"commercial") -> commercial | H8: =IF(ISNA(MATCH($A8,EPRI_DC_2023!$A$2:$A$45,0)),"n/a - missing DC data",IFERROR(IF(NOT(OR(D8>=Keys!$C$10,C8>=Keys!$C$11)),"n/a - immaterial",IF(OR(AND(E8>0,E8>Keys!$C$9*F8),AND(F8>0,F8>Keys!$C$9*E8)),"high","LOW - verify")),"n/a - missing DC data")) -> high
A9: Arkansas | B9: AR | C9: =IFERROR(INDEX(EPRI_DC_2023!$B$2:$B$45,MATCH($A9,EPRI_DC_2023!$A$2:$A$45,0))/1000,0) -> 0 | D9: =IFERROR(INDEX(EPRI_DC_2023!$C$2:$C$45,MATCH($A9,EPRI_DC_2023!$A$2:$A$45,0)),0) -> 0 | E9: =IFERROR(INDEX(EIA861_sales!$D$4:$D$51,MATCH($B9,EIA861_sales!$A$4:$A$51,0))-INDEX(EIA861_sales!$C$4:$C$51,MATCH($B9,EIA861_sales!$A$4:$A$51,0)),"") -> -584.2 | F9: =IFERROR(INDEX(EIA861_sales!$F$4:$F$51,MATCH($B9,EIA861_sales!$A$4:$A$51,0))-INDEX(EIA861_sales!$E$4:$E$51,MATCH($B9,EIA861_sales!$A$4:$A$51,0)),"") -> 516.2 | G9: =IFERROR(IF(AND(OR(D9>=Keys!$C$10,C9>=Keys!$C$11),AND(F9>0,F9>Keys!$C$9*E9)),"industrial","commercial"),"commercial") -> commercial | H9: =IF(ISNA(MATCH($A9,EPRI_DC_2023!$A$2:$A$45,0)),"n/a - missing DC data",IFERROR(IF(NOT(OR(D9>=Keys!$C$10,C9>=Keys!$C$11)),"n/a - immaterial",IF(OR(AND(E9>0,E9>Keys!$C$9*F9),AND(F9>0,F9>Keys!$C$9*E9)),"high","LOW - verify")),"n/a - missing DC data")) -> n/a - missing DC data
A10: California | B10: CA | C10: =IFERROR(INDEX(EPRI_DC_2023!$B$2:$B$45,MATCH($A10,EPRI_DC_2023!$A$2:$A$45,0))/1000,0) -> 9313.619 | D10: =IFERROR(INDEX(EPRI_DC_2023!$C$2:$C$45,MATCH($A10,EPRI_DC_2023!$A$2:$A$45,0)),0) -> 0.037 | E10: =IFERROR(INDEX(EIA861_sales!$D$4:$D$51,MATCH($B10,EIA861_sales!$A$4:$A$51,0))-INDEX(EIA861_sales!$C$4:$C$51,MATCH($B10,EIA861_sales!$A$4:$A$51,0)),"") -> -2850.9 | F10: =IFERROR(INDEX(EIA861_sales!$F$4:$F$51,MATCH($B10,EIA861_sales!$A$4:$A$51,0))-INDEX(EIA861_sales!$E$4:$E$51,MATCH($B10,EIA861_sales!$A$4:$A$51,0)),"") -> -6492.8 | G10: =IFERROR(IF(AND(OR(D10>=Keys!$C$10,C10>=Keys!$C$11),AND(F10>0,F10>Keys!$C$9*E10)),"industrial","commercial"),"commercial") -> commercial | H10: =IF(ISNA(MATCH($A10,EPRI_DC_2023!$A$2:$A$45,0)),"n/a - missing DC data",IFERROR(IF(NOT(OR(D10>=Keys!$C$10,C10>=Keys!$C$11)),"n/a - immaterial",IF(OR(AND(E10>0,E10>Keys!$C$9*F10),AND(F10>0,F10>Keys!$C$9*E10)),"high","LOW - verify")),"n/a - missing DC data")) -> LOW - verify
A11: Colorado | B11: CO | C11: =IFERROR(INDEX(EPRI_DC_2023!$B$2:$B$45,MATCH($A11,EPRI_DC_2023!$A$2:$A$45,0))/1000,0) -> 1509.64 | D11: =IFERROR(INDEX(EPRI_DC_2023!$C$2:$C$45,MATCH($A11,EPRI_DC_2023!$A$2:$A$45,0)),0) -> 0.0266 | E11: =IFERROR(INDEX(EIA861_sales!$D$4:$D$51,MATCH($B11,EIA861_sales!$A$4:$A$51,0))-INDEX(EIA861_sales!$C$4:$C$51,MATCH($B11,EIA861_sales!$A$4:$A$51,0)),"") -> -325.6 | F11: =IFERROR(INDEX(EIA861_sales!$F$4:$F$51,MATCH($B11,EIA861_sales!$A$4:$A$51,0))-INDEX(EIA861_sales!$E$4:$E$51,MATCH($B11,EIA861_sales!$A$4:$A$51,0)),"") -> -1268.5 | G11: =IFERROR(IF(AND(OR(D11>=Keys!$C$10,C11>=Keys!$C$11),AND(F11>0,F11>Keys!$C$9*E11)),"industrial","commercial"),"commercial") -> commercial | H11: =IF(ISNA(MATCH($A11,EPRI_DC_2023!$A$2:$A$45,0)),"n/a - missing DC data",IFERROR(IF(NOT(OR(D11>=Keys!$C$10,C11>=Keys!$C$11)),"n/a - immaterial",IF(OR(AND(E11>0,E11>Keys!$C$9*F11),AND(F11>0,F11>Keys!$C$9*E11)),"high","LOW - verify")),"n/a - missing DC data")) -> LOW - verify
A12: Connecticut | B12: CT | C12: =IFERROR(INDEX(EPRI_DC_2023!$B$2:$B$45,MATCH($A12,EPRI_DC_2023!$A$2:$A$45,0))/1000,0) -> 262.8 | D12: =IFERROR(INDEX(EPRI_DC_2023!$C$2:$C$45,MATCH($A12,EPRI_DC_2023!$A$2:$A$45,0)),0) -> 0.0095 | E12: =IFERROR(INDEX(EIA861_sales!$D$4:$D$51,MATCH($B12,EIA861_sales!$A$4:$A$51,0))-INDEX(EIA861_sales!$C$4:$C$51,MATCH($B12,EIA861_sales!$A$4:$A$51,0)),"") -> -1007.5 | F12: =IFERROR(INDEX(EIA861_sales!$F$4:$F$51,MATCH($B12,EIA861_sales!$A$4:$A$51,0))-INDEX(EIA861_sales!$E$4:$E$51,MATCH($B12,EIA861_sales!$A$4:$A$51,0)),"") -> -630.6 | G12: =IFERROR(IF(AND(OR(D12>=Keys!$C$10,C12>=Keys!$C$11),AND(F12>0,F12>Keys!$C$9*E12)),"industrial","commercial"),"commercial") -> commercial | H12: =IF(ISNA(MATCH($A12,EPRI_DC_2023!$A$2:$A$45,0)),"n/a - missing DC data",IFERROR(IF(NOT(OR(D12>=Keys!$C$10,C12>=Keys!$C$11)),"n/a - immaterial",IF(OR(AND(E12>0,E12>Keys!$C$9*F12),AND(F12>0,F12>Keys!$C$9*E12)),"high","LOW - verify")),"n/a - missing DC data")) -> n/a - immaterial
A13: Delaware | B13: DE | C13: =IFERROR(INDEX(EPRI_DC_2023!$B$2:$B$45,MATCH($A13,EPRI_DC_2023!$A$2:$A$45,0))/1000,0) -> 0 | D13: =IFERROR(INDEX(EPRI_DC_2023!$C$2:$C$45,MATCH($A13,EPRI_DC_2023!$A$2:$A$45,0)),0) -> 0 | E13: =IFERROR(INDEX(EIA861_sales!$D$4:$D$51,MATCH($B13,EIA861_sales!$A$4:$A$51,0))-INDEX(EIA861_sales!$C$4:$C$51,MATCH($B13,EIA861_sales!$A$4:$A$51,0)),"") -> -193.8 | F13: =IFERROR(INDEX(EIA861_sales!$F$4:$F$51,MATCH($B13,EIA861_sales!$A$4:$A$51,0))-INDEX(EIA861_sales!$E$4:$E$51,MATCH($B13,EIA861_sales!$A$4:$A$51,0)),"") -> -920.3 | G13: =IFERROR(IF(AND(OR(D13>=Keys!$C$10,C13>=Keys!$C$11),AND(F13>0,F13>Keys!$C$9*E13)),"industrial","commercial"),"commercial") -> commercial | H13: =IF(ISNA(MATCH($A13,EPRI_DC_2023!$A$2:$A$45,0)),"n/a - missing DC data",IFERROR(IF(NOT(OR(D13>=Keys!$C$10,C13>=Keys!$C$11)),"n/a - immaterial",IF(OR(AND(E13>0,E13>Keys!$C$9*F13),AND(F13>0,F13>Keys!$C$9*E13)),"high","LOW - verify")),"n/a - missing DC data")) -> n/a - missing DC data
A14: Florida | B14: FL | C14: =IFERROR(INDEX(EPRI_DC_2023!$B$2:$B$45,MATCH($A14,EPRI_DC_2023!$A$2:$A$45,0))/1000,0) -> 1384.08 | D14: =IFERROR(INDEX(EPRI_DC_2023!$C$2:$C$45,MATCH($A14,EPRI_DC_2023!$A$2:$A$45,0)),0) -> 0.0056 | E14: =IFERROR(INDEX(EIA861_sales!$D$4:$D$51,MATCH($B14,EIA861_sales!$A$4:$A$51,0))-INDEX(EIA861_sales!$C$4:$C$51,MATCH($B14,EIA861_sales!$A$4:$A$51,0)),"") -> 990.1 | F14: =IFERROR(INDEX(EIA861_sales!$F$4:$F$51,MATCH($B14,EIA861_sales!$A$4:$A$51,0))-INDEX(EIA861_sales!$E$4:$E$51,MATCH($B14,EIA861_sales!$A$4:$A$51,0)),"") -> 1119.5 | G14: =IFERROR(IF(AND(OR(D14>=Keys!$C$10,C14>=Keys!$C$11),AND(F14>0,F14>Keys!$C$9*E14)),"industrial","commercial"),"commercial") -> commercial | H14: =IF(ISNA(MATCH($A14,EPRI_DC_2023!$A$2:$A$45,0)),"n/a - missing DC data",IFERROR(IF(NOT(OR(D14>=Keys!$C$10,C14>=Keys!$C$11)),"n/a - immaterial",IF(OR(AND(E14>0,E14>Keys!$C$9*F14),AND(F14>0,F14>Keys!$C$9*E14)),"high","LOW - verify")),"n/a - missing DC data")) -> LOW - verify
A15: Georgia | B15: GA | C15: =IFERROR(INDEX(EPRI_DC_2023!$B$2:$B$45,MATCH($A15,EPRI_DC_2023!$A$2:$A$45,0))/1000,0) -> 6175.391 | D15: =IFERROR(INDEX(EPRI_DC_2023!$C$2:$C$45,MATCH($A15,EPRI_DC_2023!$A$2:$A$45,0)),0) -> 0.0426 | E15: =IFERROR(INDEX(EIA861_sales!$D$4:$D$51,MATCH($B15,EIA861_sales!$A$4:$A$51,0))-INDEX(EIA861_sales!$C$4:$C$51,MATCH($B15,EIA861_sales!$A$4:$A$51,0)),"") -> 4093 | F15: =IFERROR(INDEX(EIA861_sales!$F$4:$F$51,MATCH($B15,EIA861_sales!$A$4:$A$51,0))-INDEX(EIA861_sales!$E$4:$E$51,MATCH($B15,EIA861_sales!$A$4:$A$51,0)),"") -> -628.3 | G15: =IFERROR(IF(AND(OR(D15>=Keys!$C$10,C15>=Keys!$C$11),AND(F15>0,F15>Keys!$C$9*E15)),"industrial","commercial"),"commercial") -> commercial | H15: =IF(ISNA(MATCH($A15,EPRI_DC_2023!$A$2:$A$45,0)),"n/a - missing DC data",IFERROR(IF(NOT(OR(D15>=Keys!$C$10,C15>=Keys!$C$11)),"n/a - immaterial",IF(OR(AND(E15>0,E15>Keys!$C$9*F15),AND(F15>0,F15>Keys!$C$9*E15)),"high","LOW - verify")),"n/a - missing DC data")) -> high
A16: Idaho | B16: ID | C16: =IFERROR(INDEX(EPRI_DC_2023!$B$2:$B$45,MATCH($A16,EPRI_DC_2023!$A$2:$A$45,0))/1000,0) -> 148.92 | D16: =IFERROR(INDEX(EPRI_DC_2023!$C$2:$C$45,MATCH($A16,EPRI_DC_2023!$A$2:$A$45,0)),0) -> 0.0057 | E16: =IFERROR(INDEX(EIA861_sales!$D$4:$D$51,MATCH($B16,EIA861_sales!$A$4:$A$51,0))-INDEX(EIA861_sales!$C$4:$C$51,MATCH($B16,EIA861_sales!$A$4:$A$51,0)),"") -> 405.2 | F16: =IFERROR(INDEX(EIA861_sales!$F$4:$F$51,MATCH($B16,EIA861_sales!$A$4:$A$51,0))-INDEX(EIA861_sales!$E$4:$E$51,MATCH($B16,EIA861_sales!$A$4:$A$51,0)),"") -> 149.6 | G16: =IFERROR(IF(AND(OR(D16>=Keys!$C$10,C16>=Keys!$C$11),AND(F16>0,F16>Keys!$C$9*E16)),"industrial","commercial"),"commercial") -> commercial | H16: =IF(ISNA(MATCH($A16,EPRI_DC_2023!$A$2:$A$45,0)),"n/a - missing DC data",IFERROR(IF(NOT(OR(D16>=Keys!$C$10,C16>=Keys!$C$11)),"n/a - immaterial",IF(OR(AND(E16>0,E16>Keys!$C$9*F16),AND(F16>0,F16>Keys!$C$9*E16)),"high","LOW - verify")),"n/a - missing DC data")) -> n/a - immaterial
A17: Illinois | B17: IL | C17: =IFERROR(INDEX(EPRI_DC_2023!$B$2:$B$45,MATCH($A17,EPRI_DC_2023!$A$2:$A$45,0))/1000,0) -> 7450.176 | D17: =IFERROR(INDEX(EPRI_DC_2023!$C$2:$C$45,MATCH($A17,EPRI_DC_2023!$A$2:$A$45,0)),0) -> 0.0548 | E17: =IFERROR(INDEX(EIA861_sales!$D$4:$D$51,MATCH($B17,EIA861_sales!$A$4:$A$51,0))-INDEX(EIA861_sales!$C$4:$C$51,MATCH($B17,EIA861_sales!$A$4:$A$51,0)),"") -> -5186.5 | F17: =IFERROR(INDEX(EIA861_sales!$F$4:$F$51,MATCH($B17,EIA861_sales!$A$4:$A$51,0))-INDEX(EIA861_sales!$E$4:$E$51,MATCH($B17,EIA861_sales!$A$4:$A$51,0)),"") -> -2847.3 | G17: =IFERROR(IF(AND(OR(D17>=Keys!$C$10,C17>=Keys!$C$11),AND(F17>0,F17>Keys!$C$9*E17)),"industrial","commercial"),"commercial") -> commercial | H17: =IF(ISNA(MATCH($A17,EPRI_DC_2023!$A$2:$A$45,0)),"n/a - missing DC data",IFERROR(IF(NOT(OR(D17>=Keys!$C$10,C17>=Keys!$C$11)),"n/a - immaterial",IF(OR(AND(E17>0,E17>Keys!$C$9*F17),AND(F17>0,F17>Keys!$C$9*E17)),"high","LOW - verify")),"n/a - missing DC data")) -> LOW - verify
A18: Indiana | B18: IN | C18: =IFERROR(INDEX(EPRI_DC_2023!$B$2:$B$45,MATCH($A18,EPRI_DC_2023!$A$2:$A$45,0))/1000,0) -> 192.72 | D18: =IFERROR(INDEX(EPRI_DC_2023!$C$2:$C$45,MATCH($A18,EPRI_DC_2023!$A$2:$A$45,0)),0) -> 0.0019 | E18: =IFERROR(INDEX(EIA861_sales!$D$4:$D$51,MATCH($B18,EIA861_sales!$A$4:$A$51,0))-INDEX(EIA861_sales!$C$4:$C$51,MATCH($B18,EIA861_sales!$A$4:$A$51,0)),"") -> -1288.8 | F18: =IFERROR(INDEX(EIA861_sales!$F$4:$F$51,MATCH($B18,EIA861_sales!$A$4:$A$51,0))-INDEX(EIA861_sales!$E$4:$E$51,MATCH($B18,EIA861_sales!$A$4:$A$51,0)),"") -> -3967.5 | G18: =IFERROR(IF(AND(OR(D18>=Keys!$C$10,C18>=Keys!$C$11),AND(F18>0,F18>Keys!$C$9*E18)),"industrial","commercial"),"commercial") -> commercial | H18: =IF(ISNA(MATCH($A18,EPRI_DC_2023!$A$2:$A$45,0)),"n/a - missing DC data",IFERROR(IF(NOT(OR(D18>=Keys!$C$10,C18>=Keys!$C$11)),"n/a - immaterial",IF(OR(AND(E18>0,E18>Keys!$C$9*F18),AND(F18>0,F18>Keys!$C$9*E18)),"high","LOW - verify")),"n/a - missing DC data")) -> n/a - immaterial
... A54: Wyoming | B54: WY | C54: =IFERROR(INDEX(EPRI_DC_2023!$B$2:$B$45,MATCH($A54,EPRI_DC_2023!$A$2:$A$45,0))/1000,0) -> 1857.12 | D54: =IFERROR(INDEX(EPRI_DC_2023!$C$2:$C$45,MATCH($A54,EPRI_DC_2023!$A$2:$A$45,0)),0) -> 0.1126 | E54: =IFERROR(INDEX(EIA861_sales!$D$4:$D$51,MATCH($B54,EIA861_sales!$A$4:$A$51,0))-INDEX(EIA861_sales!$C$4:$C$51,MATCH($B54,EIA861_sales!$A$4:$A$51,0)),"") -> 1288.7 | F54: =IFERROR(INDEX(EIA861_sales!$F$4:$F$51,MATCH($B54,EIA861_sales!$A$4:$A$51,0))-INDEX(EIA861_sales!$E$4:$E$51,MATCH($B54,EIA861_sales!$A$4:$A$51,0)),"") -> -1562.8 | G54: =IFERROR(IF(AND(OR(D54>=Keys!$C$10,C54>=Keys!$C$11),AND(F54>0,F54>Keys!$C$9*E54)),"industrial","commercial"),"commercial") -> commercial | H54: =IF(ISNA(MATCH($A54,EPRI_DC_2023!$A$2:$A$45,0)),"n/a - missing DC data",IFERROR(IF(NOT(OR(D54>=Keys!$C$10,C54>=Keys!$C$11)),"n/a - immaterial",IF(OR(AND(E54>0,E54>Keys!$C$9*F54),AND(F54>0,F54>Keys!$C$9*E54)),"high","LOW - verify")),"n/a - missing DC data")) -> high

Sheet State Policies
A1: Policy | B1: State | C1: Year Enacted | D1: Updated policy notes | E1: Data Center Growth Limitation | F1: State Abbreviation | G1: Policy Status | H1: Description | I1: category | J1: latest policy link | K1: latest policy name | L1: latest policy year | M1: eps file name short | N1: eps file name long | O1: eps file notes | P1: new state policy | Q1: policy type previously modeled | R1: new cxc policy type | S1: downscaled policy | T1: update action
A2: Data Center Bans and Moratoriums | B2: New York | C2: 2026 | D2: Data center state permit moratorium for maximum 1 year following executive order. Data centers are operational ~2 years post permit -> data center growth = 0 for the year 2028 | E2: 0% 2028 | F2: NY | G2: enacted | H2: Executive Order No. 62 establishes a one-year statewide moratorium on discretionary permits for new hyperscale data centers while the state develops environmental review standards (a Generic Environmental Impact Statement) and a Community Investment Framework. | I2: Buildings & Efficiency | J2: https://www.governor.ny.gov/news/first-statewide-moratorium-new-hyperscale-data-centers-launched-governor-kathy-hochul | K2: Executive Order No. 62: Temporary Moratorium on New Hyperscale Data Centers | L2: 2026 | M2: BDCL | N2: BAU Data Center Load | O2: Not tracked by CXC | P2: Y | Q2: Y | R2: Y | S2: N | T2: possible action, new policy type

Sheet State Calculations
B1: =About!B1 -> Iowa
B2: =About!B2 -> IA
B4: 2024 | C4: 2025 | D4: 2026 | E4: 2027 | F4: 2028 | G4: 2029 | H4: 2030 | I4: 2031 | J4: 2032 | K4: 2033 | L4: 2034 | M4: 2035 | N4: 2036 | O4: 2037 | P4: 2038 | Q4: 2039 | R4: 2040 | S4: 2041 | T4: 2042 | U4: 2043 | V4: 2044 | W4: 2045 | X4: 2046 | Y4: 2047 | Z4: 2048 | AA4: 2049 | AB4: 2050
A5: Policy Growth Rate | B5: =IFERROR(IF(VALUE(INDEX($F$8:$F$100,MATCH($B$2,$C$8:$C$100,0)))=B4,INDEX($E$8:$E$100,MATCH($B$2,$C$8:$C$100,0)),IFERROR(IF(VALUE(INDEX($I$8:$I$100,MATCH($B$2,$C$8:$C$100,0)))=B4,INDEX($H$8:$H$100,MATCH($B$2,$C$8:$C$100,0)),""),"")),"") | C5: =IFERROR(IF(VALUE(INDEX($F$8:$F$100,MATCH($B$2,$C$8:$C$100,0)))=C4,INDEX($E$8:$E$100,MATCH($B$2,$C$8:$C$100,0)),IFERROR(IF(VALUE(INDEX($I$8:$I$100,MATCH($B$2,$C$8:$C$100,0)))=C4,INDEX($H$8:$H$100,MATCH($B$2,$C$8:$C$100,0)),""),"")),"") | D5: =IFERROR(IF(VALUE(INDEX($F$8:$F$100,MATCH($B$2,$C$8:$C$100,0)))=D4,INDEX($E$8:$E$100,MATCH($B$2,$C$8:$C$100,0)),IFERROR(IF(VALUE(INDEX($I$8:$I$100,MATCH($B$2,$C$8:$C$100,0)))=D4,INDEX($H$8:$H$100,MATCH($B$2,$C$8:$C$100,0)),""),"")),"") | E5: =IFERROR(IF(VALUE(INDEX($F$8:$F$100,MATCH($B$2,$C$8:$C$100,0)))=E4,INDEX($E$8:$E$100,MATCH($B$2,$C$8:$C$100,0)),IFERROR(IF(VALUE(INDEX($I$8:$I$100,MATCH($B$2,$C$8:$C$100,0)))=E4,INDEX($H$8:$H$100,MATCH($B$2,$C$8:$C$100,0)),""),"")),"") | F5: =IFERROR(IF(VALUE(INDEX($F$8:$F$100,MATCH($B$2,$C$8:$C$100,0)))=F4,INDEX($E$8:$E$100,MATCH($B$2,$C$8:$C$100,0)),IFERROR(IF(VALUE(INDEX($I$8:$I$100,MATCH($B$2,$C$8:$C$100,0)))=F4,INDEX($H$8:$H$100,MATCH($B$2,$C$8:$C$100,0)),""),"")),"") | G5: =IFERROR(IF(VALUE(INDEX($F$8:$F$100,MATCH($B$2,$C$8:$C$100,0)))=G4,INDEX($E$8:$E$100,MATCH($B$2,$C$8:$C$100,0)),IFERROR(IF(VALUE(INDEX($I$8:$I$100,MATCH($B$2,$C$8:$C$100,0)))=G4,INDEX($H$8:$H$100,MATCH($B$2,$C$8:$C$100,0)),""),"")),"") | H5: =IFERROR(IF(VALUE(INDEX($F$8:$F$100,MATCH($B$2,$C$8:$C$100,0)))=H4,INDEX($E$8:$E$100,MATCH($B$2,$C$8:$C$100,0)),IFERROR(IF(VALUE(INDEX($I$8:$I$100,MATCH($B$2,$C$8:$C$100,0)))=H4,INDEX($H$8:$H$100,MATCH($B$2,$C$8:$C$100,0)),""),"")),"") | I5: =IFERROR(IF(VALUE(INDEX($F$8:$F$100,MATCH($B$2,$C$8:$C$100,0)))=I4,INDEX($E$8:$E$100,MATCH($B$2,$C$8:$C$100,0)),IFERROR(IF(VALUE(INDEX($I$8:$I$100,MATCH($B$2,$C$8:$C$100,0)))=I4,INDEX($H$8:$H$100,MATCH($B$2,$C$8:$C$100,0)),""),"")),"") | ... AB5: =IFERROR(IF(VALUE(INDEX($F$8:$F$100,MATCH($B$2,$C$8:$C$100,0)))=AB4,INDEX($E$8:$E$100,MATCH($B$2,$C$8:$C$100,0)),IFERROR(IF(VALUE(INDEX($I$8:$I$100,MATCH($B$2,$C$8:$C$100,0)))=AB4,INDEX($H$8:$H$100,MATCH($B$2,$C$8:$C$100,0)),""),"")),"")
A8: State | B8: Data Center Growth Limitation | D8: Growth Rate 1 | E8: Value 1 | F8: Year 1 | G8: Growth Rate 2 | H8: Value 2 | I8: Year 2
A9: =IF(ISBLANK('State Policies'!B2),"",'State Policies'!B2) -> New York | B9: =IF(ISBLANK('State Policies'!E2),"",'State Policies'!E2) -> 0% 2028 | C9: =IF(ISBLANK('State Policies'!F2),"",'State Policies'!F2) -> NY | D9: =IF($B9="","",IFERROR(INDEX(_xlfn.TEXTSPLIT($B9,";"),1,1),"")) -> 0% 2028 | E9: =IF($D9="","",IFERROR(INDEX(_xlfn.TEXTSPLIT($D9,"% "),1,1)/100,"")) -> 0 | F9: =IF($D9="","",IFERROR(VALUE(INDEX(_xlfn.TEXTSPLIT($D9,"% "),1,2)),"")) -> 2028 | G9: =IF($B9="","",IFERROR(INDEX(_xlfn.TEXTSPLIT($B9,";"),1,2),"")) | H9: =IF($G9="","",IFERROR(INDEX(_xlfn.TEXTSPLIT($G9,"% "),1,1)/100,"")) | I9: =IF($G9="","",IFERROR(VALUE(INDEX(_xlfn.TEXTSPLIT($G9,"% "),1,2)),""))

Sheet Calcs
A1: Calcs — every value traces to EPRI_PI2026 / Keys by cell reference. Grid rows cover all 48 states (WV resolves to 0 via IFERROR: no EPRI Table 2 row).
A3: STEP 1 — Active state
A4: name: | B4: =About!$B$1 -> Iowa
A5: code: | B5: =About!$B$2 -> IA
A7: STEP 2L — LOW capacity path (MW): single 2024 base (raw col F = 2024 MEDIUM) -> scenario 2030 endpoint (raw col H), geometric; then growth / decay_factor per decay_period after interp_end (Keys).
A8: state \ year | B8: 2024 | C8: 2025 | D8: 2026 | E8: 2027 | F8: 2028 | G8: 2029 | H8: 2030 | I8: 2031 | J8: 2032 | K8: 2033 | L8: 2034 | M8: 2035 | N8: 2036 | O8: 2037 | P8: 2038 | Q8: 2039 | R8: 2040 | S8: 2041 | T8: 2042 | U8: 2043 | V8: 2044 | W8: 2045 | X8: 2046 | Y8: 2047 | Z8: 2048 | AA8: 2049 | AB8: 2050 | AC8: g (2025-30 annual)
A9: AL | B9: =IFERROR(EPRI_PI2026!$F$2,0) -> 353 | C9: =B9*(1+$AC9) -> 368.119 | D9: =C9*(1+$AC9) -> 383.88554 | E9: =D9*(1+$AC9) -> 400.32737 | F9: =E9*(1+$AC9) -> 417.47339 | G9: =F9*(1+$AC9) -> 435.35379 | H9: =G9*(1+$AC9) -> 454 | I9: =H9*(1+$AC9/Keys!$C$7^ROUNDUP((I$8-Keys!$C$6)/Keys!$C$8,0)) -> 458.86121 | J9: =I9*(1+$AC9/Keys!$C$7^ROUNDUP((J$8-Keys!$C$6)/Keys!$C$8,0)) -> 463.77447 | K9: =J9*(1+$AC9/Keys!$C$7^ROUNDUP((K$8-Keys!$C$6)/Keys!$C$8,0)) -> 468.74033 | L9: =K9*(1+$AC9/Keys!$C$7^ROUNDUP((L$8-Keys!$C$6)/Keys!$C$8,0)) -> 473.75937 | M9: =L9*(1+$AC9/Keys!$C$7^ROUNDUP((M$8-Keys!$C$6)/Keys!$C$8,0)) -> 478.83215 | N9: =M9*(1+$AC9/Keys!$C$7^ROUNDUP((N$8-Keys!$C$6)/Keys!$C$8,0)) -> 480.11393 | O9: =N9*(1+$AC9/Keys!$C$7^ROUNDUP((O$8-Keys!$C$6)/Keys!$C$8,0)) -> 481.39913 | P9: =O9*(1+$AC9/Keys!$C$7^ROUNDUP((P$8-Keys!$C$6)/Keys!$C$8,0)) -> 482.68778 | ... AB9: =AA9*(1+$AC9/Keys!$C$7^ROUNDUP((AB$8-Keys!$C$6)/Keys!$C$8,0)) -> 487.30882 | AC9: =IFERROR((EPRI_PI2026!$H$2/EPRI_PI2026!$F$2)^(1/6)-1,0) -> 0.04283002
A10: AZ | B10: =IFERROR(EPRI_PI2026!$F$5,0) -> 1864 | C10: =B10*(1+$AC10) -> 1962.2681 | D10: =C10*(1+$AC10) -> 2065.7167 | E10: =D10*(1+$AC10) -> 2174.619 | F10: =E10*(1+$AC10) -> 2289.2626 | G10: =F10*(1+$AC10) -> 2409.95 | H10: =G10*(1+$AC10) -> 2537 | I10: =H10*(1+$AC10/Keys!$C$7^ROUNDUP((I$8-Keys!$C$6)/Keys!$C$8,0)) -> 2570.437 | J10: =I10*(1+$AC10/Keys!$C$7^ROUNDUP((J$8-Keys!$C$6)/Keys!$C$8,0)) -> 2604.3146 | K10: =J10*(1+$AC10/Keys!$C$7^ROUNDUP((K$8-Keys!$C$6)/Keys!$C$8,0)) -> 2638.6388 | L10: =K10*(1+$AC10/Keys!$C$7^ROUNDUP((L$8-Keys!$C$6)/Keys!$C$8,0)) -> 2673.4153 | M10: =L10*(1+$AC10/Keys!$C$7^ROUNDUP((M$8-Keys!$C$6)/Keys!$C$8,0)) -> 2708.6502 | N10: =M10*(1+$AC10/Keys!$C$7^ROUNDUP((N$8-Keys!$C$6)/Keys!$C$8,0)) -> 2717.575 | O10: =N10*(1+$AC10/Keys!$C$7^ROUNDUP((O$8-Keys!$C$6)/Keys!$C$8,0)) -> 2726.5293 | P10: =O10*(1+$AC10/Keys!$C$7^ROUNDUP((P$8-Keys!$C$6)/Keys!$C$8,0)) -> 2735.513 | ... AB10: =AA10*(1+$AC10/Keys!$C$7^ROUNDUP((AB$8-Keys!$C$6)/Keys!$C$8,0)) -> 2767.7772 | AC10: =IFERROR((EPRI_PI2026!$H$5/EPRI_PI2026!$F$5)^(1/6)-1,0) -> 0.052718916
A11: AR | B11: =IFERROR(EPRI_PI2026!$F$4,0) -> 11 | C11: =B11*(1+$AC11) -> 10.431391 | D11: =C11*(1+$AC11) -> 9.8921749 | E11: =D11*(1+$AC11) -> 9.3808315 | F11: =E11*(1+$AC11) -> 8.8959204 | G11: =F11*(1+$AC11) -> 8.4360751 | H11: =G11*(1+$AC11) -> 8 | I11: =H11*(1+$AC11/Keys!$C$7^ROUNDUP((I$8-Keys!$C$6)/Keys!$C$8,0)) -> 7.8966166 | J11: =I11*(1+$AC11/Keys!$C$7^ROUNDUP((J$8-Keys!$C$6)/Keys!$C$8,0)) -> 7.7945692 | K11: =J11*(1+$AC11/Keys!$C$7^ROUNDUP((K$8-Keys!$C$6)/Keys!$C$8,0)) -> 7.6938406 | L11: =K11*(1+$AC11/Keys!$C$7^ROUNDUP((L$8-Keys!$C$6)/Keys!$C$8,0)) -> 7.5944136 | M11: =L11*(1+$AC11/Keys!$C$7^ROUNDUP((M$8-Keys!$C$6)/Keys!$C$8,0)) -> 7.4962716 | N11: =M11*(1+$AC11/Keys!$C$7^ROUNDUP((N$8-Keys!$C$6)/Keys!$C$8,0)) -> 7.4720532 | O11: =N11*(1+$AC11/Keys!$C$7^ROUNDUP((O$8-Keys!$C$6)/Keys!$C$8,0)) -> 7.447913 | P11: =O11*(1+$AC11/Keys!$C$7^ROUNDUP((P$8-Keys!$C$6)/Keys!$C$8,0)) -> 7.4238507 | ... AB11: =AA11*(1+$AC11/Keys!$C$7^ROUNDUP((AB$8-Keys!$C$6)/Keys!$C$8,0)) -> 7.3388064 | AC11: =IFERROR((EPRI_PI2026!$H$4/EPRI_PI2026!$F$4)^(1/6)-1,0) -> -0.051691703
A12: CA | B12: =IFERROR(EPRI_PI2026!$F$6,0) -> 1496 | C12: =B12*(1+$AC12) -> 1494.8311 | D12: =C12*(1+$AC12) -> 1493.663 | E12: =D12*(1+$AC12) -> 1492.4959 | F12: =E12*(1+$AC12) -> 1491.3297 | G12: =F12*(1+$AC12) -> 1490.1644 | H12: =G12*(1+$AC12) -> 1489 | I12: =H12*(1+$AC12/Keys!$C$7^ROUNDUP((I$8-Keys!$C$6)/Keys!$C$8,0)) -> 1488.7091 | J12: =I12*(1+$AC12/Keys!$C$7^ROUNDUP((J$8-Keys!$C$6)/Keys!$C$8,0)) -> 1488.4183 | K12: =J12*(1+$AC12/Keys!$C$7^ROUNDUP((K$8-Keys!$C$6)/Keys!$C$8,0)) -> 1488.1276 | L12: =K12*(1+$AC12/Keys!$C$7^ROUNDUP((L$8-Keys!$C$6)/Keys!$C$8,0)) -> 1487.8369 | M12: =L12*(1+$AC12/Keys!$C$7^ROUNDUP((M$8-Keys!$C$6)/Keys!$C$8,0)) -> 1487.5462 | N12: =M12*(1+$AC12/Keys!$C$7^ROUNDUP((N$8-Keys!$C$6)/Keys!$C$8,0)) -> 1487.4736 | O12: =N12*(1+$AC12/Keys!$C$7^ROUNDUP((O$8-Keys!$C$6)/Keys!$C$8,0)) -> 1487.4009 | P12: =O12*(1+$AC12/Keys!$C$7^ROUNDUP((P$8-Keys!$C$6)/Keys!$C$8,0)) -> 1487.3283 | ... AB12: =AA12*(1+$AC12/Keys!$C$7^ROUNDUP((AB$8-Keys!$C$6)/Keys!$C$8,0)) -> 1487.0695 | AC12: =IFERROR((EPRI_PI2026!$H$6/EPRI_PI2026!$F$6)^(1/6)-1,0) -> -0.0007813822
A13: CO | B13: =IFERROR(EPRI_PI2026!$F$7,0) -> 241 | C13: =B13*(1+$AC13) -> 254.34405 | D13: =C13*(1+$AC13) -> 268.42694 | E13: =D13*(1+$AC13) -> 283.2896 | F13: =E13*(1+$AC13) -> 298.9752 | G13: =F13*(1+$AC13) -> 315.52931 | H13: =G13*(1+$AC13) -> 333 | I13: =H13*(1+$AC13/Keys!$C$7^ROUNDUP((I$8-Keys!$C$6)/Keys!$C$8,0)) -> 337.60951 | J13: =I13*(1+$AC13/Keys!$C$7^ROUNDUP((J$8-Keys!$C$6)/Keys!$C$8,0)) -> 342.28283 | K13: =J13*(1+$AC13/Keys!$C$7^ROUNDUP((K$8-Keys!$C$6)/Keys!$C$8,0)) -> 347.02083 | L13: =K13*(1+$AC13/Keys!$C$7^ROUNDUP((L$8-Keys!$C$6)/Keys!$C$8,0)) -> 351.82442 | M13: =L13*(1+$AC13/Keys!$C$7^ROUNDUP((M$8-Keys!$C$6)/Keys!$C$8,0)) -> 356.69451 | N13: =M13*(1+$AC13/Keys!$C$7^ROUNDUP((N$8-Keys!$C$6)/Keys!$C$8,0)) -> 357.92888 | O13: =N13*(1+$AC13/Keys!$C$7^ROUNDUP((O$8-Keys!$C$6)/Keys!$C$8,0)) -> 359.16753 | P13: =O13*(1+$AC13/Keys!$C$7^ROUNDUP((P$8-Keys!$C$6)/Keys!$C$8,0)) -> 360.41046 | ... AB13: =AA13*(1+$AC13/Keys!$C$7^ROUNDUP((AB$8-Keys!$C$6)/Keys!$C$8,0)) -> 364.87615 | AC13: =IFERROR((EPRI_PI2026!$H$7/EPRI_PI2026!$F$7)^(1/6)-1,0) -> 0.055369483
A14: CT | B14: =IFERROR(EPRI_PI2026!$F$8,0) -> 29 | C14: =B14*(1+$AC14) -> 38.629359 | D14: =C14*(1+$AC14) -> 51.456116 | E14: =D14*(1+$AC14) -> 68.541958 | F14: =E14*(1+$AC14) -> 91.3011 | G14: =F14*(1+$AC14) -> 121.61734 | H14: =G14*(1+$AC14) -> 162 | I14: =H14*(1+$AC14/Keys!$C$7^ROUNDUP((I$8-Keys!$C$6)/Keys!$C$8,0)) -> 175.4479 | J14: =I14*(1+$AC14/Keys!$C$7^ROUNDUP((J$8-Keys!$C$6)/Keys!$C$8,0)) -> 190.01213 | K14: =J14*(1+$AC14/Keys!$C$7^ROUNDUP((K$8-Keys!$C$6)/Keys!$C$8,0)) -> 205.78536 | L14: =K14*(1+$AC14/Keys!$C$7^ROUNDUP((L$8-Keys!$C$6)/Keys!$C$8,0)) -> 222.86796 | M14: =L14*(1+$AC14/Keys!$C$7^ROUNDUP((M$8-Keys!$C$6)/Keys!$C$8,0)) -> 241.36861 | N14: =M14*(1+$AC14/Keys!$C$7^ROUNDUP((N$8-Keys!$C$6)/Keys!$C$8,0)) -> 246.37771 | O14: =N14*(1+$AC14/Keys!$C$7^ROUNDUP((O$8-Keys!$C$6)/Keys!$C$8,0)) -> 251.49077 | P14: =O14*(1+$AC14/Keys!$C$7^ROUNDUP((P$8-Keys!$C$6)/Keys!$C$8,0)) -> 256.70994 | ... AB14: =AA14*(1+$AC14/Keys!$C$7^ROUNDUP((AB$8-Keys!$C$6)/Keys!$C$8,0)) -> 276.27122 | AC14: =IFERROR((EPRI_PI2026!$H$8/EPRI_PI2026!$F$8)^(1/6)-1,0) -> 0.33204686
A15: DE | B15: =IFERROR(EPRI_PI2026!$F$9,0) -> 14 | C15: =B15*(1+$AC15) -> 13.236506 | D15: =C15*(1+$AC15) -> 12.514649 | E15: =D15*(1+$AC15) -> 11.83216 | F15: =E15*(1+$AC15) -> 11.186889 | G15: =F15*(1+$AC15) -> 10.576809 | H15: =G15*(1+$AC15) -> 10 | I15: =H15*(1+$AC15/Keys!$C$7^ROUNDUP((I$8-Keys!$C$6)/Keys!$C$8,0)) -> 9.8636618 | J15: =I15*(1+$AC15/Keys!$C$7^ROUNDUP((J$8-Keys!$C$6)/Keys!$C$8,0)) -> 9.7291824 | K15: =J15*(1+$AC15/Keys!$C$7^ROUNDUP((K$8-Keys!$C$6)/Keys!$C$8,0)) -> 9.5965365 | L15: =K15*(1+$AC15/Keys!$C$7^ROUNDUP((L$8-Keys!$C$6)/Keys!$C$8,0)) -> 9.465699 | M15: =L15*(1+$AC15/Keys!$C$7^ROUNDUP((M$8-Keys!$C$6)/Keys!$C$8,0)) -> 9.3366454 | N15: =M15*(1+$AC15/Keys!$C$7^ROUNDUP((N$8-Keys!$C$6)/Keys!$C$8,0)) -> 9.3048219 | O15: =N15*(1+$AC15/Keys!$C$7^ROUNDUP((O$8-Keys!$C$6)/Keys!$C$8,0)) -> 9.2731068 | P15: =O15*(1+$AC15/Keys!$C$7^ROUNDUP((P$8-Keys!$C$6)/Keys!$C$8,0)) -> 9.2414998 | ... AB15: =AA15*(1+$AC15/Keys!$C$7^ROUNDUP((AB$8-Keys!$C$6)/Keys!$C$8,0)) -> 9.1298384 | AC15: =IFERROR((EPRI_PI2026!$H$9/EPRI_PI2026!$F$9)^(1/6)-1,0) -> -0.054535281
A16: FL | B16: =IFERROR(EPRI_PI2026!$F$10,0) -> 188 | C16: =B16*(1+$AC16) -> 207.71565 | D16: =C16*(1+$AC16) -> 229.4989 | E16: =D16*(1+$AC16) -> 253.56656 | F16: =E16*(1+$AC16) -> 280.15821 | G16: =F16*(1+$AC16) -> 309.53854 | H16: =G16*(1+$AC16) -> 342 | I16: =H16*(1+$AC16/Keys!$C$7^ROUNDUP((I$8-Keys!$C$6)/Keys!$C$8,0)) -> 350.96643 | J16: =I16*(1+$AC16/Keys!$C$7^ROUNDUP((J$8-Keys!$C$6)/Keys!$C$8,0)) -> 360.16793 | K16: =J16*(1+$AC16/Keys!$C$7^ROUNDUP((K$8-Keys!$C$6)/Keys!$C$8,0)) -> 369.61068 | L16: =K16*(1+$AC16/Keys!$C$7^ROUNDUP((L$8-Keys!$C$6)/Keys!$C$8,0)) -> 379.30099 | M16: =L16*(1+$AC16/Keys!$C$7^ROUNDUP((M$8-Keys!$C$6)/Keys!$C$8,0)) -> 389.24536 | N16: =M16*(1+$AC16/Keys!$C$7^ROUNDUP((N$8-Keys!$C$6)/Keys!$C$8,0)) -> 391.79664 | O16: =N16*(1+$AC16/Keys!$C$7^ROUNDUP((O$8-Keys!$C$6)/Keys!$C$8,0)) -> 394.36463 | P16: =O16*(1+$AC16/Keys!$C$7^ROUNDUP((P$8-Keys!$C$6)/Keys!$C$8,0)) -> 396.94946 | ... AB16: =AA16*(1+$AC16/Keys!$C$7^ROUNDUP((AB$8-Keys!$C$6)/Keys!$C$8,0)) -> 406.30704 | AC16: =IFERROR((EPRI_PI2026!$H$10/EPRI_PI2026!$F$10)^(1/6)-1,0) -> 0.1048705
A17: GA | B17: =IFERROR(EPRI_PI2026!$F$11,0) -> 1774 | C17: =B17*(1+$AC17) -> 1937.8428 | D17: =C17*(1+$AC17) -> 2116.8179 | E17: =D17*(1+$AC17) -> 2312.3226 | F17: =E17*(1+$AC17) -> 2525.8838 | G17: =F17*(1+$AC17) -> 2759.169 | H17: =G17*(1+$AC17) -> 3014 | I17: =H17*(1+$AC17/Keys!$C$7^ROUNDUP((I$8-Keys!$C$6)/Keys!$C$8,0)) -> 3083.5916 | J17: =I17*(1+$AC17/Keys!$C$7^ROUNDUP((J$8-Keys!$C$6)/Keys!$C$8,0)) -> 3154.7901 | K17: =J17*(1+$AC17/Keys!$C$7^ROUNDUP((K$8-Keys!$C$6)/Keys!$C$8,0)) -> 3227.6325 | L17: =K17*(1+$AC17/Keys!$C$7^ROUNDUP((L$8-Keys!$C$6)/Keys!$C$8,0)) -> 3302.1569 | M17: =L17*(1+$AC17/Keys!$C$7^ROUNDUP((M$8-Keys!$C$6)/Keys!$C$8,0)) -> 3378.4019 | N17: =M17*(1+$AC17/Keys!$C$7^ROUNDUP((N$8-Keys!$C$6)/Keys!$C$8,0)) -> 3397.9033 | O17: =N17*(1+$AC17/Keys!$C$7^ROUNDUP((O$8-Keys!$C$6)/Keys!$C$8,0)) -> 3417.5172 | P17: =O17*(1+$AC17/Keys!$C$7^ROUNDUP((P$8-Keys!$C$6)/Keys!$C$8,0)) -> 3437.2444 | ... AB17: =AA17*(1+$AC17/Keys!$C$7^ROUNDUP((AB$8-Keys!$C$6)/Keys!$C$8,0)) -> 3508.524 | AC17: =IFERROR((EPRI_PI2026!$H$11/EPRI_PI2026!$F$11)^(1/6)-1,0) -> 0.092357862
A18: ID | B18: =IFERROR(EPRI_PI2026!$F$13,0) -> 89 | C18: =B18*(1+$AC18) -> 108.36557 | D18: =C18*(1+$AC18) -> 131.94492 | E18: =D18*(1+$AC18) -> 160.65491 | F18: =E18*(1+$AC18) -> 195.61193 | G18: =F18*(1+$AC18) -> 238.17527 | H18: =G18*(1+$AC18) -> 290 | I18: =H18*(1+$AC18/Keys!$C$7^ROUNDUP((I$8-Keys!$C$6)/Keys!$C$8,0)) -> 305.77533 | J18: =I18*(1+$AC18/Keys!$C$7^ROUNDUP((J$8-Keys!$C$6)/Keys!$C$8,0)) -> 322.4088 | K18: =J18*(1+$AC18/Keys!$C$7^ROUNDUP((K$8-Keys!$C$6)/Keys!$C$8,0)) -> 339.94709 | L18: =K18*(1+$AC18/Keys!$C$7^ROUNDUP((L$8-Keys!$C$6)/Keys!$C$8,0)) -> 358.43942 | M18: =L18*(1+$AC18/Keys!$C$7^ROUNDUP((M$8-Keys!$C$6)/Keys!$C$8,0)) -> 377.93769 | N18: =M18*(1+$AC18/Keys!$C$7^ROUNDUP((N$8-Keys!$C$6)/Keys!$C$8,0)) -> 383.07743 | O18: =N18*(1+$AC18/Keys!$C$7^ROUNDUP((O$8-Keys!$C$6)/Keys!$C$8,0)) -> 388.28706 | P18: =O18*(1+$AC18/Keys!$C$7^ROUNDUP((P$8-Keys!$C$6)/Keys!$C$8,0)) -> 393.56754 | ... AB18: =AA18*(1+$AC18/Keys!$C$7^ROUNDUP((AB$8-Keys!$C$6)/Keys!$C$8,0)) -> 413.01615 | AC18: =IFERROR((EPRI_PI2026!$H$13/EPRI_PI2026!$F$13)^(1/6)-1,0) -> 0.21759073
A19: IL | B19: =IFERROR(EPRI_PI2026!$F$14,0) -> 1602 | C19: =B19*(1+$AC19) -> 1632.9646 | D19: =C19*(1+$AC19) -> 1664.5277 | E19: =D19*(1+$AC19) -> 1696.7009 | F19: =E19*(1+$AC19) -> 1729.496 | G19: =F19*(1+$AC19) -> 1762.9249 | H19: =G19*(1+$AC19) -> 1797 | I19: =H19*(1+$AC19/Keys!$C$7^ROUNDUP((I$8-Keys!$C$6)/Keys!$C$8,0)) -> 1805.6834 | J19: =I19*(1+$AC19/Keys!$C$7^ROUNDUP((J$8-Keys!$C$6)/Keys!$C$8,0)) -> 1814.4088 | K19: =J19*(1+$AC19/Keys!$C$7^ROUNDUP((K$8-Keys!$C$6)/Keys!$C$8,0)) -> 1823.1764 | L19: =K19*(1+$AC19/Keys!$C$7^ROUNDUP((L$8-Keys!$C$6)/Keys!$C$8,0)) -> 1831.9863 | M19: =L19*(1+$AC19/Keys!$C$7^ROUNDUP((M$8-Keys!$C$6)/Keys!$C$8,0)) -> 1840.8388 | N19: =M19*(1+$AC19/Keys!$C$7^ROUNDUP((N$8-Keys!$C$6)/Keys!$C$8,0)) -> 1843.0626 | O19: =N19*(1+$AC19/Keys!$C$7^ROUNDUP((O$8-Keys!$C$6)/Keys!$C$8,0)) -> 1845.2891 | P19: =O19*(1+$AC19/Keys!$C$7^ROUNDUP((P$8-Keys!$C$6)/Keys!$C$8,0)) -> 1847.5183 | ... AB19: =AA19*(1+$AC19/Keys!$C$7^ROUNDUP((AB$8-Keys!$C$6)/Keys!$C$8,0)) -> 1855.4834 | AC19: =IFERROR((EPRI_PI2026!$H$14/EPRI_PI2026!$F$14)^(1/6)-1,0) -> 0.01932872
A20: IN | B20: =IFERROR(EPRI_PI2026!$F$15,0) -> 292 | C20: =B20*(1+$AC20) -> 405.006 | D20: =C20*(1+$AC20) -> 561.7461 | E20: =D20*(1+$AC20) -> 779.14569 | F20: =E20*(1+$AC20) -> 1080.6804 | G20: =F20*(1+$AC20) -> 1498.9111 | H20: =G20*(1+$AC20) -> 2079 | I20: =H20*(1+$AC20/Keys!$C$7^ROUNDUP((I$8-Keys!$C$6)/Keys!$C$8,0)) -> 2280.1468 | J20: =I20*(1+$AC20/Keys!$C$7^ROUNDUP((J$8-Keys!$C$6)/Keys!$C$8,0)) -> 2500.7549 | K20: =J20*(1+$AC20/Keys!$C$7^ROUNDUP((K$8-Keys!$C$6)/Keys!$C$8,0)) -> 2742.7072 | L20: =K20*(1+$AC20/Keys!$C$7^ROUNDUP((L$8-Keys!$C$6)/Keys!$C$8,0)) -> 3008.0689 | M20: =L20*(1+$AC20/Keys!$C$7^ROUNDUP((M$8-Keys!$C$6)/Keys!$C$8,0)) -> 3299.1047 | N20: =M20*(1+$AC20/Keys!$C$7^ROUNDUP((N$8-Keys!$C$6)/Keys!$C$8,0)) -> 3378.9032 | O20: =N20*(1+$AC20/Keys!$C$7^ROUNDUP((O$8-Keys!$C$6)/Keys!$C$8,0)) -> 3460.6319 | P20: =O20*(1+$AC20/Keys!$C$7^ROUNDUP((P$8-Keys!$C$6)/Keys!$C$8,0)) -> 3544.3374 | ... AB20: =AA20*(1+$AC20/Keys!$C$7^ROUNDUP((AB$8-Keys!$C$6)/Keys!$C$8,0)) -> 3860.6987 | AC20: =IFERROR((EPRI_PI2026!$H$15/EPRI_PI2026!$F$15)^(1/6)-1,0) -> 0.38700685
A21: IA | B21: =IFERROR(EPRI_PI2026!$F$16,0) -> 1698 | C21: =B21*(1+$AC21) -> 1668.7706 | D21: =C21*(1+$AC21) -> 1640.0444 | E21: =D21*(1+$AC21) -> 1611.8126 | F21: =E21*(1+$AC21) -> 1584.0669 | G21: =F21*(1+$AC21) -> 1556.7987 | H21: =G21*(1+$AC21) -> 1530 | I21: =H21*(1+$AC21/Keys!$C$7^ROUNDUP((I$8-Keys!$C$6)/Keys!$C$8,0)) -> 1523.4156 | J21: =I21*(1+$AC21/Keys!$C$7^ROUNDUP((J$8-Keys!$C$6)/Keys!$C$8,0)) -> 1516.8596 | K21: =J21*(1+$AC21/Keys!$C$7^ROUNDUP((K$8-Keys!$C$6)/Keys!$C$8,0)) -> 1510.3318 | L21: =K21*(1+$AC21/Keys!$C$7^ROUNDUP((L$8-Keys!$C$6)/Keys!$C$8,0)) -> 1503.8321 | M21: =L21*(1+$AC21/Keys!$C$7^ROUNDUP((M$8-Keys!$C$6)/Keys!$C$8,0)) -> 1497.3603 | N21: =M21*(1+$AC21/Keys!$C$7^ROUNDUP((N$8-Keys!$C$6)/Keys!$C$8,0)) -> 1495.7494 | O21: =N21*(1+$AC21/Keys!$C$7^ROUNDUP((O$8-Keys!$C$6)/Keys!$C$8,0)) -> 1494.1401 | P21: =O21*(1+$AC21/Keys!$C$7^ROUNDUP((P$8-Keys!$C$6)/Keys!$C$8,0)) -> 1492.5326 | ... AB21: =AA21*(1+$AC21/Keys!$C$7^ROUNDUP((AB$8-Keys!$C$6)/Keys!$C$8,0)) -> 1486.821 | AC21: =IFERROR((EPRI_PI2026!$H$16/EPRI_PI2026!$F$16)^(1/6)-1,0) -> -0.017214008
A22: KS | B22: =IFERROR(EPRI_PI2026!$F$17,0) -> 44 | C22: =B22*(1+$AC22) -> 42.747513 | D22: =C22*(1+$AC22) -> 41.530678 | E22: =D22*(1+$AC22) -> 40.348482 | F22: =E22*(1+$AC22) -> 39.199938 | G22: =F22*(1+$AC22) -> 38.084087 | H22: =G22*(1+$AC22) -> 37 | I22: =H22*(1+$AC22/Keys!$C$7^ROUNDUP((I$8-Keys!$C$6)/Keys!$C$8,0)) -> 36.736693 | J22: =I22*(1+$AC22/Keys!$C$7^ROUNDUP((J$8-Keys!$C$6)/Keys!$C$8,0)) -> 36.47526 | K22: =J22*(1+$AC22/Keys!$C$7^ROUNDUP((K$8-Keys!$C$6)/Keys!$C$8,0)) -> 36.215687 | L22: =K22*(1+$AC22/Keys!$C$7^ROUNDUP((L$8-Keys!$C$6)/Keys!$C$8,0)) -> 35.957962 | M22: =L22*(1+$AC22/Keys!$C$7^ROUNDUP((M$8-Keys!$C$6)/Keys!$C$8,0)) -> 35.70207 | N22: =M22*(1+$AC22/Keys!$C$7^ROUNDUP((N$8-Keys!$C$6)/Keys!$C$8,0)) -> 35.638553 | O22: =N22*(1+$AC22/Keys!$C$7^ROUNDUP((O$8-Keys!$C$6)/Keys!$C$8,0)) -> 35.575148 | P22: =O22*(1+$AC22/Keys!$C$7^ROUNDUP((P$8-Keys!$C$6)/Keys!$C$8,0)) -> 35.511856 | ... AB22: =AA22*(1+$AC22/Keys!$C$7^ROUNDUP((AB$8-Keys!$C$6)/Keys!$C$8,0)) -> 35.287362 | AC22: =IFERROR((EPRI_PI2026!$H$17/EPRI_PI2026!$F$17)^(1/6)-1,0) -> -0.028465618
A23: KY | B23: =IFERROR(EPRI_PI2026!$F$18,0) -> 375 | C23: =B23*(1+$AC23) -> 380.30855 | D23: =C23*(1+$AC23) -> 385.69224 | E23: =D23*(1+$AC23) -> 391.15214 | F23: =E23*(1+$AC23) -> 396.68934 | G23: =F23*(1+$AC23) -> 402.30492 | H23: =G23*(1+$AC23) -> 408 | I23: =H23*(1+$AC23/Keys!$C$7^ROUNDUP((I$8-Keys!$C$6)/Keys!$C$8,0)) -> 409.44392 | J23: =I23*(1+$AC23/Keys!$C$7^ROUNDUP((J$8-Keys!$C$6)/Keys!$C$8,0)) -> 410.89296 | K23: =J23*(1+$AC23/Keys!$C$7^ROUNDUP((K$8-Keys!$C$6)/Keys!$C$8,0)) -> 412.34712 | L23: =K23*(1+$AC23/Keys!$C$7^ROUNDUP((L$8-Keys!$C$6)/Keys!$C$8,0)) -> 413.80643 | M23: =L23*(1+$AC23/Keys!$C$7^ROUNDUP((M$8-Keys!$C$6)/Keys!$C$8,0)) -> 415.2709 | N23: =M23*(1+$AC23/Keys!$C$7^ROUNDUP((N$8-Keys!$C$6)/Keys!$C$8,0)) -> 415.63832 | O23: =N23*(1+$AC23/Keys!$C$7^ROUNDUP((O$8-Keys!$C$6)/Keys!$C$8,0)) -> 416.00606 | P23: =O23*(1+$AC23/Keys!$C$7^ROUNDUP((P$8-Keys!$C$6)/Keys!$C$8,0)) -> 416.37412 | ... AB23: =AA23*(1+$AC23/Keys!$C$7^ROUNDUP((AB$8-Keys!$C$6)/Keys!$C$8,0)) -> 417.6882 | AC23: =IFERROR((EPRI_PI2026!$H$18/EPRI_PI2026!$F$18)^(1/6)-1,0) -> 0.01415612
A24: LA | B24: =IFERROR(EPRI_PI2026!$F$19,0) -> 9 | C24: =B24*(1+$AC24) -> 19.048474 | D24: =C24*(1+$AC24) -> 40.316038 | E24: =D24*(1+$AC24) -> 85.328776 | F24: =E24*(1+$AC24) -> 180.5981 | G24: =F24*(1+$AC24) -> 382.23535 | H24: =G24*(1+$AC24) -> 809 | I24: =H24*(1+$AC24/Keys!$C$7^ROUNDUP((I$8-Keys!$C$6)/Keys!$C$8,0)) -> 1034.8115 | J24: =I24*(1+$AC24/Keys!$C$7^ROUNDUP((J$8-Keys!$C$6)/Keys!$C$8,0)) -> 1323.6525 | K24: =J24*(1+$AC24/Keys!$C$7^ROUNDUP((K$8-Keys!$C$6)/Keys!$C$8,0)) -> 1693.1161 | L24: =K24*(1+$AC24/Keys!$C$7^ROUNDUP((L$8-Keys!$C$6)/Keys!$C$8,0)) -> 2165.7059 | M24: =L24*(1+$AC24/Keys!$C$7^ROUNDUP((M$8-Keys!$C$6)/Keys!$C$8,0)) -> 2770.2069 | N24: =M24*(1+$AC24/Keys!$C$7^ROUNDUP((N$8-Keys!$C$6)/Keys!$C$8,0)) -> 2963.5149 | O24: =N24*(1+$AC24/Keys!$C$7^ROUNDUP((O$8-Keys!$C$6)/Keys!$C$8,0)) -> 3170.3121 | P24: =O24*(1+$AC24/Keys!$C$7^ROUNDUP((P$8-Keys!$C$6)/Keys!$C$8,0)) -> 3391.5399 | ... AB24: =AA24*(1+$AC24/Keys!$C$7^ROUNDUP((AB$8-Keys!$C$6)/Keys!$C$8,0)) -> 4325.0577 | AC24: =IFERROR((EPRI_PI2026!$H$19/EPRI_PI2026!$F$19)^(1/6)-1,0) -> 1.1164971
A25: ME | B25: =IFERROR(EPRI_PI2026!$F$20,0) -> 3 | C25: =B25*(1+$AC25) -> 3 | D25: =C25*(1+$AC25) -> 3 | E25: =D25*(1+$AC25) -> 3 | F25: =E25*(1+$AC25) -> 3 | G25: =F25*(1+$AC25) -> 3 | H25: =G25*(1+$AC25) -> 3 | I25: =H25*(1+$AC25/Keys!$C$7^ROUNDUP((I$8-Keys!$C$6)/Keys!$C$8,0)) -> 3 | J25: =I25*(1+$AC25/Keys!$C$7^ROUNDUP((J$8-Keys!$C$6)/Keys!$C$8,0)) -> 3 | K25: =J25*(1+$AC25/Keys!$C$7^ROUNDUP((K$8-Keys!$C$6)/Keys!$C$8,0)) -> 3 | L25: =K25*(1+$AC25/Keys!$C$7^ROUNDUP((L$8-Keys!$C$6)/Keys!$C$8,0)) -> 3 | M25: =L25*(1+$AC25/Keys!$C$7^ROUNDUP((M$8-Keys!$C$6)/Keys!$C$8,0)) -> 3 | N25: =M25*(1+$AC25/Keys!$C$7^ROUNDUP((N$8-Keys!$C$6)/Keys!$C$8,0)) -> 3 | O25: =N25*(1+$AC25/Keys!$C$7^ROUNDUP((O$8-Keys!$C$6)/Keys!$C$8,0)) -> 3 | P25: =O25*(1+$AC25/Keys!$C$7^ROUNDUP((P$8-Keys!$C$6)/Keys!$C$8,0)) -> 3 | ... AB25: =AA25*(1+$AC25/Keys!$C$7^ROUNDUP((AB$8-Keys!$C$6)/Keys!$C$8,0)) -> 3 | AC25: =IFERROR((EPRI_PI2026!$H$20/EPRI_PI2026!$F$20)^(1/6)-1,0) -> 0
A26: MD | B26: =IFERROR(EPRI_PI2026!$F$21,0) -> 63 | C26: =B26*(1+$AC26) -> 90.319532 | D26: =C26*(1+$AC26) -> 129.486 | E26: =D26*(1+$AC26) -> 185.63674 | F26: =E26*(1+$AC26) -> 266.13688 | G26: =F26*(1+$AC26) -> 381.54538 | H26: =G26*(1+$AC26) -> 547 | I26: =H26*(1+$AC26/Keys!$C$7^ROUNDUP((I$8-Keys!$C$6)/Keys!$C$8,0)) -> 606.30073 | J26: =I26*(1+$AC26/Keys!$C$7^ROUNDUP((J$8-Keys!$C$6)/Keys!$C$8,0)) -> 672.0303 | K26: =J26*(1+$AC26/Keys!$C$7^ROUNDUP((K$8-Keys!$C$6)/Keys!$C$8,0)) -> 744.88567 | L26: =K26*(1+$AC26/Keys!$C$7^ROUNDUP((L$8-Keys!$C$6)/Keys!$C$8,0)) -> 825.63936 | M26: =L26*(1+$AC26/Keys!$C$7^ROUNDUP((M$8-Keys!$C$6)/Keys!$C$8,0)) -> 915.14761 | N26: =M26*(1+$AC26/Keys!$C$7^ROUNDUP((N$8-Keys!$C$6)/Keys!$C$8,0)) -> 939.95059 | O26: =N26*(1+$AC26/Keys!$C$7^ROUNDUP((O$8-Keys!$C$6)/Keys!$C$8,0)) -> 965.4258 | P26: =O26*(1+$AC26/Keys!$C$7^ROUNDUP((P$8-Keys!$C$6)/Keys!$C$8,0)) -> 991.59146 | ... AB26: =AA26*(1+$AC26/Keys!$C$7^ROUNDUP((AB$8-Keys!$C$6)/Keys!$C$8,0)) -> 1091.1873 | AC26: =IFERROR((EPRI_PI2026!$H$21/EPRI_PI2026!$F$21)^(1/6)-1,0) -> 0.43364337
A27: MA | B27: =IFERROR(EPRI_PI2026!$F$22,0) -> 171 | C27: =B27*(1+$AC27) -> 169.1155 | D27: =C27*(1+$AC27) -> 167.25177 | E27: =D27*(1+$AC27) -> 165.40859 | F27: =E27*(1+$AC27) -> 163.58571 | G27: =F27*(1+$AC27) -> 161.78292 | H27: =G27*(1+$AC27) -> 160 | I27: =H27*(1+$AC27/Keys!$C$7^ROUNDUP((I$8-Keys!$C$6)/Keys!$C$8,0)) -> 159.55918 | J27: =I27*(1+$AC27/Keys!$C$7^ROUNDUP((J$8-Keys!$C$6)/Keys!$C$8,0)) -> 159.11958 | K27: =J27*(1+$AC27/Keys!$C$7^ROUNDUP((K$8-Keys!$C$6)/Keys!$C$8,0)) -> 158.68119 | L27: =K27*(1+$AC27/Keys!$C$7^ROUNDUP((L$8-Keys!$C$6)/Keys!$C$8,0)) -> 158.244 | M27: =L27*(1+$AC27/Keys!$C$7^ROUNDUP((M$8-Keys!$C$6)/Keys!$C$8,0)) -> 157.80802 | N27: =M27*(1+$AC27/Keys!$C$7^ROUNDUP((N$8-Keys!$C$6)/Keys!$C$8,0)) -> 157.69933 | O27: =N27*(1+$AC27/Keys!$C$7^ROUNDUP((O$8-Keys!$C$6)/Keys!$C$8,0)) -> 157.59071 | P27: =O27*(1+$AC27/Keys!$C$7^ROUNDUP((P$8-Keys!$C$6)/Keys!$C$8,0)) -> 157.48216 | ... AB27: =AA27*(1+$AC27/Keys!$C$7^ROUNDUP((AB$8-Keys!$C$6)/Keys!$C$8,0)) -> 157.09612 | AC27: =IFERROR((EPRI_PI2026!$H$22/EPRI_PI2026!$F$22)^(1/6)-1,0) -> -0.011020449
A28: MI | B28: =IFERROR(EPRI_PI2026!$F$23,0) -> 97 | C28: =B28*(1+$AC28) -> 100.22055 | D28: =C28*(1+$AC28) -> 103.54803 | E28: =D28*(1+$AC28) -> 106.98598 | F28: =E28*(1+$AC28) -> 110.53808 | G28: =F28*(1+$AC28) -> 114.20811 | H28: =G28*(1+$AC28) -> 118 | I28: =H28*(1+$AC28/Keys!$C$7^ROUNDUP((I$8-Keys!$C$6)/Keys!$C$8,0)) -> 118.97945 | J28: =I28*(1+$AC28/Keys!$C$7^ROUNDUP((J$8-Keys!$C$6)/Keys!$C$8,0)) -> 119.96702 | K28: =J28*(1+$AC28/Keys!$C$7^ROUNDUP((K$8-Keys!$C$6)/Keys!$C$8,0)) -> 120.96279 | L28: =K28*(1+$AC28/Keys!$C$7^ROUNDUP((L$8-Keys!$C$6)/Keys!$C$8,0)) -> 121.96683 | M28: =L28*(1+$AC28/Keys!$C$7^ROUNDUP((M$8-Keys!$C$6)/Keys!$C$8,0)) -> 122.9792 | N28: =M28*(1+$AC28/Keys!$C$7^ROUNDUP((N$8-Keys!$C$6)/Keys!$C$8,0)) -> 123.2344 | O28: =N28*(1+$AC28/Keys!$C$7^ROUNDUP((O$8-Keys!$C$6)/Keys!$C$8,0)) -> 123.49012 | P28: =O28*(1+$AC28/Keys!$C$7^ROUNDUP((P$8-Keys!$C$6)/Keys!$C$8,0)) -> 123.74637 | ... AB28: =AA28*(1+$AC28/Keys!$C$7^ROUNDUP((AB$8-Keys!$C$6)/Keys!$C$8,0)) -> 124.66394 | AC28: =IFERROR((EPRI_PI2026!$H$23/EPRI_PI2026!$F$23)^(1/6)-1,0) -> 0.033201542
A29: MN | B29: =IFERROR(EPRI_PI2026!$F$24,0) -> 106 | C29: =B29*(1+$AC29) -> 122.78017 | D29: =C29*(1+$AC29) -> 142.21669 | E29: =D29*(1+$AC29) -> 164.73008 | F29: =E29*(1+$AC29) -> 190.80742 | G29: =F29*(1+$AC29) -> 221.0129 | H29: =G29*(1+$AC29) -> 256 | I29: =H29*(1+$AC29/Keys!$C$7^ROUNDUP((I$8-Keys!$C$6)/Keys!$C$8,0)) -> 266.13142 | J29: =I29*(1+$AC29/Keys!$C$7^ROUNDUP((J$8-Keys!$C$6)/Keys!$C$8,0)) -> 276.6638 | K29: =J29*(1+$AC29/Keys!$C$7^ROUNDUP((K$8-Keys!$C$6)/Keys!$C$8,0)) -> 287.61301 | L29: =K29*(1+$AC29/Keys!$C$7^ROUNDUP((L$8-Keys!$C$6)/Keys!$C$8,0)) -> 298.99554 | M29: =L29*(1+$AC29/Keys!$C$7^ROUNDUP((M$8-Keys!$C$6)/Keys!$C$8,0)) -> 310.82855 | N29: =M29*(1+$AC29/Keys!$C$7^ROUNDUP((N$8-Keys!$C$6)/Keys!$C$8,0)) -> 313.90388 | O29: =N29*(1+$AC29/Keys!$C$7^ROUNDUP((O$8-Keys!$C$6)/Keys!$C$8,0)) -> 317.00963 | P29: =O29*(1+$AC29/Keys!$C$7^ROUNDUP((P$8-Keys!$C$6)/Keys!$C$8,0)) -> 320.14611 | ... AB29: =AA29*(1+$AC29/Keys!$C$7^ROUNDUP((AB$8-Keys!$C$6)/Keys!$C$8,0)) -> 331.59398 | AC29: =IFERROR((EPRI_PI2026!$H$24/EPRI_PI2026!$F$24)^(1/6)-1,0) -> 0.15830345
A30: MS | B30: =IFERROR(EPRI_PI2026!$F$25,0) -> 46 | C30: =B30*(1+$AC30) -> 70.615105 | D30: =C30*(1+$AC30) -> 108.40202 | E30: =D30*(1+$AC30) -> 166.40913 | F30: =E30*(1+$AC30) -> 255.45649 | G30: =F30*(1+$AC30) -> 392.15406 | H30: =G30*(1+$AC30) -> 602 | I30: =H30*(1+$AC30/Keys!$C$7^ROUNDUP((I$8-Keys!$C$6)/Keys!$C$8,0)) -> 682.5342 | J30: =I30*(1+$AC30/Keys!$C$7^ROUNDUP((J$8-Keys!$C$6)/Keys!$C$8,0)) -> 773.84209 | K30: =J30*(1+$AC30/Keys!$C$7^ROUNDUP((K$8-Keys!$C$6)/Keys!$C$8,0)) -> 877.36494 | L30: =K30*(1+$AC30/Keys!$C$7^ROUNDUP((L$8-Keys!$C$6)/Keys!$C$8,0)) -> 994.73684 | M30: =L30*(1+$AC30/Keys!$C$7^ROUNDUP((M$8-Keys!$C$6)/Keys!$C$8,0)) -> 1127.8105 | N30: =M30*(1+$AC30/Keys!$C$7^ROUNDUP((N$8-Keys!$C$6)/Keys!$C$8,0)) -> 1165.5295 | O30: =N30*(1+$AC30/Keys!$C$7^ROUNDUP((O$8-Keys!$C$6)/Keys!$C$8,0)) -> 1204.5099 | P30: =O30*(1+$AC30/Keys!$C$7^ROUNDUP((P$8-Keys!$C$6)/Keys!$C$8,0)) -> 1244.7941 | ... AB30: =AA30*(1+$AC30/Keys!$C$7^ROUNDUP((AB$8-Keys!$C$6)/Keys!$C$8,0)) -> 1400.5108 | AC30: =IFERROR((EPRI_PI2026!$H$25/EPRI_PI2026!$F$25)^(1/6)-1,0) -> 0.53511097
A31: MO | B31: =IFERROR(EPRI_PI2026!$F$26,0) -> 224 | C31: =B31*(1+$AC31) -> 242.3199 | D31: =C31*(1+$AC31) -> 262.13811 | E31: =D31*(1+$AC31) -> 283.57715 | F31: =E31*(1+$AC31) -> 306.76959 | G31: =F31*(1+$AC31) -> 331.85883 | H31: =G31*(1+$AC31) -> 359 | I31: =H31*(1+$AC31/Keys!$C$7^ROUNDUP((I$8-Keys!$C$6)/Keys!$C$8,0)) -> 366.34023 | J31: =I31*(1+$AC31/Keys!$C$7^ROUNDUP((J$8-Keys!$C$6)/Keys!$C$8,0)) -> 373.83054 | K31: =J31*(1+$AC31/Keys!$C$7^ROUNDUP((K$8-Keys!$C$6)/Keys!$C$8,0)) -> 381.474 | L31: =K31*(1+$AC31/Keys!$C$7^ROUNDUP((L$8-Keys!$C$6)/Keys!$C$8,0)) -> 389.27374 | M31: =L31*(1+$AC31/Keys!$C$7^ROUNDUP((M$8-Keys!$C$6)/Keys!$C$8,0)) -> 397.23296 | N31: =M31*(1+$AC31/Keys!$C$7^ROUNDUP((N$8-Keys!$C$6)/Keys!$C$8,0)) -> 399.26345 | O31: =N31*(1+$AC31/Keys!$C$7^ROUNDUP((O$8-Keys!$C$6)/Keys!$C$8,0)) -> 401.30431 | P31: =O31*(1+$AC31/Keys!$C$7^ROUNDUP((P$8-Keys!$C$6)/Keys!$C$8,0)) -> 403.35561 | ... AB31: =AA31*(1+$AC31/Keys!$C$7^ROUNDUP((AB$8-Keys!$C$6)/Keys!$C$8,0)) -> 410.75553 | AC31: =IFERROR((EPRI_PI2026!$H$26/EPRI_PI2026!$F$26)^(1/6)-1,0) -> 0.08178529
A32: MT | B32: =IFERROR(EPRI_PI2026!$F$27,0) -> 106 | C32: =B32*(1+$AC32) -> 104.26377 | D32: =C32*(1+$AC32) -> 102.55598 | E32: =D32*(1+$AC32) -> 100.87616 | F32: =E32*(1+$AC32) -> 99.223858 | G32: =F32*(1+$AC32) -> 97.598619 | H32: =G32*(1+$AC32) -> 96 | I32: =H32*(1+$AC32/Keys!$C$7^ROUNDUP((I$8-Keys!$C$6)/Keys!$C$8,0)) -> 95.606891 | J32: =I32*(1+$AC32/Keys!$C$7^ROUNDUP((J$8-Keys!$C$6)/Keys!$C$8,0)) -> 95.215393 | K32: =J32*(1+$AC32/Keys!$C$7^ROUNDUP((K$8-Keys!$C$6)/Keys!$C$8,0)) -> 94.825497 | L32: =K32*(1+$AC32/Keys!$C$7^ROUNDUP((L$8-Keys!$C$6)/Keys!$C$8,0)) -> 94.437198 | M32: =L32*(1+$AC32/Keys!$C$7^ROUNDUP((M$8-Keys!$C$6)/Keys!$C$8,0)) -> 94.050489 | N32: =M32*(1+$AC32/Keys!$C$7^ROUNDUP((N$8-Keys!$C$6)/Keys!$C$8,0)) -> 93.954207 | O32: =N32*(1+$AC32/Keys!$C$7^ROUNDUP((O$8-Keys!$C$6)/Keys!$C$8,0)) -> 93.858025 | P32: =O32*(1+$AC32/Keys!$C$7^ROUNDUP((P$8-Keys!$C$6)/Keys!$C$8,0)) -> 93.76194 | ... AB32: =AA32*(1+$AC32/Keys!$C$7^ROUNDUP((AB$8-Keys!$C$6)/Keys!$C$8,0)) -> 93.420499 | AC32: =IFERROR((EPRI_PI2026!$H$27/EPRI_PI2026!$F$27)^(1/6)-1,0) -> -0.016379523
A33: NE | B33: =IFERROR(EPRI_PI2026!$F$28,0) -> 1021 | C33: =B33*(1+$AC33) -> 1042.6524 | D33: =C33*(1+$AC33) -> 1064.764 | E33: =D33*(1+$AC33) -> 1087.3445 | F33: =E33*(1+$AC33) -> 1110.4038 | G33: =F33*(1+$AC33) -> 1133.9522 | H33: =G33*(1+$AC33) -> 1158 | I33: =H33*(1+$AC33/Keys!$C$7^ROUNDUP((I$8-Keys!$C$6)/Keys!$C$8,0)) -> 1164.1394 | J33: =I33*(1+$AC33/Keys!$C$7^ROUNDUP((J$8-Keys!$C$6)/Keys!$C$8,0)) -> 1170.3114 | K33: =J33*(1+$AC33/Keys!$C$7^ROUNDUP((K$8-Keys!$C$6)/Keys!$C$8,0)) -> 1176.5161 | L33: =K33*(1+$AC33/Keys!$C$7^ROUNDUP((L$8-Keys!$C$6)/Keys!$C$8,0)) -> 1182.7538 | M33: =L33*(1+$AC33/Keys!$C$7^ROUNDUP((M$8-Keys!$C$6)/Keys!$C$8,0)) -> 1189.0244 | N33: =M33*(1+$AC33/Keys!$C$7^ROUNDUP((N$8-Keys!$C$6)/Keys!$C$8,0)) -> 1190.6004 | O33: =N33*(1+$AC33/Keys!$C$7^ROUNDUP((O$8-Keys!$C$6)/Keys!$C$8,0)) -> 1192.1785 | P33: =O33*(1+$AC33/Keys!$C$7^ROUNDUP((P$8-Keys!$C$6)/Keys!$C$8,0)) -> 1193.7586 | ... AB33: =AA33*(1+$AC33/Keys!$C$7^ROUNDUP((AB$8-Keys!$C$6)/Keys!$C$8,0)) -> 1199.4063 | AC33: =IFERROR((EPRI_PI2026!$H$28/EPRI_PI2026!$F$28)^(1/6)-1,0) -> 0.021207047
A34: NV | B34: =IFERROR(EPRI_PI2026!$F$29,0) -> 866 | C34: =B34*(1+$AC34) -> 922.82238 | D34: =C34*(1+$AC34) -> 983.37315 | E34: =D34*(1+$AC34) -> 1047.8969 | F34: =E34*(1+$AC34) -> 1116.6544 | G34: =F34*(1+$AC34) -> 1189.9235 | H34: =G34*(1+$AC34) -> 1268 | I34: =H34*(1+$AC34/Keys!$C$7^ROUNDUP((I$8-Keys!$C$6)/Keys!$C$8,0)) -> 1288.7999 | J34: =I34*(1+$AC34/Keys!$C$7^ROUNDUP((J$8-Keys!$C$6)/Keys!$C$8,0)) -> 1309.941 | K34: =J34*(1+$AC34/Keys!$C$7^ROUNDUP((K$8-Keys!$C$6)/Keys!$C$8,0)) -> 1331.4288 | L34: =K34*(1+$AC34/Keys!$C$7^ROUNDUP((L$8-Keys!$C$6)/Keys!$C$8,0)) -> 1353.2692 | M34: =L34*(1+$AC34/Keys!$C$7^ROUNDUP((M$8-Keys!$C$6)/Keys!$C$8,0)) -> 1375.4678 | N34: =M34*(1+$AC34/Keys!$C$7^ROUNDUP((N$8-Keys!$C$6)/Keys!$C$8,0)) -> 1381.1085 | O34: =N34*(1+$AC34/Keys!$C$7^ROUNDUP((O$8-Keys!$C$6)/Keys!$C$8,0)) -> 1386.7723 | P34: =O34*(1+$AC34/Keys!$C$7^ROUNDUP((P$8-Keys!$C$6)/Keys!$C$8,0)) -> 1392.4593 | ... AB34: =AA34*(1+$AC34/Keys!$C$7^ROUNDUP((AB$8-Keys!$C$6)/Keys!$C$8,0)) -> 1412.9242 | AC34: =IFERROR((EPRI_PI2026!$H$29/EPRI_PI2026!$F$29)^(1/6)-1,0) -> 0.065614759
A35: NH | B35: =IFERROR(EPRI_PI2026!$F$30,0) -> 4 | C35: =B35*(1+$AC35) -> 3.8127372 | D35: =C35*(1+$AC35) -> 3.6342412 | E35: =D35*(1+$AC35) -> 3.4641016 | F35: =E35*(1+$AC35) -> 3.3019272 | G35: =F35*(1+$AC35) -> 3.1473452 | H35: =G35*(1+$AC35) -> 3 | I35: =H35*(1+$AC35/Keys!$C$7^ROUNDUP((I$8-Keys!$C$6)/Keys!$C$8,0)) -> 2.9648882 | J35: =I35*(1+$AC35/Keys!$C$7^ROUNDUP((J$8-Keys!$C$6)/Keys!$C$8,0)) -> 2.9301874 | K35: =J35*(1+$AC35/Keys!$C$7^ROUNDUP((K$8-Keys!$C$6)/Keys!$C$8,0)) -> 2.8958927 | L35: =K35*(1+$AC35/Keys!$C$7^ROUNDUP((L$8-Keys!$C$6)/Keys!$C$8,0)) -> 2.8619994 | M35: =L35*(1+$AC35/Keys!$C$7^ROUNDUP((M$8-Keys!$C$6)/Keys!$C$8,0)) -> 2.8285027 | N35: =M35*(1+$AC35/Keys!$C$7^ROUNDUP((N$8-Keys!$C$6)/Keys!$C$8,0)) -> 2.8202266 | O35: =N35*(1+$AC35/Keys!$C$7^ROUNDUP((O$8-Keys!$C$6)/Keys!$C$8,0)) -> 2.8119747 | P35: =O35*(1+$AC35/Keys!$C$7^ROUNDUP((P$8-Keys!$C$6)/Keys!$C$8,0)) -> 2.8037469 | ... AB35: =AA35*(1+$AC35/Keys!$C$7^ROUNDUP((AB$8-Keys!$C$6)/Keys!$C$8,0)) -> 2.7746452 | AC35: =IFERROR((EPRI_PI2026!$H$30/EPRI_PI2026!$F$30)^(1/6)-1,0) -> -0.046815707
A36: NJ | B36: =IFERROR(EPRI_PI2026!$F$31,0) -> 547 | C36: =B36*(1+$AC36) -> 570.08871 | D36: =C36*(1+$AC36) -> 594.15199 | E36: =D36*(1+$AC36) -> 619.23097 | F36: =E36*(1+$AC36) -> 645.36853 | G36: =F36*(1+$AC36) -> 672.60935 | H36: =G36*(1+$AC36) -> 701 | I36: =H36*(1+$AC36/Keys!$C$7^ROUNDUP((I$8-Keys!$C$6)/Keys!$C$8,0)) -> 708.39725 | J36: =I36*(1+$AC36/Keys!$C$7^ROUNDUP((J$8-Keys!$C$6)/Keys!$C$8,0)) -> 715.87256 | K36: =J36*(1+$AC36/Keys!$C$7^ROUNDUP((K$8-Keys!$C$6)/Keys!$C$8,0)) -> 723.42676 | L36: =K36*(1+$AC36/Keys!$C$7^ROUNDUP((L$8-Keys!$C$6)/Keys!$C$8,0)) -> 731.06066 | M36: =L36*(1+$AC36/Keys!$C$7^ROUNDUP((M$8-Keys!$C$6)/Keys!$C$8,0)) -> 738.77513 | N36: =M36*(1+$AC36/Keys!$C$7^ROUNDUP((N$8-Keys!$C$6)/Keys!$C$8,0)) -> 740.7241 | O36: =N36*(1+$AC36/Keys!$C$7^ROUNDUP((O$8-Keys!$C$6)/Keys!$C$8,0)) -> 742.67821 | P36: =O36*(1+$AC36/Keys!$C$7^ROUNDUP((P$8-Keys!$C$6)/Keys!$C$8,0)) -> 744.63747 | ... AB36: =AA36*(1+$AC36/Keys!$C$7^ROUNDUP((AB$8-Keys!$C$6)/Keys!$C$8,0)) -> 751.66266 | AC36: =IFERROR((EPRI_PI2026!$H$31/EPRI_PI2026!$F$31)^(1/6)-1,0) -> 0.042209711
