Workbook

Sheet About
A1: DRCF Demand Response Capacity Factor | B1: Iowa
A3: Sources: | B3: U.S. Energy Information Administration
B4: 2021
B5: Form 861
B6: https://www.eia.gov/electricity/data/eia861/
B7: Demand_Response_2021.xlsx
A9: Notes:
A10: We calculate the capacity factor as the total MWh
A11: demand response generation divided by the MW
A12: peak demand savings times the number of hours
A13: per year.

Sheet Form 861
A1: Utility Characteristics | F1: Yearly Energy and Demand Savings | Z1: Program Costs | AJ1: DSM Program
F2: Number of Customers Enrolled | K2: Energy Savings (MWh) | P2: Potential Peak Demand Savings (MW) | U2: Actual Peak Demand Savings (MW) | Z2: Customer Incentives (Thousand Dollars) | AE2: All Other Costs (Thousand Dollars) | AJ2: Grid Connected
A3: Data Year | B3: Utility Number | C3: Utility Name | D3: State | E3: BA Code | F3: Residential | G3: Commercial | H3: Industrial | I3: Transportation | J3: Total | K3: Residential | L3: Commercial | M3: Industrial | N3: Transportation | O3: Total | P3: Residential | Q3: Commercial | R3: Industrial | S3: Transportation | T3: Total | U3: Residential | V3: Commercial | W3: Industrial | X3: Transportation | Y3: Total | Z3: Residential | AA3: Commercial | AB3: Industrial | AC3: Transportation | AD3: Total | AE3: Residential | AF3: Commercial | AG3: Industrial | AH3: Transportation | AI3: Total | AJ3: Water Heater
A4: 2021 | B4: 162 | C4: Aiken Electric Coop Inc | D4: SC | E4: SC | F4: 284 | G4: 0 | H4: 0 | I4: 0 | J4: 284 | K4: 3.525 | L4: 0 | M4: 0 | N4: 0 | O4: 3.525 | P4: 0.202 | Q4: 0 | R4: 0 | S4: 0 | T4: 0.202 | U4: 0.202 | V4: 0 | W4: 0 | X4: 0 | Y4: 0.202 | Z4: 14.2 | AA4: 0 | AB4: 0 | AC4: 0 | AD4: 14.2 | AE4: 0 | AF4: 0 | AG4: 0 | AH4: 0 | AI4: 0 | AJ4: 231
A5: 2021 | B5: 189 | C5: PowerSouth Energy Cooperative | D5: AL | E5: SOCO | F5: 20948 | G5: . | H5: . | I5: . | J5: 20948 | K5: 0 | L5: . | M5: . | N5: . | O5: 0 | P5: 18 | Q5: . | R5: . | S5: . | T5: 18 | U5: 18 | V5: . | W5: . | X5: . | Y5: 18 | Z5: 0 | AA5: . | AB5: . | AC5: . | AD5: 0 | AE5: 105 | AF5: . | AG5: . | AH5: . | AI5: 105 | AJ5: 177
A6: 2021 | B6: 195 | C6: Alabama Power Co | D6: AL | E6: SOCO | F6: 5488 | G6: 5 | H6: 28 | I6: . | J6: 5521 | K6: 0 | L6: 0 | M6: 0 | N6: . | O6: 0 | P6: 147.394 | Q6: 4.455 | R6: 1530.676 | S6: . | T6: 1682.525 | U6: 2.479 | V6: 0 | W6: 0 | X6: . | Y6: 2.479 | Z6: 250.375 | AA6: 107.474 | AB6: 26583.809 | AC6: . | AD6: 26941.658 | AE6: 842.046 | AF6: 10.133 | AG6: 1129.619 | AH6: . | AI6: 1981.798 | AJ6: .
A7: 2021 | B7: 207 | C7: Alameda Municipal Power | D7: CA | E7: CISO | F7: 32044 | G7: 4135 | H7: . | I7: . | J7: 36179 | K7: . | L7: . | M7: . | N7: . | O7: . | P7: . | Q7: . | R7: . | S7: . | T7: . | U7: . | V7: . | W7: . | X7: . | Y7: . | Z7: . | AA7: . | AB7: . | AC7: . | AD7: . | AE7: . | AF7: . | AG7: . | AH7: . | AI7: . | AJ7: .
A8: 2021 | B8: 213 | C8: Alaska Electric Light & Power Co. | D8: AK | E8: NA | F8: 2263 | G8: 30 | H8: . | I8: . | J8: 2293 | K8: . | L8: . | M8: . | N8: . | O8: . | P8: 5 | Q8: 13 | R8: . | S8: . | T8: 18 | U8: . | V8: . | W8: . | X8: . | Y8: . | Z8: 63.569 | AA8: 0.843 | AB8: . | AC8: . | AD8: 64.412 | AE8: 1.7 | AF8: 0.023 | AG8: . | AH8: . | AI8: 1.723 | AJ8: .
A9: 2021 | B9: 295 | C9: City of Alexandria - (MN) | D9: MN | E9: MISO | F9: 2823 | G9: . | H9: . | I9: . | J9: 2823 | K9: . | L9: . | M9: . | N9: . | O9: . | P9: 9 | Q9: . | R9: . | S9: . | T9: 9 | U9: 3.7 | V9: . | W9: . | X9: . | Y9: 3.7 | Z9: 0 | AA9: . | AB9: . | AC9: . | AD9: 0 | AE9: 42.7 | AF9: . | AG9: . | AH9: . | AI9: 42.7 | AJ9: .
A10: 2021 | B10: 332 | C10: Allegheny Electric Coop Inc | D10: PA | E10: PJM | F10: 45080 | G10: . | H10: . | I10: . | J10: 45080 | K10: . | L10: . | M10: . | N10: . | O10: . | P10: 45 | Q10: . | R10: . | S10: . | T10: 45 | U10: 43 | V10: . | W10: . | X10: . | Y10: 43 | Z10: . | AA10: . | AB10: . | AC10: . | AD10: . | AE10: 2680.233 | AF10: . | AG10: . | AH10: . | AI10: 2680.233 | AJ10: .
A11: 2021 | B11: 407 | C11: Altamaha Electric Member Corp | D11: GA | E11: SOCO | F11: . | G11: . | H11: 234 | I11: . | J11: 234 | K11: . | L11: . | M11: 151 | N11: . | O11: 151 | P11: . | Q11: . | R11: 16 | S11: . | T11: 16 | U11: . | V11: . | W11: 10 | X11: . | Y11: 10 | Z11: . | AA11: . | AB11: . | AC11: . | AD11: . | AE11: . | AF11: . | AG11: 130 | AH11: . | AI11: 130 | AJ11: .
A12: 2021 | B12: 590 | C12: City of Anaheim - (CA) | D12: CA | E12: CISO | F12: 431 | G12: 12 | H12: . | I12: . | J12: 443 | K12: 2.248 | L12: . | M12: . | N12: . | O12: 2.248 | P12: . | Q12: 8.4 | R12: . | S12: . | T12: 8.4 | U12: . | V12: . | W12: . | X12: . | Y12: . | Z12: 6.481 | AA12: . | AB12: . | AC12: . | AD12: 6.481 | AE12: . | AF12: . | AG12: . | AH12: . | AI12: . | AJ12: .
A13: 2021 | B13: 733 | C13: Appalachian Power Co | D13: VA | E13: PJM | F13: 4031 | G13: 0 | H13: 0 | I13: 0 | J13: 4031 | K13: 122 | L13: 0 | M13: 0 | N13: 0 | O13: 122 | P13: 4.5 | Q13: 0 | R13: 0 | S13: 0 | T13: 4.5 | U13: 4.5 | V13: 0 | W13: 0 | X13: 0 | Y13: 4.5 | Z13: 222 | AA13: 0 | AB13: 0 | AC13: 0 | AD13: 222 | AE13: 488 | AF13: 0 | AG13: 0 | AH13: 0 | AI13: 488 | AJ13: .
A14: 2021 | B14: 733 | C14: Appalachian Power Co | D14: WV | E14: PJM | F14: 2278 | G14: 0 | H14: 5 | I14: 0 | J14: 2283 | K14: 53 | L14: 0 | M14: 0 | N14: 0 | O14: 53 | P14: 1.8 | Q14: 0 | R14: 68.2 | S14: 0 | T14: 70 | U14: 1.8 | V14: 0 | W14: 0 | X14: 0 | Y14: 1.8 | Z14: 99 | AA14: 0 | AB14: 0 | AC14: 0 | AD14: 99 | AE14: 274 | AF14: 0 | AG14: 0 | AH14: 0 | AI14: 274 | AJ14: .
A15: 2021 | B15: 803 | C15: Arizona Public Service Co | D15: AZ | E15: AZPS | F15: 781061 | G15: 223 | H15: . | I15: . | J15: 781284 | K15: 781279 | L15: 538 | M15: . | N15: . | O15: 781817 | P15: 191.3 | Q15: 20.7 | R15: . | S15: . | T15: 212 | U15: 191.3 | V15: 20.7 | W15: . | X15: . | Y15: 212 | Z15: 5783.3 | AA15: . | AB15: . | AC15: . | AD15: 5783.3 | AE15: 3813.6 | AF15: 1008 | AG15: . | AH15: . | AI15: 4821.6 | AJ15: 6
A16: 2021 | B16: 807 | C16: Arkansas Electric Coop Corp | D16: AR | E16: MISO | F16: . | G16: . | H16: 8 | I16: . | J16: 8 | K16: . | L16: . | M16: . | N16: . | O16: . | P16: . | Q16: . | R16: 628 | S16: . | T16: 628 | U16: . | V16: . | W16: . | X16: . | Y16: . | Z16: . | AA16: . | AB16: 28299.451 | AC16: . | AD16: 28299.451 | AE16: . | AF16: . | AG16: . | AH16: . | AI16: . | AJ16: .
A17: 2021 | B17: 814 | C17: Entergy Arkansas LLC | D17: AR | E17: MISO | F17: 19655 | G17: 146 | H17: 1861 | I17: . | J17: 21662 | K17: 2169 | L17: 1047 | M17: 1767 | N17: . | O17: 4983 | P17: 21.2 | Q17: . | R17: 356.7 | S17: . | T17: 377.9 | U17: 21.2 | V17: . | W17: 22.3 | X17: . | Y17: 43.5 | Z17: 312 | AA17: 1183 | AB17: 434 | AC17: . | AD17: 1929 | AE17: 611 | AF17: 3430 | AG17: 3099 | AH17: . | AI17: 7140 | AJ17: .
A18: 2021 | B18: 1009 | C18: City of Austin - (MN) | D18: MN | E18: MISO | F18: 6802 | G18: 2 | H18: . | I18: . | J18: 6804 | K18: 148 | L18: 1.253 | M18: . | N18: . | O18: 149.253 | P18: 3.911 | Q18: 0.37 | R18: . | S18: . | T18: 4.281 | U18: 3.911 | V18: 0.301 | W18: . | X18: . | Y18: 4.212 | Z18: 0 | AA18: 17.638 | AB18: . | AC18: . | AD18: 17.638 | AE18: 0 | AF18: 0 | AG18: . | AH18: . | AI18: 0 | AJ18: .
A19: 2021 | B19: 1015 | C19: Austin Energy | D19: TX | E19: ERCO | F19: 81591 | G19: 4393 | H19: 1464 | I19: . | J19: 87448 | K19: 621.495 | L19: 1234.579 | M19: 411.526 | N19: . | O19: 2267.6 | P19: 92.927 | Q19: 5.26 | R19: 1.753 | S19: . | T19: 99.94 | U19: 43.776 | V19: 4.347 | W19: 1.403 | X19: . | Y19: 49.526 | Z19: 1779.615 | AA19: 712.405 | AB19: 237.468 | AC19: . | AD19: 2729.488 | AE19: 606.243 | AF19: 465.824 | AG19: 155.275 | AH19: . | AI19: 1227.342 | AJ19: 1119
A20: 2021 | B20: 1167 | C20: Baltimore Gas & Electric Co | D20: MD | E20: PJM | F20: 851307 | G20: . | H20: . | I20: . | J20: 851307 | K20: 97.755 | L20: . | M20: . | N20: . | O20: 97.755 | P20: 341.41 | Q20: . | R20: . | S20: . | T20: 341.41 | U20: 0 | V20: . | W20: . | X20: . | Y20: 0 | Z20: 26094.675 | AA20: . | AB20: . | AC20: . | AD20: 26094.675 | AE20: 10031.227 | AF20: . | AG20: . | AH20: . | AI20: 10031.227 | AJ20: .
A21: 2021 | B21: 1251 | C21: Barron Electric Coop | D21: WI | E21: MISO | F21: 6211 | G21: 253 | H21: 0 | I21: 0 | J21: 6464 | K21: 0 | L21: 0 | M21: 0 | N21: 0 | O21: 0 | P21: 6.748 | Q21: 3.903 | R21: 0 | S21: 0 | T21: 10.651 | U21: 4.58 | V21: 2.649 | W21: 0 | X21: 0 | Y21: 7.229 | Z21: 24 | AA21: 1 | AB21: 0 | AC21: 0 | AD21: 25 | AE21: 85 | AF21: 3 | AG21: 0 | AH21: 0 | AI21: 88 | AJ21: 9
A22: 2021 | B22: 1529 | C22: Beltrami Electric Coop, Inc | D22: MN | E22: MISO | F22: 7376 | G22: 205 | H22: . | I22: 0 | J22: 7581 | K22: 2.102 | L22: 60.84 | M22: 0 | N22: 0 | O22: 62.942 | P22: 219.96 | Q22: 6.36 | R22: 0 | S22: 0 | T22: 226.32 | U22: 28.59 | V22: 0.82 | W22: 0 | X22: 0 | Y22: 29.41 | Z22: 60.98 | AA22: 1.77 | AB22: 0 | AC22: 0 | AD22: 62.75 | AE22: 439.75 | AF22: 12.73 | AG22: 0 | AH22: 0 | AI22: 452.48 | AJ22: 0
A23: 2021 | B23: 1613 | C23: Berkeley Electric Coop Inc | D23: SC | E23: SC | F23: 448 | G23: . | H23: . | I23: . | J23: 448 | K23: 19.375 | L23: . | M23: . | N23: . | O23: 19.375 | P23: 0.398 | Q23: . | R23: . | S23: . | T23: 0.398 | U23: 0.398 | V23: . | W23: . | X23: . | Y23: 0.398 | Z23: 86.65 | AA23: . | AB23: . | AC23: . | AD23: 86.65 | AE23: 27 | AF23: . | AG23: . | AH23: . | AI23: 27 | AJ23: 205
A24: 2021 | B24: 1769 | C24: Black Hills Electric Coop, Inc | D24: SD | E24: SWPP | F24: 495 | G24: 20 | H24: 0 | I24: 0 | J24: 515 | K24: 4.264 | L24: 1 | M24: 0 | N24: 0 | O24: 5.264 | P24: 1.058 | Q24: 0.2 | R24: 0 | S24: 0 | T24: 1.258 | U24: 0.593 | V24: 0.2 | W24: 0 | X24: 0 | Y24: 0.793 | Z24: 0 | AA24: 0 | AB24: 0 | AC24: 0 | AD24: 0 | AE24: 5.2 | AF24: 0.5 | AG24: 0 | AH24: 0 | AI24: 5.7 | AJ24: 19
A25: 2021 | B25: 1889 | C25: Blue Ridge Elec Member Corp - (NC) | D25: NC | E25: DUK | F25: 39416 | G25: . | H25: . | I25: . | J25: 39416 | K25: 2.346 | L25: . | M25: . | N25: . | O25: 2.346 | P25: 3.32 | Q25: . | R25: . | S25: . | T25: 3.32 | U25: 2.598 | V25: . | W25: . | X25: . | Y25: 2.598 | Z25: 23.872 | AA25: . | AB25: . | AC25: . | AD25: 23.872 | AE25: . | AF25: . | AG25: . | AH25: . | AI25: . | AJ25: .
A26: 2021 | B26: 2212 | C26: Broad River Electric Coop, Inc | D26: NC | E26: DUK | F26: 15 | G26: . | H26: . | I26: . | J26: 15 | K26: . | L26: . | M26: . | N26: . | O26: . | P26: 0.016 | Q26: . | R26: . | S26: . | T26: 0.016 | U26: 0.016 | V26: . | W26: . | X26: . | Y26: 0.016 | Z26: 0.75 | AA26: . | AB26: . | AC26: . | AD26: 0.75 | AE26: . | AF26: . | AG26: . | AH26: . | AI26: . | AJ26: .
A27: 2021 | B27: 2678 | C27: C & L Electric Coop Corp | D27: AR | E27: MISO | F27: . | G27: 29 | H27: . | I27: . | J27: 29 | K27: . | L27: . | M27: . | N27: . | O27: . | P27: . | Q27: 0.905 | R27: . | S27: . | T27: 0.905 | U27: . | V27: 0.472 | W27: . | X27: . | Y27: 0.472 | Z27: . | AA27: 10.369 | AB27: . | AC27: . | AD27: 10.369 | AE27: . | AF27: . | AG27: . | AH27: . | AI27: . | AJ27: .
A28: 2021 | B28: 2985 | C28: Capital Electric Coop, Inc | D28: ND | E28: SWPP | F28: 7557 | G28: 10 | H28: 24 | I28: . | J28: 7591 | K28: . | L28: . | M28: . | N28: . | O28: . | P28: 13.934 | Q28: 5.796 | R28: 6.133 | S28: . | T28: 25.863 | U28: 11.06 | V28: 5.767 | W28: 6.133 | X28: . | Y28: 22.96 | Z28: 142.744 | AA28: 64.608 | AB28: 71.76 | AC28: . | AD28: 279.112 | AE28: 164.79 | AF28: 0.218 | AG28: 0.523 | AH28: . | AI28: 165.531 | AJ28: 66
A29: 2021 | B29: 3046 | C29: Duke Energy Progress - (NC) | D29: NC | E29: CPLE | F29: 198051 | G29: 2755 | H29: . | I29: . | J29: 200806 | K29: . | L29: . | M29: . | N29: . | O29: . | P29: 378.128 | Q29: 148.813 | R29: . | S29: . | T29: 526.941 | U29: . | V29: . | W29: . | X29: . | Y29: . | Z29: 5237.116 | AA29: 1982.709 | AB29: . | AC29: . | AD29: 7219.825 | AE29: 5855.948 | AF29: 157.254 | AG29: . | AH29: . | AI29: 6013.202 | AJ29: .
A30: 2021 | B30: 3046 | C30: Duke Energy Progress - (NC) | D30: SC | E30: CPLE | F30: 16579 | G30: 282 | H30: . | I30: . | J30: 16861 | K30: . | L30: . | M30: . | N30: . | O30: . | P30: 32.01 | Q30: 100.92 | R30: . | S30: . | T30: 132.93 | U30: . | V30: . | W30: . | X30: . | Y30: . | Z30: 758 | AA30: 287 | AB30: . | AC30: . | AD30: 1045 | AE30: 847 | AF30: 23 | AG30: . | AH30: . | AI30: 870 | AJ30: .
A31: 2021 | B31: 3107 | C31: Carteret-Craven El Member Corp | D31: NC | E31: CPLE | F31: 1435 | G31: 36 | H31: . | I31: . | J31: 1471 | K31: 820.07 | L31: 48 | M31: . | N31: . | O31: 868.07 | P31: 0.034 | Q31: 2.02 | R31: . | S31: . | T31: 2.054 | U31: 0.034 | V31: 2.02 | W31: . | X31: . | Y31: 2.054 | Z31: 0 | AA31: 64.944 | AB31: . | AC31: . | AD31: 64.944 | AE31: 0 | AF31: 3.24 | AG31: . | AH31: . | AI31: 3.24 | AJ31: .
A32: 2021 | B32: 3205 | C32: Cedar-Knox Public Power Dist | D32: NE | E32: SWPP | F32: . | G32: . | H32: 734 | I32: . | J32: 734 | K32: . | L32: . | M32: . | N32: . | O32: . | P32: . | Q32: . | R32: 45.063 | S32: . | T32: 45.063 | U32: . | V32: . | W32: 23.357 | X32: . | Y32: 23.357 | Z32: . | AA32: . | AB32: . | AC32: . | AD32: . | AE32: . | AF32: . | AG32: 121.519 | AH32: . | AI32: 121.519 | AJ32: .
A33: 2021 | B33: 3222 | C33: Central Alabama Electric Coop | D33: AL | E33: SOCO | F33: 166 | G33: . | H33: . | I33: . | J33: 166 | K33: 136.972 | L33: . | M33: . | N33: . | O33: 136.972 | P33: 0.278 | Q33: . | R33: . | S33: . | T33: 0.278 | U33: 0.278 | V33: . | W33: . | X33: . | Y33: 0.278 | Z33: . | AA33: . | AB33: . | AC33: . | AD33: . | AE33: 17 | AF33: . | AG33: . | AH33: . | AI33: 17 | AJ33: .
A34: 2021 | B34: 3248 | C34: Central Georgia El Member Corp | D34: GA | E34: SOCO | F34: 3339 | G34: . | H34: . | I34: . | J34: 3339 | K34: 188 | L34: . | M34: . | N34: . | O34: 188 | P34: 7 | Q34: . | R34: . | S34: . | T34: 7 | U34: 4 | V34: . | W34: . | X34: . | Y34: 4 | Z34: 73 | AA34: . | AB34: . | AC34: . | AD34: 73 | AE34: 133 | AF34: . | AG34: . | AH34: . | AI34: 133 | AJ34: 529
A35: 2021 | B35: 3249 | C35: Central Hudson Gas & Elec Corp | D35: NY | E35: NYIS | F35: 3901 | G35: 10 | H35: 4 | I35: . | J35: 3915 | K35: 17.204 | L35: 1.084 | M35: 3.065 | N35: . | O35: 21.353 | P35: 4.301 | Q35: 1.084 | R35: 3.065 | S35: . | T35: 8.45 | U35: 4.301 | V35: 1.084 | W35: 3.065 | X35: . | Y35: 8.45 | Z35: . | AA35: . | AB35: . | AC35: . | AD35: . | AE35: . | AF35: . | AG35: . | AH35: . | AI35: . | AJ35: .
A36: 2021 | B36: 3278 | C36: AEP Texas Central Company | D36: TX | E36: ERCO | F36: 0 | G36: 68 | H36: 0 | I36: 0 | J36: 68 | K36: 0 | L36: 19 | M36: 0 | N36: 0 | O36: 19 | P36: 0 | Q36: 28.4 | R36: 0 | S36: 0 | T36: 28.4 | U36: 0 | V36: 19.4 | W36: 0 | X36: 0 | Y36: 19.4 | Z36: 0 | AA36: 500 | AB36: 0 | AC36: 0 | AD36: 500 | AE36: 0 | AF36: 54 | AG36: 0 | AH36: 0 | AI36: 54 | AJ36: .
A37: 2021 | B37: 3279 | C37: Central Power Elec Coop, Inc | D37: ND | E37: SWPP | F37: . | G37: . | H37: . | I37: . | J37: . | K37: 2838 | L37: 560.6 | M37: . | N37: . | O37: 3398.6 | P37: 13.38 | Q37: 1.372 | R37: . | S37: . | T37: 14.752 | U37: 13.38 | V37: 1.372 | W37: . | X37: . | Y37: 14.752 | Z37: 284.085 | AA37: 366.379 | AB37: 28.883 | AC37: . | AD37: 679.347 | AE37: . | AF37: . | AG37: . | AH37: . | AI37: . | AJ37: .
A38: 2021 | B38: 3502 | C38: Choctawhatche Elec Coop, Inc | D38: FL | E38: SOCO | F38: 52926 | G38: 7662 | H38: 0 | I38: 0 | J38: 60588 | K38: 0 | L38: 0 | M38: 0 | N38: 0 | O38: 0 | P38: 40.28 | Q38: 5.85 | R38: 0 | S38: 0 | T38: 46.13 | U38: 40.28 | V38: 5.85 | W38: 0 | X38: 0 | Y38: 46.13 | Z38: 23.18 | AA38: 0 | AB38: 0 | AC38: 0 | AD38: 23.18 | AE38: 5.8 | AF38: 0.2 | AG38: 0 | AH38: 0 | AI38: 6 | AJ38: .
A39: 2021 | B39: 3503 | C39: Choptank Electric Cooperative, Inc | D39: MD | E39: PJM | F39: 0 | G39: 187 | H39: 8 | I39: 0 | J39: 195 | K39: 0 | L39: 0 | M39: 0 | N39: 0 | O39: 0 | P39: 0 | Q39: 3.926 | R39: 8.753 | S39: 0 | T39: 12.679 | U39: 0 | V39: 0 | W39: 0 | X39: 0 | Y39: 0 | Z39: . | AA39: . | AB39: . | AC39: . | AD39: . | AE39: . | AF39: 0.77 | AG39: 0.03 | AH39: . | AI39: 0.8 | AJ39: .
A40: 2021 | B40: 3755 | C40: Cleveland Electric Illum Co | D40: OH | E40: PJM | F40: 0 | G40: 0 | H40: 4 | I40: 0 | J40: 4 | K40: 0 | L40: 0 | M40: 0 | N40: 0 | O40: 0 | P40: 0 | Q40: 0 | R40: 189.722 | S40: 0 | T40: 189.722 | U40: 0 | V40: 0 | W40: 189.722 | X40: 0 | Y40: 189.722 | Z40: 0 | AA40: 0 | AB40: 8356.159 | AC40: 0 | AD40: 8356.159 | AE40: 0 | AF40: 0 | AG40: 0 | AH40: 0 | AI40: 0 | AJ40: .
...

Sheet Calculation
A1: Total MWh Demand Response | B1: =SUM('Form 861'!O:O) -> 1188725.9
A2: Total MW Actual Peak Demand Savings | B2: =SUM('Form 861'!Y:Y) -> 13146.531
A3: Hours per Year | B3: 8760
A5: Calculated Capacity Factor | B5: =B1/(B2*B3) -> 0.010322062

Sheet DRCF
A1: (dmnl) | B1: 2018 | C1: 2019 | D1: 2020 | E1: 2021 | F1: 2022 | G1: 2023 | H1: 2024 | I1: 2025 | J1: 2026 | K1: 2027 | L1: 2028 | M1: 2029 | N1: 2030 | O1: 2031 | P1: 2032 | Q1: 2033 | R1: 2034 | S1: 2035 | T1: 2036 | U1: 2037 | V1: 2038 | W1: 2039 | X1: 2040 | Y1: 2041 | Z1: 2042 | AA1: 2043 | AB1: 2044 | AC1: 2045 | AD1: 2046 | AE1: 2047 | AF1: 2048 | AG1: 2049 | AH1: 2050
A2: DR Capacity Factor | B2: =Calculation!$B$5 -> 0.010322062 | C2: =Calculation!$B$5 -> 0.010322062 | D2: =Calculation!$B$5 -> 0.010322062 | E2: =Calculation!$B$5 -> 0.010322062 | F2: =Calculation!$B$5 -> 0.010322062 | G2: =Calculation!$B$5 -> 0.010322062 | H2: =Calculation!$B$5 -> 0.010322062 | I2: =Calculation!$B$5 -> 0.010322062 | ... AH2: =Calculation!$B$5 -> 0.010322062
