Workbook

Sheet About
A1: HYECFCA Historical Year Electricity Capacity Factor Calibration Adjustment | B1: Iowa | C1: 2026-09-02 | K1: Alabama | L1: AL
A2: Active state: cell B1 (full state name). B2 resolves the abbreviation used by the calc tabs. | B2: =INDEX(L1:L48,MATCH(B1,K1:K48,0)) -> IA | K2: Arizona | L2: AZ
K3: Arkansas | L3: AR
A4: Sources: | B4: EPS SYSHECF + SHELF inputs (state-eps-data, compiled verbatim); EIA-923 2025 Early Release + EIA-860 2025 ER (tech-level, BHRaSYC include filter); BHRaSYC-embedded national 2024 Form 923/860 for 2024 CFs. | K4: California | L4: CA
A5: Method: | B5: HYECFCA 2025 multiplier = EIA CF 2025 / EPS day-weighted avg CF (CF_summary col H), applied to ALL plant types (staff direction 2026-07-20). Techs with no 2025 data (or not modeled in the state) get the Keys default (1.0). Years 2026-2050 = 1.0. | K5: Colorado | L5: CO
A6: Basis: | B6: CONFIRMED post-SYSHECF-rework (staff decision 2026-07-21): SYSHECF now carries mean(2024,2025) observed CF levels, and HYECFCA deliberately keeps the EIA-2025/EPS ratio on top -- so the START YEAR is anchored to 2025 actuals (including 2025 refueling outages and water-year conditions), while 2026+ revert to the two-year-mean basis when the multiplier returns to 1.0. Median ratio post-rework = 1.002; the residual spread IS the 2025-vs-mean difference, not error. | K6: Connecticut | L6: CT
A7: NOTE: | B7: For cost-dispatched techs (coal, gas CC/steam, oil with BGDPbES=0) the observed CF measures UTILIZATION, not availability, so their ratios (typically <1) set availability equal to the 2025 dispatch outcome. This removes dispatch headroom above 2025 utilization: demand growth, retirement backfill, and policy-driven redispatch (e.g. carbon-price coal<->gas swings) cannot lift these fleets above their 2025 CFs. Deliberate staff choice, documented for traceability. | K7: Delaware | L7: DE
A8: Caveats: | B8: CF_summary col P flags "over" where ratio x max hourly SYSHECF CF > 100% -- those state/tech ratios need a model-side clamp or a manual trim. Ratios inherit the actual-CF artifacts documented on the review About tab: partial-year 2025 builds bias ratios DOWN (small new fleets), nuclear refueling years bias DOWN (MO, WA), 2025 was a thin PNW water year. Consider the EIA-2024/EPS ratio (CF_summary col G) or the mean before adopting; DRAFT for staff review, verify against primary sources. | K8: Florida | L8: FL
A9: Rebuild: | B9: python outputs/HYECFCA/_build_hyecfca_workbook.py | K9: Georgia | L9: GA
K10: Idaho | L10: ID
K11: Illinois | L11: IL
K12: Indiana | L12: IN
K13: Iowa | L13: IA
K14: Kansas | L14: KS
K15: Kentucky | L15: KY
K16: Louisiana | L16: LA
K17: Maine | L17: ME
K18: Maryland | L18: MD
K19: Massachusetts | L19: MA
K20: Michigan | L20: MI
K21: Minnesota | L21: MN
... K48: Wyoming | L48: WY

Sheet Keys
A1: category | B1: key | C1: value | D1: description
A2: gate | B2: default_multiplier | C2: 1 | D2: Multiplier for missing-data techs and all years after 2025
A3: year | B3: ratio_year | C3: 2025 | D3: Only this year column carries the calibration ratio
A4: unit | B4: hours_per_year | C4: 8760 | D4: Hours in a year (365 SHELF days x 24 h); the CF denominator basis, same as EIA
A5: unit | B5: mw_per_gw | C5: 1000 | D5: MW per GW: converts EIA GWh over MW-capacity into a capacity factor
A6: flag | B6: over_flag | C6: over | D6: Flag string written by the CF_summary over-100%-of-max-hourly check column

Sheet SHELF_days
A1: state | B1: timeslice | C1: days | D1: key (state|timeslice)
A2: AL | B2: Winter | C2: 37 | D2: =A2&"|"&B2 -> AL|Winter
A3: AL | B3: Spring | C3: 145 | D3: =A3&"|"&B3 -> AL|Spring
A4: AL | B4: Summer | C4: 70 | D4: =A4&"|"&B4 -> AL|Summer
A5: AL | B5: Fall | C5: 96 | D5: =A5&"|"&B5 -> AL|Fall
A6: AL | B6: Summer Peak | C6: 14 | D6: =A6&"|"&B6 -> AL|Summer Peak
A7: AL | B7: Winter Peak | C7: 3 | D7: =A7&"|"&B7 -> AL|Winter Peak
A8: AR | B8: Winter | C8: 35 | D8: =A8&"|"&B8 -> AR|Winter
A9: AR | B9: Spring | C9: 92 | D9: =A9&"|"&B9 -> AR|Spring
A10: AR | B10: Summer | C10: 56 | D10: =A10&"|"&B10 -> AR|Summer
A11: AR | B11: Fall | C11: 146 | D11: =A11&"|"&B11 -> AR|Fall
A12: AR | B12: Summer Peak | C12: 20 | D12: =A12&"|"&B12 -> AR|Summer Peak
A13: AR | B13: Winter Peak | C13: 16 | D13: =A13&"|"&B13 -> AR|Winter Peak
... A289: WY | B289: Winter Peak | C289: 9 | D289: =A289&"|"&B289 -> WY|Winter Peak

Sheet SYSHECF
A1: state | B1: tech | C1: timeslice | D1: Hour0 | E1: Hour1 | F1: Hour2 | G1: Hour3 | H1: Hour4 | I1: Hour5 | J1: Hour6 | K1: Hour7 | L1: Hour8 | M1: Hour9 | N1: Hour10 | O1: Hour11 | P1: Hour12 | Q1: Hour13 | R1: Hour14 | S1: Hour15 | T1: Hour16 | U1: Hour17 | V1: Hour18 | W1: Hour19 | X1: Hour20 | Y1: Hour21 | Z1: Hour22 | AA1: Hour23 | AB1: sum_24h | AC1: days | AD1: cf_hours (=sum x days) | AE1: max_24h
A2: AL | B2: biomass ccs | C2: Winter | D2: 0.8 | E2: 0.8 | F2: 0.8 | G2: 0.8 | H2: 0.8 | I2: 0.8 | J2: 0.8 | K2: 0.8 | L2: 0.8 | M2: 0.8 | N2: 0.8 | O2: 0.8 | P2: 0.8 | Q2: 0.8 | R2: 0.8 | S2: 0.8 | T2: 0.8 | U2: 0.8 | V2: 0.8 | W2: 0.8 | X2: 0.8 | Y2: 0.8 | Z2: 0.8 | AA2: 0.8 | AB2: =SUM(D2:AA2) -> 19.2 | AC2: =INDEX(SHELF_days!$C$2:$C$289,MATCH(A2&"|"&C2,SHELF_days!$D$2:$D$289,0)) -> 37 | AD2: =AB2*AC2 -> 710.4 | AE2: =MAX(D2:AA2) -> 0.8
A3: AL | B3: biomass ccs | C3: Spring | D3: 0.8 | E3: 0.8 | F3: 0.8 | G3: 0.8 | H3: 0.8 | I3: 0.8 | J3: 0.8 | K3: 0.8 | L3: 0.8 | M3: 0.8 | N3: 0.8 | O3: 0.8 | P3: 0.8 | Q3: 0.8 | R3: 0.8 | S3: 0.8 | T3: 0.8 | U3: 0.8 | V3: 0.8 | W3: 0.8 | X3: 0.8 | Y3: 0.8 | Z3: 0.8 | AA3: 0.8 | AB3: =SUM(D3:AA3) -> 19.2 | AC3: =INDEX(SHELF_days!$C$2:$C$289,MATCH(A3&"|"&C3,SHELF_days!$D$2:$D$289,0)) -> 145 | AD3: =AB3*AC3 -> 2784 | AE3: =MAX(D3:AA3) -> 0.8
A4: AL | B4: biomass ccs | C4: Summer | D4: 0.8 | E4: 0.8 | F4: 0.8 | G4: 0.8 | H4: 0.8 | I4: 0.8 | J4: 0.8 | K4: 0.8 | L4: 0.8 | M4: 0.8 | N4: 0.8 | O4: 0.8 | P4: 0.8 | Q4: 0.8 | R4: 0.8 | S4: 0.8 | T4: 0.8 | U4: 0.8 | V4: 0.8 | W4: 0.8 | X4: 0.8 | Y4: 0.8 | Z4: 0.8 | AA4: 0.8 | AB4: =SUM(D4:AA4) -> 19.2 | AC4: =INDEX(SHELF_days!$C$2:$C$289,MATCH(A4&"|"&C4,SHELF_days!$D$2:$D$289,0)) -> 70 | AD4: =AB4*AC4 -> 1344 | AE4: =MAX(D4:AA4) -> 0.8
A5: AL | B5: biomass ccs | C5: Fall | D5: 0.8 | E5: 0.8 | F5: 0.8 | G5: 0.8 | H5: 0.8 | I5: 0.8 | J5: 0.8 | K5: 0.8 | L5: 0.8 | M5: 0.8 | N5: 0.8 | O5: 0.8 | P5: 0.8 | Q5: 0.8 | R5: 0.8 | S5: 0.8 | T5: 0.8 | U5: 0.8 | V5: 0.8 | W5: 0.8 | X5: 0.8 | Y5: 0.8 | Z5: 0.8 | AA5: 0.8 | AB5: =SUM(D5:AA5) -> 19.2 | AC5: =INDEX(SHELF_days!$C$2:$C$289,MATCH(A5&"|"&C5,SHELF_days!$D$2:$D$289,0)) -> 96 | AD5: =AB5*AC5 -> 1843.2 | AE5: =MAX(D5:AA5) -> 0.8
A6: AL | B6: biomass ccs | C6: Summer Peak | D6: 0.8 | E6: 0.8 | F6: 0.8 | G6: 0.8 | H6: 0.8 | I6: 0.8 | J6: 0.8 | K6: 0.8 | L6: 0.8 | M6: 0.8 | N6: 0.8 | O6: 0.8 | P6: 0.8 | Q6: 0.8 | R6: 0.8 | S6: 0.8 | T6: 0.8 | U6: 0.8 | V6: 0.8 | W6: 0.8 | X6: 0.8 | Y6: 0.8 | Z6: 0.8 | AA6: 0.8 | AB6: =SUM(D6:AA6) -> 19.2 | AC6: =INDEX(SHELF_days!$C$2:$C$289,MATCH(A6&"|"&C6,SHELF_days!$D$2:$D$289,0)) -> 14 | AD6: =AB6*AC6 -> 268.8 | AE6: =MAX(D6:AA6) -> 0.8
A7: AL | B7: biomass ccs | C7: Winter Peak | D7: 0.8 | E7: 0.8 | F7: 0.8 | G7: 0.8 | H7: 0.8 | I7: 0.8 | J7: 0.8 | K7: 0.8 | L7: 0.8 | M7: 0.8 | N7: 0.8 | O7: 0.8 | P7: 0.8 | Q7: 0.8 | R7: 0.8 | S7: 0.8 | T7: 0.8 | U7: 0.8 | V7: 0.8 | W7: 0.8 | X7: 0.8 | Y7: 0.8 | Z7: 0.8 | AA7: 0.8 | AB7: =SUM(D7:AA7) -> 19.2 | AC7: =INDEX(SHELF_days!$C$2:$C$289,MATCH(A7&"|"&C7,SHELF_days!$D$2:$D$289,0)) -> 3 | AD7: =AB7*AC7 -> 57.6 | AE7: =MAX(D7:AA7) -> 0.8
A8: AL | B8: biomass | C8: Winter | D8: 0.5102 | E8: 0.5102 | F8: 0.5102 | G8: 0.5102 | H8: 0.5102 | I8: 0.5102 | J8: 0.5102 | K8: 0.5102 | L8: 0.5102 | M8: 0.5102 | N8: 0.5102 | O8: 0.5102 | P8: 0.5102 | Q8: 0.5102 | R8: 0.5102 | S8: 0.5102 | T8: 0.5102 | U8: 0.5102 | V8: 0.5102 | W8: 0.5102 | X8: 0.5102 | Y8: 0.5102 | Z8: 0.5102 | AA8: 0.5102 | AB8: =SUM(D8:AA8) -> 12.2448 | AC8: =INDEX(SHELF_days!$C$2:$C$289,MATCH(A8&"|"&C8,SHELF_days!$D$2:$D$289,0)) -> 37 | AD8: =AB8*AC8 -> 453.0576 | AE8: =MAX(D8:AA8) -> 0.5102
A9: AL | B9: biomass | C9: Spring | D9: 0.5102 | E9: 0.5102 | F9: 0.5102 | G9: 0.5102 | H9: 0.5102 | I9: 0.5102 | J9: 0.5102 | K9: 0.5102 | L9: 0.5102 | M9: 0.5102 | N9: 0.5102 | O9: 0.5102 | P9: 0.5102 | Q9: 0.5102 | R9: 0.5102 | S9: 0.5102 | T9: 0.5102 | U9: 0.5102 | V9: 0.5102 | W9: 0.5102 | X9: 0.5102 | Y9: 0.5102 | Z9: 0.5102 | AA9: 0.5102 | AB9: =SUM(D9:AA9) -> 12.2448 | AC9: =INDEX(SHELF_days!$C$2:$C$289,MATCH(A9&"|"&C9,SHELF_days!$D$2:$D$289,0)) -> 145 | AD9: =AB9*AC9 -> 1775.496 | AE9: =MAX(D9:AA9) -> 0.5102
A10: AL | B10: biomass | C10: Summer | D10: 0.5102 | E10: 0.5102 | F10: 0.5102 | G10: 0.5102 | H10: 0.5102 | I10: 0.5102 | J10: 0.5102 | K10: 0.5102 | L10: 0.5102 | M10: 0.5102 | N10: 0.5102 | O10: 0.5102 | P10: 0.5102 | Q10: 0.5102 | R10: 0.5102 | S10: 0.5102 | T10: 0.5102 | U10: 0.5102 | V10: 0.5102 | W10: 0.5102 | X10: 0.5102 | Y10: 0.5102 | Z10: 0.5102 | AA10: 0.5102 | AB10: =SUM(D10:AA10) -> 12.2448 | AC10: =INDEX(SHELF_days!$C$2:$C$289,MATCH(A10&"|"&C10,SHELF_days!$D$2:$D$289,0)) -> 70 | AD10: =AB10*AC10 -> 857.136 | AE10: =MAX(D10:AA10) -> 0.5102
A11: AL | B11: biomass | C11: Fall | D11: 0.5102 | E11: 0.5102 | F11: 0.5102 | G11: 0.5102 | H11: 0.5102 | I11: 0.5102 | J11: 0.5102 | K11: 0.5102 | L11: 0.5102 | M11: 0.5102 | N11: 0.5102 | O11: 0.5102 | P11: 0.5102 | Q11: 0.5102 | R11: 0.5102 | S11: 0.5102 | T11: 0.5102 | U11: 0.5102 | V11: 0.5102 | W11: 0.5102 | X11: 0.5102 | Y11: 0.5102 | Z11: 0.5102 | AA11: 0.5102 | AB11: =SUM(D11:AA11) -> 12.2448 | AC11: =INDEX(SHELF_days!$C$2:$C$289,MATCH(A11&"|"&C11,SHELF_days!$D$2:$D$289,0)) -> 96 | AD11: =AB11*AC11 -> 1175.5008 | AE11: =MAX(D11:AA11) -> 0.5102
A12: AL | B12: biomass | C12: Summer Peak | D12: 0.5102 | E12: 0.5102 | F12: 0.5102 | G12: 0.5102 | H12: 0.5102 | I12: 0.5102 | J12: 0.5102 | K12: 0.5102 | L12: 0.5102 | M12: 0.5102 | N12: 0.5102 | O12: 0.5102 | P12: 0.5102 | Q12: 0.5102 | R12: 0.5102 | S12: 0.5102 | T12: 0.5102 | U12: 0.5102 | V12: 0.5102 | W12: 0.5102 | X12: 0.5102 | Y12: 0.5102 | Z12: 0.5102 | AA12: 0.5102 | AB12: =SUM(D12:AA12) -> 12.2448 | AC12: =INDEX(SHELF_days!$C$2:$C$289,MATCH(A12&"|"&C12,SHELF_days!$D$2:$D$289,0)) -> 14 | AD12: =AB12*AC12 -> 171.4272 | AE12: =MAX(D12:AA12) -> 0.5102
A13: AL | B13: biomass | C13: Winter Peak | D13: 0.5102 | E13: 0.5102 | F13: 0.5102 | G13: 0.5102 | H13: 0.5102 | I13: 0.5102 | J13: 0.5102 | K13: 0.5102 | L13: 0.5102 | M13: 0.5102 | N13: 0.5102 | O13: 0.5102 | P13: 0.5102 | Q13: 0.5102 | R13: 0.5102 | S13: 0.5102 | T13: 0.5102 | U13: 0.5102 | V13: 0.5102 | W13: 0.5102 | X13: 0.5102 | Y13: 0.5102 | Z13: 0.5102 | AA13: 0.5102 | AB13: =SUM(D13:AA13) -> 12.2448 | AC13: =INDEX(SHELF_days!$C$2:$C$289,MATCH(A13&"|"&C13,SHELF_days!$D$2:$D$289,0)) -> 3 | AD13: =AB13*AC13 -> 36.7344 | AE13: =MAX(D13:AA13) -> 0.5102
... A7489: WY | B7489: natural gas steam turbine | C7489: Winter Peak | D7489: 0.3247 | E7489: 0.3247 | F7489: 0.3247 | G7489: 0.3247 | H7489: 0.3247 | I7489: 0.3247 | J7489: 0.3247 | K7489: 0.3247 | L7489: 0.3247 | M7489: 0.3247 | N7489: 0.3247 | O7489: 0.3247 | P7489: 0.3247 | Q7489: 0.3247 | R7489: 0.3247 | S7489: 0.3247 | T7489: 0.3247 | U7489: 0.3247 | V7489: 0.3247 | W7489: 0.3247 | X7489: 0.3247 | Y7489: 0.3247 | Z7489: 0.3247 | AA7489: 0.3247 | AB7489: =SUM(D7489:AA7489) -> 7.7928 | AC7489: =INDEX(SHELF_days!$C$2:$C$289,MATCH(A7489&"|"&C7489,SHELF_days!$D$2:$D$289,0)) -> 9 | AD7489: =AB7489*AC7489 -> 70.1352 | AE7489: =MAX(D7489:AA7489) -> 0.3247

Sheet EIA_2025
A1: state | B1: eps_tech | C1: gen_2025_twh (923ER) | D1: cap_2025_gw (860ER net summer) | E1: key (state|tech)
A2: AL | B2: biomass | C2: 0.0243 | D2: 0.0064 | E2: =A2&"|"&B2 -> AL|biomass
A3: AL | B3: hard coal | C3: 21.6615 | D3: 4.728 | E3: =A3&"|"&B3 -> AL|hard coal
A4: AL | B4: hydro | C4: 8.5829 | D4: 3.2906 | E4: =A4&"|"&B4 -> AL|hydro
A5: AL | B5: natural gas combined cycle | C5: 59.151 | D5: 11.072 | E5: =A5&"|"&B5 -> AL|natural gas combined cycle
A6: AL | B6: natural gas peaker | C6: 1.2251 | D6: 3.2452 | E6: =A6&"|"&B6 -> AL|natural gas peaker
A7: AL | B7: natural gas steam turbine | C7: 3.4291 | D7: 1.6961 | E7: =A7&"|"&B7 -> AL|natural gas steam turbine
A8: AL | B8: nuclear | C8: 42.6727 | D8: 5.4527 | E8: =A8&"|"&B8 -> AL|nuclear
A9: AL | B9: other | C9: -0.0024 | D9: 0.001 | E9: =A9&"|"&B9 -> AL|other
A10: AL | B10: petroleum | C10: 0.0075 | D10: 0.0426 | E10: =A10&"|"&B10 -> AL|petroleum
A11: AL | B11: solar pv | C11: 1.3233 | D11: 0.7435 | E11: =A11&"|"&B11 -> AL|solar pv
A12: AR | B12: biomass | C12: 0.0298 | D12: 0.0088 | E12: =A12&"|"&B12 -> AR|biomass
A13: AR | B13: hard coal | C13: 20.3432 | D13: 4.7427 | E13: =A13&"|"&B13 -> AR|hard coal
... A530: WY | B530: solar pv | C530: 0.496 | D530: 0.242 | E530: =A530&"|"&B530 -> WY|solar pv

Sheet EIA_2024
A1: state | B1: eps_tech | C1: basis | D1: gen_2024_twh (923 via BHRaSYC) | E1: cap_2024_gw (860 net summer via BHRaSYC) | F1: key (state|tech)
A2: AL | B2: biomass | C2: BHRaSYC 2024 (tech-level) | D2: 0.0368 | E2: 0.0064 | F2: =A2&"|"&B2 -> AL|biomass
A3: AL | B3: hard coal | C3: BHRaSYC 2024 (tech-level) | D3: 20.9362 | E3: 4.728 | F3: =A3&"|"&B3 -> AL|hard coal
A4: AL | B4: hydro | C4: BHRaSYC 2024 (tech-level) | D4: 8.3573 | E4: 3.2906 | F4: =A4&"|"&B4 -> AL|hydro
A5: AL | B5: natural gas combined cycle | C5: BHRaSYC 2024 (tech-level) | D5: 58.5823 | E5: 11.072 | F5: =A5&"|"&B5 -> AL|natural gas combined cycle
A6: AL | B6: natural gas peaker | C6: BHRaSYC 2024 (tech-level) | D6: 1.0923 | E6: 3.2202 | F6: =A6&"|"&B6 -> AL|natural gas peaker
A7: AL | B7: natural gas steam turbine | C7: BHRaSYC 2024 (tech-level) | D7: 3.1471 | E7: 1.6961 | F7: =A7&"|"&B7 -> AL|natural gas steam turbine
A8: AL | B8: nuclear | C8: BHRaSYC 2024 (tech-level) | D8: 44.4872 | E8: 5.4527 | F8: =A8&"|"&B8 -> AL|nuclear
A9: AL | B9: other | C9: BHRaSYC 2024 (tech-level) | D9: -0.0016 | E9: 0.026 | F9: =A9&"|"&B9 -> AL|other
A10: AL | B10: petroleum | C10: BHRaSYC 2024 (tech-level) | D10: 0.0034 | E10: 0.0426 | F10: =A10&"|"&B10 -> AL|petroleum
A11: AL | B11: solar pv | C11: BHRaSYC 2024 (tech-level) | D11: 1.2551 | E11: 0.6635 | F11: =A11&"|"&B11 -> AL|solar pv
A12: AR | B12: biomass | C12: BHRaSYC 2024 (tech-level) | D12: 0.0272 | E12: 0.0088 | F12: =A12&"|"&B12 -> AR|biomass
A13: AR | B13: hard coal | C13: BHRaSYC 2024 (tech-level) | D13: 15.628 | E13: 4.7296 | F13: =A13&"|"&B13 -> AR|hard coal
... A514: WY | B514: solar pv | C514: BHRaSYC 2024 (tech-level) | D514: 0.4231 | E514: 0.242 | F514: =A514&"|"&B514 -> WY|solar pv

Sheet CF_summary
A1: state | B1: tech | C1: check type | D1: EPS avg CF (day-weighted) | E1: EIA CF 2024 | F1: EIA CF 2025 | G1: EIA 2024 / EPS | H1: EIA 2025 / EPS | I1: gen 2024 (TWh) | J1: cap 2024 (GW) | K1: gen 2025 (TWh) | L1: cap 2025 (GW) | M1: 2024 basis | N1: key (state|tech) | O1: max hourly CF (SYSHECF) | P1: over (ratio x max hourly > 100%)
A2: AL | B2: biomass | C2: ceiling check | D2: =SUMIFS(SYSHECF!$AD$2:$AD$7489,SYSHECF!$A$2:$A$7489,$A2,SYSHECF!$B$2:$B$7489,$B2)/Keys!$C$4 -> 0.5102 | E2: =IF(OR($J2="",$J2=0),"",$I2*Keys!$C$5/($J2*Keys!$C$4)) -> 0.65639269 | F2: =IF(OR($L2="",$L2=0),"",$K2*Keys!$C$5/($L2*Keys!$C$4)) -> 0.43343322 | G2: =IF(OR($E2="",$D2=0),"",$E2/$D2) -> 1.28654 | H2: =IF(OR($F2="",$D2=0),"",$F2/$D2) -> 0.84953591 | I2: =IFERROR(INDEX(EIA_2024!$D$2:$D$514,MATCH($A2&"|"&$B2,EIA_2024!$F$2:$F$514,0)),"") -> 0.0368 | J2: =IFERROR(INDEX(EIA_2024!$E$2:$E$514,MATCH($A2&"|"&$B2,EIA_2024!$F$2:$F$514,0)),"") -> 0.0064 | K2: =IFERROR(INDEX(EIA_2025!$C$2:$C$530,MATCH($A2&"|"&$B2,EIA_2025!$E$2:$E$530,0)),"") -> 0.0243 | L2: =IFERROR(INDEX(EIA_2025!$D$2:$D$530,MATCH($A2&"|"&$B2,EIA_2025!$E$2:$E$530,0)),"") -> 0.0064 | M2: =IFERROR(INDEX(EIA_2024!$C$2:$C$514,MATCH($A2&"|"&$B2,EIA_2024!$F$2:$F$514,0)),"") -> BHRaSYC 2024 (tech-level) | N2: =A2&"|"&B2 -> AL|biomass | O2: =IFERROR(_xludf.MAXIFS(SYSHECF!$AE$2:$AE$7489,SYSHECF!$A$2:$A$7489,$A2,SYSHECF!$B$2:$B$7489,$B2),"") | P2: =IF(AND($H2<>"",$O2<>"",$H2*$O2>1),Keys!$C$6,"") -> #VALUE!
A3: AL | B3: geothermal | C3: level check | D3: =SUMIFS(SYSHECF!$AD$2:$AD$7489,SYSHECF!$A$2:$A$7489,$A3,SYSHECF!$B$2:$B$7489,$B3)/Keys!$C$4 -> 0.6595 | E3: =IF(OR($J3="",$J3=0),"",$I3*Keys!$C$5/($J3*Keys!$C$4)) | F3: =IF(OR($L3="",$L3=0),"",$K3*Keys!$C$5/($L3*Keys!$C$4)) | G3: =IF(OR($E3="",$D3=0),"",$E3/$D3) | H3: =IF(OR($F3="",$D3=0),"",$F3/$D3) | I3: =IFERROR(INDEX(EIA_2024!$D$2:$D$514,MATCH($A3&"|"&$B3,EIA_2024!$F$2:$F$514,0)),"") | J3: =IFERROR(INDEX(EIA_2024!$E$2:$E$514,MATCH($A3&"|"&$B3,EIA_2024!$F$2:$F$514,0)),"") | K3: =IFERROR(INDEX(EIA_2025!$C$2:$C$530,MATCH($A3&"|"&$B3,EIA_2025!$E$2:$E$530,0)),"") | L3: =IFERROR(INDEX(EIA_2025!$D$2:$D$530,MATCH($A3&"|"&$B3,EIA_2025!$E$2:$E$530,0)),"") | M3: =IFERROR(INDEX(EIA_2024!$C$2:$C$514,MATCH($A3&"|"&$B3,EIA_2024!$F$2:$F$514,0)),"") | N3: =A3&"|"&B3 -> AL|geothermal | O3: =IFERROR(_xludf.MAXIFS(SYSHECF!$AE$2:$AE$7489,SYSHECF!$A$2:$A$7489,$A3,SYSHECF!$B$2:$B$7489,$B3),"") | P3: =IF(AND($H3<>"",$O3<>"",$H3*$O3>1),Keys!$C$6,"") -> #VALUE!
A4: AL | B4: hard coal | C4: ceiling check | D4: =SUMIFS(SYSHECF!$AD$2:$AD$7489,SYSHECF!$A$2:$A$7489,$A4,SYSHECF!$B$2:$B$7489,$B4)/Keys!$C$4 -> 0.5143 | E4: =IF(OR($J4="",$J4=0),"",$I4*Keys!$C$5/($J4*Keys!$C$4)) -> 0.50549433 | F4: =IF(OR($L4="",$L4=0),"",$K4*Keys!$C$5/($L4*Keys!$C$4)) -> 0.52300634 | G4: =IF(OR($E4="",$D4=0),"",$E4/$D4) -> 0.98287833 | H4: =IF(OR($F4="",$D4=0),"",$F4/$D4) -> 1.0169285 | I4: =IFERROR(INDEX(EIA_2024!$D$2:$D$514,MATCH($A4&"|"&$B4,EIA_2024!$F$2:$F$514,0)),"") -> 20.9362 | J4: =IFERROR(INDEX(EIA_2024!$E$2:$E$514,MATCH($A4&"|"&$B4,EIA_2024!$F$2:$F$514,0)),"") -> 4.728 | K4: =IFERROR(INDEX(EIA_2025!$C$2:$C$530,MATCH($A4&"|"&$B4,EIA_2025!$E$2:$E$530,0)),"") -> 21.6615 | L4: =IFERROR(INDEX(EIA_2025!$D$2:$D$530,MATCH($A4&"|"&$B4,EIA_2025!$E$2:$E$530,0)),"") -> 4.728 | M4: =IFERROR(INDEX(EIA_2024!$C$2:$C$514,MATCH($A4&"|"&$B4,EIA_2024!$F$2:$F$514,0)),"") -> BHRaSYC 2024 (tech-level) | N4: =A4&"|"&B4 -> AL|hard coal | O4: =IFERROR(_xludf.MAXIFS(SYSHECF!$AE$2:$AE$7489,SYSHECF!$A$2:$A$7489,$A4,SYSHECF!$B$2:$B$7489,$B4),"") | P4: =IF(AND($H4<>"",$O4<>"",$H4*$O4>1),Keys!$C$6,"") -> #VALUE!
A5: AL | B5: hydro | C5: level check | D5: =SUMIFS(SYSHECF!$AD$2:$AD$7489,SYSHECF!$A$2:$A$7489,$A5,SYSHECF!$B$2:$B$7489,$B5)/Keys!$C$4 -> 0.2938 | E5: =IF(OR($J5="",$J5=0),"",$I5*Keys!$C$5/($J5*Keys!$C$4)) -> 0.28992575 | F5: =IF(OR($L5="",$L5=0),"",$K5*Keys!$C$5/($L5*Keys!$C$4)) -> 0.29775211 | G5: =IF(OR($E5="",$D5=0),"",$E5/$D5) -> 0.98681332 | H5: =IF(OR($F5="",$D5=0),"",$F5/$D5) -> 1.0134517 | I5: =IFERROR(INDEX(EIA_2024!$D$2:$D$514,MATCH($A5&"|"&$B5,EIA_2024!$F$2:$F$514,0)),"") -> 8.3573 | J5: =IFERROR(INDEX(EIA_2024!$E$2:$E$514,MATCH($A5&"|"&$B5,EIA_2024!$F$2:$F$514,0)),"") -> 3.2906 | K5: =IFERROR(INDEX(EIA_2025!$C$2:$C$530,MATCH($A5&"|"&$B5,EIA_2025!$E$2:$E$530,0)),"") -> 8.5829 | L5: =IFERROR(INDEX(EIA_2025!$D$2:$D$530,MATCH($A5&"|"&$B5,EIA_2025!$E$2:$E$530,0)),"") -> 3.2906 | M5: =IFERROR(INDEX(EIA_2024!$C$2:$C$514,MATCH($A5&"|"&$B5,EIA_2024!$F$2:$F$514,0)),"") -> BHRaSYC 2024 (tech-level) | N5: =A5&"|"&B5 -> AL|hydro | O5: =IFERROR(_xludf.MAXIFS(SYSHECF!$AE$2:$AE$7489,SYSHECF!$A$2:$A$7489,$A5,SYSHECF!$B$2:$B$7489,$B5),"") | P5: =IF(AND($H5<>"",$O5<>"",$H5*$O5>1),Keys!$C$6,"") -> #VALUE!
A6: AL | B6: lignite | C6: ceiling check | D6: =SUMIFS(SYSHECF!$AD$2:$AD$7489,SYSHECF!$A$2:$A$7489,$A6,SYSHECF!$B$2:$B$7489,$B6)/Keys!$C$4 -> 0.638 | E6: =IF(OR($J6="",$J6=0),"",$I6*Keys!$C$5/($J6*Keys!$C$4)) | F6: =IF(OR($L6="",$L6=0),"",$K6*Keys!$C$5/($L6*Keys!$C$4)) | G6: =IF(OR($E6="",$D6=0),"",$E6/$D6) | H6: =IF(OR($F6="",$D6=0),"",$F6/$D6) | I6: =IFERROR(INDEX(EIA_2024!$D$2:$D$514,MATCH($A6&"|"&$B6,EIA_2024!$F$2:$F$514,0)),"") | J6: =IFERROR(INDEX(EIA_2024!$E$2:$E$514,MATCH($A6&"|"&$B6,EIA_2024!$F$2:$F$514,0)),"") | K6: =IFERROR(INDEX(EIA_2025!$C$2:$C$530,MATCH($A6&"|"&$B6,EIA_2025!$E$2:$E$530,0)),"") | L6: =IFERROR(INDEX(EIA_2025!$D$2:$D$530,MATCH($A6&"|"&$B6,EIA_2025!$E$2:$E$530,0)),"") | M6: =IFERROR(INDEX(EIA_2024!$C$2:$C$514,MATCH($A6&"|"&$B6,EIA_2024!$F$2:$F$514,0)),"") | N6: =A6&"|"&B6 -> AL|lignite | O6: =IFERROR(_xludf.MAXIFS(SYSHECF!$AE$2:$AE$7489,SYSHECF!$A$2:$A$7489,$A6,SYSHECF!$B$2:$B$7489,$B6),"") | P6: =IF(AND($H6<>"",$O6<>"",$H6*$O6>1),Keys!$C$6,"") -> #VALUE!
A7: AL | B7: municipal solid waste | C7: ceiling check | D7: =SUMIFS(SYSHECF!$AD$2:$AD$7489,SYSHECF!$A$2:$A$7489,$A7,SYSHECF!$B$2:$B$7489,$B7)/Keys!$C$4 -> 0.7342 | E7: =IF(OR($J7="",$J7=0),"",$I7*Keys!$C$5/($J7*Keys!$C$4)) | F7: =IF(OR($L7="",$L7=0),"",$K7*Keys!$C$5/($L7*Keys!$C$4)) | G7: =IF(OR($E7="",$D7=0),"",$E7/$D7) | H7: =IF(OR($F7="",$D7=0),"",$F7/$D7) | I7: =IFERROR(INDEX(EIA_2024!$D$2:$D$514,MATCH($A7&"|"&$B7,EIA_2024!$F$2:$F$514,0)),"") | J7: =IFERROR(INDEX(EIA_2024!$E$2:$E$514,MATCH($A7&"|"&$B7,EIA_2024!$F$2:$F$514,0)),"") | K7: =IFERROR(INDEX(EIA_2025!$C$2:$C$530,MATCH($A7&"|"&$B7,EIA_2025!$E$2:$E$530,0)),"") | L7: =IFERROR(INDEX(EIA_2025!$D$2:$D$530,MATCH($A7&"|"&$B7,EIA_2025!$E$2:$E$530,0)),"") | M7: =IFERROR(INDEX(EIA_2024!$C$2:$C$514,MATCH($A7&"|"&$B7,EIA_2024!$F$2:$F$514,0)),"") | N7: =A7&"|"&B7 -> AL|municipal solid waste | O7: =IFERROR(_xludf.MAXIFS(SYSHECF!$AE$2:$AE$7489,SYSHECF!$A$2:$A$7489,$A7,SYSHECF!$B$2:$B$7489,$B7),"") | P7: =IF(AND($H7<>"",$O7<>"",$H7*$O7>1),Keys!$C$6,"") -> #VALUE!
A8: AL | B8: natural gas combined cycle | C8: ceiling check | D8: =SUMIFS(SYSHECF!$AD$2:$AD$7489,SYSHECF!$A$2:$A$7489,$A8,SYSHECF!$B$2:$B$7489,$B8)/Keys!$C$4 -> 0.6069 | E8: =IF(OR($J8="",$J8=0),"",$I8*Keys!$C$5/($J8*Keys!$C$4)) -> 0.60399902 | F8: =IF(OR($L8="",$L8=0),"",$K8*Keys!$C$5/($L8*Keys!$C$4)) -> 0.60986247 | G8: =IF(OR($E8="",$D8=0),"",$E8/$D8) -> 0.99522001 | H8: =IF(OR($F8="",$D8=0),"",$F8/$D8) -> 1.0048813 | I8: =IFERROR(INDEX(EIA_2024!$D$2:$D$514,MATCH($A8&"|"&$B8,EIA_2024!$F$2:$F$514,0)),"") -> 58.5823 | J8: =IFERROR(INDEX(EIA_2024!$E$2:$E$514,MATCH($A8&"|"&$B8,EIA_2024!$F$2:$F$514,0)),"") -> 11.072 | K8: =IFERROR(INDEX(EIA_2025!$C$2:$C$530,MATCH($A8&"|"&$B8,EIA_2025!$E$2:$E$530,0)),"") -> 59.151 | L8: =IFERROR(INDEX(EIA_2025!$D$2:$D$530,MATCH($A8&"|"&$B8,EIA_2025!$E$2:$E$530,0)),"") -> 11.072 | M8: =IFERROR(INDEX(EIA_2024!$C$2:$C$514,MATCH($A8&"|"&$B8,EIA_2024!$F$2:$F$514,0)),"") -> BHRaSYC 2024 (tech-level) | N8: =A8&"|"&B8 -> AL|natural gas combined cycle | O8: =IFERROR(_xludf.MAXIFS(SYSHECF!$AE$2:$AE$7489,SYSHECF!$A$2:$A$7489,$A8,SYSHECF!$B$2:$B$7489,$B8),"") | P8: =IF(AND($H8<>"",$O8<>"",$H8*$O8>1),Keys!$C$6,"") -> #VALUE!
A9: AL | B9: natural gas peaker | C9: ceiling check | D9: =SUMIFS(SYSHECF!$AD$2:$AD$7489,SYSHECF!$A$2:$A$7489,$A9,SYSHECF!$B$2:$B$7489,$B9)/Keys!$C$4 -> 0.041074691 | E9: =IF(OR($J9="",$J9=0),"",$I9*Keys!$C$5/($J9*Keys!$C$4)) -> 0.03872175 | F9: =IF(OR($L9="",$L9=0),"",$K9*Keys!$C$5/($L9*Keys!$C$4)) -> 0.043094909 | G9: =IF(OR($E9="",$D9=0),"",$E9/$D9) -> 0.94271556 | H9: =IF(OR($F9="",$D9=0),"",$F9/$D9) -> 1.049184 | I9: =IFERROR(INDEX(EIA_2024!$D$2:$D$514,MATCH($A9&"|"&$B9,EIA_2024!$F$2:$F$514,0)),"") -> 1.0923 | J9: =IFERROR(INDEX(EIA_2024!$E$2:$E$514,MATCH($A9&"|"&$B9,EIA_2024!$F$2:$F$514,0)),"") -> 3.2202 | K9: =IFERROR(INDEX(EIA_2025!$C$2:$C$530,MATCH($A9&"|"&$B9,EIA_2025!$E$2:$E$530,0)),"") -> 1.2251 | L9: =IFERROR(INDEX(EIA_2025!$D$2:$D$530,MATCH($A9&"|"&$B9,EIA_2025!$E$2:$E$530,0)),"") -> 3.2452 | M9: =IFERROR(INDEX(EIA_2024!$C$2:$C$514,MATCH($A9&"|"&$B9,EIA_2024!$F$2:$F$514,0)),"") -> BHRaSYC 2024 (tech-level) | N9: =A9&"|"&B9 -> AL|natural gas peaker | O9: =IFERROR(_xludf.MAXIFS(SYSHECF!$AE$2:$AE$7489,SYSHECF!$A$2:$A$7489,$A9,SYSHECF!$B$2:$B$7489,$B9),"") | P9: =IF(AND($H9<>"",$O9<>"",$H9*$O9>1),Keys!$C$6,"") -> #VALUE!
A10: AL | B10: natural gas steam turbine | C10: ceiling check | D10: =SUMIFS(SYSHECF!$AD$2:$AD$7489,SYSHECF!$A$2:$A$7489,$A10,SYSHECF!$B$2:$B$7489,$B10)/Keys!$C$4 -> 0.2213 | E10: =IF(OR($J10="",$J10=0),"",$I10*Keys!$C$5/($J10*Keys!$C$4)) -> 0.21181416 | F10: =IF(OR($L10="",$L10=0),"",$K10*Keys!$C$5/($L10*Keys!$C$4)) -> 0.23079404 | G10: =IF(OR($E10="",$D10=0),"",$E10/$D10) -> 0.95713582 | H10: =IF(OR($F10="",$D10=0),"",$F10/$D10) -> 1.0429012 | I10: =IFERROR(INDEX(EIA_2024!$D$2:$D$514,MATCH($A10&"|"&$B10,EIA_2024!$F$2:$F$514,0)),"") -> 3.1471 | J10: =IFERROR(INDEX(EIA_2024!$E$2:$E$514,MATCH($A10&"|"&$B10,EIA_2024!$F$2:$F$514,0)),"") -> 1.6961 | K10: =IFERROR(INDEX(EIA_2025!$C$2:$C$530,MATCH($A10&"|"&$B10,EIA_2025!$E$2:$E$530,0)),"") -> 3.4291 | L10: =IFERROR(INDEX(EIA_2025!$D$2:$D$530,MATCH($A10&"|"&$B10,EIA_2025!$E$2:$E$530,0)),"") -> 1.6961 | M10: =IFERROR(INDEX(EIA_2024!$C$2:$C$514,MATCH($A10&"|"&$B10,EIA_2024!$F$2:$F$514,0)),"") -> BHRaSYC 2024 (tech-level) | N10: =A10&"|"&B10 -> AL|natural gas steam turbine | O10: =IFERROR(_xludf.MAXIFS(SYSHECF!$AE$2:$AE$7489,SYSHECF!$A$2:$A$7489,$A10,SYSHECF!$B$2:$B$7489,$B10),"") | P10: =IF(AND($H10<>"",$O10<>"",$H10*$O10>1),Keys!$C$6,"") -> #VALUE!
A11: AL | B11: nuclear | C11: level check | D11: =SUMIFS(SYSHECF!$AD$2:$AD$7489,SYSHECF!$A$2:$A$7489,$A11,SYSHECF!$B$2:$B$7489,$B11)/Keys!$C$4 -> 0.9124 | E11: =IF(OR($J11="",$J11=0),"",$I11*Keys!$C$5/($J11*Keys!$C$4)) -> 0.93136382 | F11: =IF(OR($L11="",$L11=0),"",$K11*Keys!$C$5/($L11*Keys!$C$4)) -> 0.89337627 | G11: =IF(OR($E11="",$D11=0),"",$E11/$D11) -> 1.0207845 | H11: =IF(OR($F11="",$D11=0),"",$F11/$D11) -> 0.97914979 | I11: =IFERROR(INDEX(EIA_2024!$D$2:$D$514,MATCH($A11&"|"&$B11,EIA_2024!$F$2:$F$514,0)),"") -> 44.4872 | J11: =IFERROR(INDEX(EIA_2024!$E$2:$E$514,MATCH($A11&"|"&$B11,EIA_2024!$F$2:$F$514,0)),"") -> 5.4527 | K11: =IFERROR(INDEX(EIA_2025!$C$2:$C$530,MATCH($A11&"|"&$B11,EIA_2025!$E$2:$E$530,0)),"") -> 42.6727 | L11: =IFERROR(INDEX(EIA_2025!$D$2:$D$530,MATCH($A11&"|"&$B11,EIA_2025!$E$2:$E$530,0)),"") -> 5.4527 | M11: =IFERROR(INDEX(EIA_2024!$C$2:$C$514,MATCH($A11&"|"&$B11,EIA_2024!$F$2:$F$514,0)),"") -> BHRaSYC 2024 (tech-level) | N11: =A11&"|"&B11 -> AL|nuclear | O11: =IFERROR(_xludf.MAXIFS(SYSHECF!$AE$2:$AE$7489,SYSHECF!$A$2:$A$7489,$A11,SYSHECF!$B$2:$B$7489,$B11),"") | P11: =IF(AND($H11<>"",$O11<>"",$H11*$O11>1),Keys!$C$6,"") -> #VALUE!
A12: AL | B12: offshore wind | C12: level check | D12: =SUMIFS(SYSHECF!$AD$2:$AD$7489,SYSHECF!$A$2:$A$7489,$A12,SYSHECF!$B$2:$B$7489,$B12)/Keys!$C$4 -> 0.2889 | E12: =IF(OR($J12="",$J12=0),"",$I12*Keys!$C$5/($J12*Keys!$C$4)) | F12: =IF(OR($L12="",$L12=0),"",$K12*Keys!$C$5/($L12*Keys!$C$4)) | G12: =IF(OR($E12="",$D12=0),"",$E12/$D12) | H12: =IF(OR($F12="",$D12=0),"",$F12/$D12) | I12: =IFERROR(INDEX(EIA_2024!$D$2:$D$514,MATCH($A12&"|"&$B12,EIA_2024!$F$2:$F$514,0)),"") | J12: =IFERROR(INDEX(EIA_2024!$E$2:$E$514,MATCH($A12&"|"&$B12,EIA_2024!$F$2:$F$514,0)),"") | K12: =IFERROR(INDEX(EIA_2025!$C$2:$C$530,MATCH($A12&"|"&$B12,EIA_2025!$E$2:$E$530,0)),"") | L12: =IFERROR(INDEX(EIA_2025!$D$2:$D$530,MATCH($A12&"|"&$B12,EIA_2025!$E$2:$E$530,0)),"") | M12: =IFERROR(INDEX(EIA_2024!$C$2:$C$514,MATCH($A12&"|"&$B12,EIA_2024!$F$2:$F$514,0)),"") | N12: =A12&"|"&B12 -> AL|offshore wind | O12: =IFERROR(_xludf.MAXIFS(SYSHECF!$AE$2:$AE$7489,SYSHECF!$A$2:$A$7489,$A12,SYSHECF!$B$2:$B$7489,$B12),"") | P12: =IF(AND($H12<>"",$O12<>"",$H12*$O12>1),Keys!$C$6,"") -> #VALUE!
A13: AL | B13: onshore wind | C13: level check | D13: =SUMIFS(SYSHECF!$AD$2:$AD$7489,SYSHECF!$A$2:$A$7489,$A13,SYSHECF!$B$2:$B$7489,$B13)/Keys!$C$4 -> 0.2659 | E13: =IF(OR($J13="",$J13=0),"",$I13*Keys!$C$5/($J13*Keys!$C$4)) | F13: =IF(OR($L13="",$L13=0),"",$K13*Keys!$C$5/($L13*Keys!$C$4)) | G13: =IF(OR($E13="",$D13=0),"",$E13/$D13) | H13: =IF(OR($F13="",$D13=0),"",$F13/$D13) | I13: =IFERROR(INDEX(EIA_2024!$D$2:$D$514,MATCH($A13&"|"&$B13,EIA_2024!$F$2:$F$514,0)),"") | J13: =IFERROR(INDEX(EIA_2024!$E$2:$E$514,MATCH($A13&"|"&$B13,EIA_2024!$F$2:$F$514,0)),"") | K13: =IFERROR(INDEX(EIA_2025!$C$2:$C$530,MATCH($A13&"|"&$B13,EIA_2025!$E$2:$E$530,0)),"") | L13: =IFERROR(INDEX(EIA_2025!$D$2:$D$530,MATCH($A13&"|"&$B13,EIA_2025!$E$2:$E$530,0)),"") | M13: =IFERROR(INDEX(EIA_2024!$C$2:$C$514,MATCH($A13&"|"&$B13,EIA_2024!$F$2:$F$514,0)),"") | N13: =A13&"|"&B13 -> AL|onshore wind | O13: =IFERROR(_xludf.MAXIFS(SYSHECF!$AE$2:$AE$7489,SYSHECF!$A$2:$A$7489,$A13,SYSHECF!$B$2:$B$7489,$B13),"") | P13: =IF(AND($H13<>"",$O13<>"",$H13*$O13>1),Keys!$C$6,"") -> #VALUE!
... A769: WY | B769: solar thermal | C769: level check | D769: =SUMIFS(SYSHECF!$AD$2:$AD$7489,SYSHECF!$A$2:$A$7489,$A769,SYSHECF!$B$2:$B$7489,$B769)/Keys!$C$4 -> 0.22458571 | E769: =IF(OR($J769="",$J769=0),"",$I769*Keys!$C$5/($J769*Keys!$C$4)) | F769: =IF(OR($L769="",$L769=0),"",$K769*Keys!$C$5/($L769*Keys!$C$4)) | G769: =IF(OR($E769="",$D769=0),"",$E769/$D769) | H769: =IF(OR($F769="",$D769=0),"",$F769/$D769) | I769: =IFERROR(INDEX(EIA_2024!$D$2:$D$514,MATCH($A769&"|"&$B769,EIA_2024!$F$2:$F$514,0)),"") | J769: =IFERROR(INDEX(EIA_2024!$E$2:$E$514,MATCH($A769&"|"&$B769,EIA_2024!$F$2:$F$514,0)),"") | K769: =IFERROR(INDEX(EIA_2025!$C$2:$C$530,MATCH($A769&"|"&$B769,EIA_2025!$E$2:$E$530,0)),"") | L769: =IFERROR(INDEX(EIA_2025!$D$2:$D$530,MATCH($A769&"|"&$B769,EIA_2025!$E$2:$E$530,0)),"") | M769: =IFERROR(INDEX(EIA_2024!$C$2:$C$514,MATCH($A769&"|"&$B769,EIA_2024!$F$2:$F$514,0)),"") | N769: =A769&"|"&B769 -> WY|solar thermal | O769: =IFERROR(_xludf.MAXIFS(SYSHECF!$AE$2:$AE$7489,SYSHECF!$A$2:$A$7489,$A769,SYSHECF!$B$2:$B$7489,$B769),"") | P769: =IF(AND($H769<>"",$O769<>"",$H769*$O769>1),Keys!$C$6,"") -> #VALUE!

Sheet Adjustments
A1: state | B1: tech (CF_summary form) | C1: boost_2025 | D1: bhrasyc_old_gw | E1: cap_2025_gw | F1: correction (formula) | G1: empirical_override | H1: note | I1: key (helper)
A2: AL | B2: solar pv | C2: 0.171558 | D2: 0.6635 | E2: 0.743 | F2: =IF(E2<=0,1,E2/(D2+MAX(0,E2-D2)*(1+C2))) -> 0.98197441 | G2: 0.951845 | H2: empirical: 2026-08-13 solar retune, 0.921284 -> 0.951845 (was -3.21% vs EIA-923 2025 on run bau-0813); supersedes formula | I2: =A2&"|"&B2 -> AL|solar pv
A3: AR | B3: onshore wind | C3: 0.137991 | D3: 0 | E3: 0.135 | F3: =IF(E3<=0,1,E3/(D3+MAX(0,E3-D3)*(1+C3))) -> 0.87874157 | G3: 0.425949 | H3: empirical: 2026-08-26 step-1a wind retune, 0.48469 -> 0.425949 (was 13.79% vs EIA-923 2025 on run climate-0825); supersedes formula and the 08-13 value | I3: =A3&"|"&B3 -> AR|onshore wind
A4: AR | B4: solar pv | C4: 0.349457 | D4: 1.7725 | E4: 2.525 | F4: =IF(E4<=0,1,E4/(D4+MAX(0,E4-D4)*(1+C4))) -> 0.90567806 | G4: 1.058135 | H4: empirical: 2026-08-13 solar retune, 0.985992 -> 1.058135 (was -6.82% vs EIA-923 2025 on run bau-0813); supersedes formula | I4: =A4&"|"&B4 -> AR|solar pv
A5: AZ | B5: onshore wind | C5: 0.012275 | D5: 1.2345 | E5: 1.234 | F5: =IF(E5<=0,1,E5/(D5+MAX(0,E5-D5)*(1+C5))) -> 0.99959498 | I5: =A5&"|"&B5 -> AZ|onshore wind
A6: AZ | B6: solar pv | C6: 0.210089 | D6: 4.7302 | E6: 6.262 | F6: =IF(E6<=0,1,E6/(D6+MAX(0,E6-D6)*(1+C6))) -> 0.95112038 | G6: 0.998708 | H6: empirical: 2026-08-13 solar retune, 0.963442 -> 0.998708 (was -3.53% vs EIA-923 2025 on run bau-0813); supersedes formula | I6: =A6&"|"&B6 -> AZ|solar pv
A7: CA | B7: onshore wind | C7: 0 | D7: 6.4287 | E7: 6.418 | F7: =IF(E7<=0,1,E7/(D7+MAX(0,E7-D7)*(1+C7))) -> 0.99833559 | I7: =A7&"|"&B7 -> CA|onshore wind
A8: CA | B8: solar pv | C8: 0.150873 | D8: 21.0873 | E8: 23.19 | F8: =IF(E8<=0,1,E8/(D8+MAX(0,E8-D8)*(1+C8))) -> 0.98650456 | I8: =A8&"|"&B8 -> CA|solar pv
A9: CO | B9: onshore wind | C9: 0.0501178 | D9: 5.3349 | E9: 5.374 | F9: =IF(E9<=0,1,E9/(D9+MAX(0,E9-D9)*(1+C9))) -> 0.99963549 | I9: =A9&"|"&B9 -> CO|onshore wind
A10: CO | B10: solar pv | C10: 0.294204 | D10: 2.3495 | E10: 3.234 | F10: =IF(E10<=0,1,E10/(D10+MAX(0,E10-D10)*(1+C10))) -> 0.92552753 | G10: 0.831744 | H10: empirical: 2026-08-13 solar retune, 0.803406 -> 0.831744 (was -3.41% vs EIA-923 2025 on run bau-0813); supersedes formula | I10: =A10&"|"&B10 -> CO|solar pv
A11: CT | B11: onshore wind | C11: 0.055842 | D11: 0.005 | E11: 0.005 | F11: =IF(E11<=0,1,E11/(D11+MAX(0,E11-D11)*(1+C11))) -> 1 | I11: =A11&"|"&B11 -> CT|onshore wind
A12: CT | B12: solar pv | C12: 0.335705 | D12: 0.3142 | E12: 0.478 | F12: =IF(E12<=0,1,E12/(D12+MAX(0,E12-D12)*(1+C12))) -> 0.89682989 | G12: 0.856123 | H12: empirical: 2026-08-13 solar retune, 0.824666 -> 0.856123 (was -3.67% vs EIA-923 2025 on run bau-0813); supersedes formula | I12: =A12&"|"&B12 -> CT|solar pv
A13: DE | B13: solar pv | C13: 0.280237 | D13: 0.0919 | E13: 0.106 | F13: =IF(E13<=0,1,E13/(D13+MAX(0,E13-D13)*(1+C13))) -> 0.96406282 | G13: 0.930008 | H13: empirical: 2026-08-13 solar retune, 0.875986 -> 0.930008 (was -5.81% vs EIA-923 2025 on run bau-0813); supersedes formula | I13: =A13&"|"&B13 -> DE|solar pv
A14: FL | B14: solar pv | C14: 0.24993 | D14: 10.9429 | E14: 12.285 | F14: =IF(E14<=0,1,E14/(D14+MAX(0,E14-D14)*(1+C14))) -> 0.97342159 | I14: =A14&"|"&B14 -> FL|solar pv
A15: GA | B15: solar pv | C15: 0.134892 | D15: 4.9994 | E15: 5.399 | F15: =IF(E15<=0,1,E15/(D15+MAX(0,E15-D15)*(1+C15))) -> 0.99011484 | I15: =A15&"|"&B15 -> GA|solar pv
A16: IA | B16: onshore wind | C16: 0.0924795 | D16: 12.8645 | E16: 13.241 | F16: =IF(E16<=0,1,E16/(D16+MAX(0,E16-D16)*(1+C16))) -> 0.9973773 | G16: 1.073084 | H16: empirical: 2026-07-28 wind curtailment gross-up (supersedes formula) | I16: =A16&"|"&B16 -> IA|onshore wind
A17: IA | B17: solar pv | C17: 0.42732 | D17: 0.6761 | E17: 0.689 | F17: =IF(E17<=0,1,E17/(D17+MAX(0,E17-D17)*(1+C17))) -> 0.99206288 | G17: 1.356136 | H17: empirical: 2026-08-13 solar retune, 1.29416 -> 1.356136 (was -4.57% vs EIA-923 2025 on run bau-0813); supersedes formula | I17: =A17&"|"&B17 -> IA|solar pv
A18: ID | B18: onshore wind | C18: 0 | D18: 1.1283 | E18: 1.128 | F18: =IF(E18<=0,1,E18/(D18+MAX(0,E18-D18)*(1+C18))) -> 0.99973411 | G18: 1.080169 | H18: empirical: 2026-07-28 wind curtailment gross-up (supersedes formula) | I18: =A18&"|"&B18 -> ID|onshore wind
A19: ID | B19: solar pv | C19: 0 | D19: 0.5 | E19: 0.7 | F19: =IF(E19<=0,1,E19/(D19+MAX(0,E19-D19)*(1+C19))) -> 1 | G19: 1.077722 | H19: empirical: 2026-08-13 solar retune, 1.03741 -> 1.077722 (was -3.74% vs EIA-923 2025 on run bau-0813); supersedes formula | I19: =A19&"|"&B19 -> ID|solar pv
A20: IL | B20: onshore wind | C20: 0.10493 | D20: 7.872 | E20: 8.429 | F20: =IF(E20<=0,1,E20/(D20+MAX(0,E20-D20)*(1+C20))) -> 0.99311383 | I20: =A20&"|"&B20 -> IL|onshore wind
A21: IL | B21: solar pv | C21: 0.593577 | D21: 2.955 | E21: 4.259 | F21: =IF(E21<=0,1,E21/(D21+MAX(0,E21-D21)*(1+C21))) -> 0.84621088 | G21: 1.011287 | H21: empirical: 2026-08-13 solar retune, 0.977431 -> 1.011287 (was -3.35% vs EIA-923 2025 on run bau-0813); supersedes formula | I21: =A21&"|"&B21 -> IL|solar pv
A22: IN | B22: onshore wind | C22: 0.239246 | D22: 3.6391 | E22: 3.852 | F22: =IF(E22<=0,1,E22/(D22+MAX(0,E22-D22)*(1+C22))) -> 0.98694945 | I22: =A22&"|"&B22 -> IN|onshore wind
A23: IN | B23: solar pv | C23: 0.475996 | D23: 2.4892 | E23: 4.591 | F23: =IF(E23<=0,1,E23/(D23+MAX(0,E23-D23)*(1+C23))) -> 0.82107527 | G23: 0.883608 | H23: empirical: 2026-08-13 solar retune, 0.766715 -> 0.883608 (was -13.23% vs EIA-923 2025 on run bau-0813); supersedes formula | I23: =A23&"|"&B23 -> IN|solar pv
A24: KS | B24: onshore wind | C24: 0.22839 | D24: 9.036 | E24: 9.644 | F24: =IF(E24<=0,1,E24/(D24+MAX(0,E24-D24)*(1+C24))) -> 0.98580567 | I24: =A24&"|"&B24 -> KS|onshore wind
A25: KS | B25: solar pv | C25: 0.372726 | D25: 0.0658 | E25: 0.278 | F25: =IF(E25<=0,1,E25/(D25+MAX(0,E25-D25)*(1+C25))) -> 0.77850986 | G25: 0.710352 | H25: empirical: 2026-08-13 solar retune, 0.618733 -> 0.710352 (was -12.9% vs EIA-923 2025 on run bau-0813); supersedes formula | I25: =A25&"|"&B25 -> KS|solar pv
A26: KY | B26: solar pv | C26: 0.947395 | D26: 0.4252 | E26: 1.135 | F26: =IF(E26<=0,1,E26/(D26+MAX(0,E26-D26)*(1+C26))) -> 0.6279527 | G26: 0.861193 | H26: empirical: 2026-08-13 solar retune, 0.69025 -> 0.861193 (was -19.85% vs EIA-923 2025 on run bau-0813); supersedes formula | I26: =A26&"|"&B26 -> KY|solar pv
A27: LA | B27: solar pv | C27: 0.472847 | D27: 1.0526 | E27: 1.335 | F27: =IF(E27<=0,1,E27/(D27+MAX(0,E27-D27)*(1+C27))) -> 0.9090711 | G27: 1.1383 | H27: empirical: 2026-09-02 dispatch retune, 1.11197 -> 1.1383 (solar +0.0% (was -16.2 mid-retune, -7.4 pre); paired with solar PV guarantee 1.0); supersedes formula and any earlier retune | I27: =A27&"|"&B27 -> LA|solar pv
A28: MA | B28: onshore wind | C28: 0.161043 | D28: 0.0851 | E28: 0.083 | F28: =IF(E28<=0,1,E28/(D28+MAX(0,E28-D28)*(1+C28))) -> 0.97532315 | G28: 0.67606 | H28: empirical: 2026-08-13 wind retune, 0.639288 -> 0.67606 (was -5.44% vs EIA-923 2025 on run bau-0813); supersedes formula | I28: =A28&"|"&B28 -> MA|onshore wind
A29: MA | B29: solar pv | C29: 0.288839 | D29: 1.4191 | E29: 1.474 | F29: =IF(E29<=0,1,E29/(D29+MAX(0,E29-D29)*(1+C29))) -> 0.98935652 | I29: =A29&"|"&B29 -> MA|solar pv
A30: MD | B30: onshore wind | C30: 0.183227 | D30: 0.19 | E30: 0.245 | F30: =IF(E30<=0,1,E30/(D30+MAX(0,E30-D30)*(1+C30))) -> 0.96049246 | I30: =A30&"|"&B30 -> MD|onshore wind
A31: MD | B31: solar pv | C31: 0.504497 | D31: 0.6597 | E31: 1.048 | F31: =IF(E31<=0,1,E31/(D31+MAX(0,E31-D31)*(1+C31))) -> 0.84251404 | G31: 0.706678 | H31: empirical: 2026-08-13 solar retune, 0.620804 -> 0.706678 (was -12.15% vs EIA-923 2025 on run bau-0813); supersedes formula | I31: =A31&"|"&B31 -> MD|solar pv
A32: ME | B32: onshore wind | C32: 0.420566 | D32: 1.0295 | E32: 1.214 | F32: =IF(E32<=0,1,E32/(D32+MAX(0,E32-D32)*(1+C32))) -> 0.93992354 | I32: =A32&"|"&B32 -> ME|onshore wind
A33: ME | B33: solar pv | C33: 0.340949 | D33: 0.8292 | E33: 0.874 | F33: =IF(E33<=0,1,E33/(D33+MAX(0,E33-D33)*(1+C33))) -> 0.98282362 | G33: 1.12135 | H33: empirical: 2026-08-28 step-1a solar retune (ceiling basis), 1.14279 -> 1.12135 (ceiling was 1.91% vs EIA-923 2025 ER on the 08-28 BAU sweep); supersedes formula and any earlier retune | I33: =A33&"|"&B33 -> ME|solar pv
A34: MI | B34: onshore wind | C34: 0.283168 | D34: 3.7743 | E34: 3.774 | F34: =IF(E34<=0,1,E34/(D34+MAX(0,E34-D34)*(1+C34))) -> 0.99992052 | I34: =A34&"|"&B34 -> MI|onshore wind
A35: MI | B35: solar pv | C35: 0.213218 | D35: 1.157 | E35: 1.965 | F35: =IF(E35<=0,1,E35/(D35+MAX(0,E35-D35)*(1+C35))) -> 0.91939281 | G35: 0.862786 | H35: empirical: 2026-08-13 solar retune, 0.804403 -> 0.862786 (was -6.77% vs EIA-923 2025 on run bau-0813); supersedes formula | I35: =A35&"|"&B35 -> MI|solar pv
A36: MN | B36: onshore wind | C36: 0.121565 | D36: 4.8915 | E36: 4.936 | F36: =IF(E36<=0,1,E36/(D36+MAX(0,E36-D36)*(1+C36))) -> 0.99890524 | I36: =A36&"|"&B36 -> MN|onshore wind
A37: MN | B37: solar pv | C37: 0.29967 | D37: 1.5967 | E37: 1.863 | F37: =IF(E37<=0,1,E37/(D37+MAX(0,E37-D37)*(1+C37))) -> 0.95892422 | G37: 1.01841 | H37: empirical: 2026-08-28 step-1a solar retune (ceiling basis), 1.02902 -> 1.01841 (ceiling was 1.04% vs EIA-923 2025 ER on the 08-28 BAU sweep); supersedes formula and any earlier retune | I37: =A37&"|"&B37 -> MN|solar pv
A38: MO | B38: onshore wind | C38: 0.22359 | D38: 2.3929 | E38: 2.393 | F38: =IF(E38<=0,1,E38/(D38+MAX(0,E38-D38)*(1+C38))) -> 0.99999066 | I38: =A38&"|"&B38 -> MO|onshore wind
A39: MO | B39: solar pv | C39: 1.69762 | D39: 0.4688 | E39: 1.336 | F39: =IF(E39<=0,1,E39/(D39+MAX(0,E39-D39)*(1+C39))) -> 0.47575365 | G39: 0.679266 | H39: empirical: 2026-08-13 solar retune, 0.625715 -> 0.679266 (was -7.88% vs EIA-923 2025 on run bau-0813); supersedes formula | I39: =A39&"|"&B39 -> MO|solar pv
A40: MS | B40: onshore wind | C40: 0.163558 | D40: 0.1845 | E40: 0.184 | F40: =IF(E40<=0,1,E40/(D40+MAX(0,E40-D40)*(1+C40))) -> 0.99728997 | I40: =A40&"|"&B40 -> MS|onshore wind
...

Sheet HYECFCA
A1: multiplier (dmnl, %) | B1: 2025 | C1: 2026 | D1: 2027 | E1: 2028 | F1: 2029 | G1: 2030 | H1: 2031 | I1: 2032 | J1: 2033 | K1: 2034 | L1: 2035 | M1: 2036 | N1: 2037 | O1: 2038 | P1: 2039 | Q1: 2040 | R1: 2041 | S1: 2042 | T1: 2043 | U1: 2044 | V1: 2045 | W1: 2046 | X1: 2047 | Y1: 2048 | Z1: 2049 | AA1: 2050
A2: hard coal es | B2: =IF(IFERROR(INDEX(Adjustments!$G$2:$G$139,MATCH(About!$B$2&"|"&LOWER(LEFT($A2,LEN($A2)-3)),Adjustments!$I$2:$I$139,0)),"")<>"",IFERROR(INDEX(Adjustments!$G$2:$G$139,MATCH(About!$B$2&"|"&LOWER(LEFT($A2,LEN($A2)-3)),Adjustments!$I$2:$I$139,0)),""),IFERROR(IF(INDEX(CF_summary!$H$2:$H$769,MATCH(About!$B$2&"|"&LOWER(LEFT($A2,LEN($A2)-3)),CF_summary!$N$2:$N$769,0))="",Keys!$C$2,INDEX(CF_summary!$H$2:$H$769,MATCH(About!$B$2&"|"&LOWER(LEFT($A2,LEN($A2)-3)),CF_summary!$N$2:$N$769,0))*IFERROR(INDEX(Adjustments!$F$2:$F$139,MATCH(About!$B$2&"|"&LOWER(LEFT($A2,LEN($A2)-3)),Adjustments!$I$2:$I$139,0)),1)),Keys!$C$2)) -> 1.1504714 | C2: =Keys!$C$2 -> 1 | D2: =Keys!$C$2 -> 1 | E2: =Keys!$C$2 -> 1 | F2: =Keys!$C$2 -> 1 | G2: =Keys!$C$2 -> 1 | H2: =Keys!$C$2 -> 1 | I2: =Keys!$C$2 -> 1 | J2: =Keys!$C$2 -> 1 | ... AA2: =Keys!$C$2 -> 1
A3: natural gas steam turbine es | B3: =IF(IFERROR(INDEX(Adjustments!$G$2:$G$139,MATCH(About!$B$2&"|"&LOWER(LEFT($A3,LEN($A3)-3)),Adjustments!$I$2:$I$139,0)),"")<>"",IFERROR(INDEX(Adjustments!$G$2:$G$139,MATCH(About!$B$2&"|"&LOWER(LEFT($A3,LEN($A3)-3)),Adjustments!$I$2:$I$139,0)),""),IFERROR(IF(INDEX(CF_summary!$H$2:$H$769,MATCH(About!$B$2&"|"&LOWER(LEFT($A3,LEN($A3)-3)),CF_summary!$N$2:$N$769,0))="",Keys!$C$2,INDEX(CF_summary!$H$2:$H$769,MATCH(About!$B$2&"|"&LOWER(LEFT($A3,LEN($A3)-3)),CF_summary!$N$2:$N$769,0))*IFERROR(INDEX(Adjustments!$F$2:$F$139,MATCH(About!$B$2&"|"&LOWER(LEFT($A3,LEN($A3)-3)),Adjustments!$I$2:$I$139,0)),1)),Keys!$C$2)) -> 1.0042973 | C3: =Keys!$C$2 -> 1 | D3: =Keys!$C$2 -> 1 | E3: =Keys!$C$2 -> 1 | F3: =Keys!$C$2 -> 1 | G3: =Keys!$C$2 -> 1 | H3: =Keys!$C$2 -> 1 | I3: =Keys!$C$2 -> 1 | J3: =Keys!$C$2 -> 1 | ... AA3: =Keys!$C$2 -> 1
A4: natural gas combined cycle es | B4: =IF(IFERROR(INDEX(Adjustments!$G$2:$G$139,MATCH(About!$B$2&"|"&LOWER(LEFT($A4,LEN($A4)-3)),Adjustments!$I$2:$I$139,0)),"")<>"",IFERROR(INDEX(Adjustments!$G$2:$G$139,MATCH(About!$B$2&"|"&LOWER(LEFT($A4,LEN($A4)-3)),Adjustments!$I$2:$I$139,0)),""),IFERROR(IF(INDEX(CF_summary!$H$2:$H$769,MATCH(About!$B$2&"|"&LOWER(LEFT($A4,LEN($A4)-3)),CF_summary!$N$2:$N$769,0))="",Keys!$C$2,INDEX(CF_summary!$H$2:$H$769,MATCH(About!$B$2&"|"&LOWER(LEFT($A4,LEN($A4)-3)),CF_summary!$N$2:$N$769,0))*IFERROR(INDEX(Adjustments!$F$2:$F$139,MATCH(About!$B$2&"|"&LOWER(LEFT($A4,LEN($A4)-3)),Adjustments!$I$2:$I$139,0)),1)),Keys!$C$2)) -> 0.96225115 | C4: =Keys!$C$2 -> 1 | D4: =Keys!$C$2 -> 1 | E4: =Keys!$C$2 -> 1 | F4: =Keys!$C$2 -> 1 | G4: =Keys!$C$2 -> 1 | H4: =Keys!$C$2 -> 1 | I4: =Keys!$C$2 -> 1 | J4: =Keys!$C$2 -> 1 | ... AA4: =Keys!$C$2 -> 1
A5: nuclear es | B5: =IF(IFERROR(INDEX(Adjustments!$G$2:$G$139,MATCH(About!$B$2&"|"&LOWER(LEFT($A5,LEN($A5)-3)),Adjustments!$I$2:$I$139,0)),"")<>"",IFERROR(INDEX(Adjustments!$G$2:$G$139,MATCH(About!$B$2&"|"&LOWER(LEFT($A5,LEN($A5)-3)),Adjustments!$I$2:$I$139,0)),""),IFERROR(IF(INDEX(CF_summary!$H$2:$H$769,MATCH(About!$B$2&"|"&LOWER(LEFT($A5,LEN($A5)-3)),CF_summary!$N$2:$N$769,0))="",Keys!$C$2,INDEX(CF_summary!$H$2:$H$769,MATCH(About!$B$2&"|"&LOWER(LEFT($A5,LEN($A5)-3)),CF_summary!$N$2:$N$769,0))*IFERROR(INDEX(Adjustments!$F$2:$F$139,MATCH(About!$B$2&"|"&LOWER(LEFT($A5,LEN($A5)-3)),Adjustments!$I$2:$I$139,0)),1)),Keys!$C$2)) -> 1 | C5: =Keys!$C$2 -> 1 | D5: =Keys!$C$2 -> 1 | E5: =Keys!$C$2 -> 1 | F5: =Keys!$C$2 -> 1 | G5: =Keys!$C$2 -> 1 | H5: =Keys!$C$2 -> 1 | I5: =Keys!$C$2 -> 1 | J5: =Keys!$C$2 -> 1 | ... AA5: =Keys!$C$2 -> 1
A6: hydro es | B6: =IF(IFERROR(INDEX(Adjustments!$G$2:$G$139,MATCH(About!$B$2&"|"&LOWER(LEFT($A6,LEN($A6)-3)),Adjustments!$I$2:$I$139,0)),"")<>"",IFERROR(INDEX(Adjustments!$G$2:$G$139,MATCH(About!$B$2&"|"&LOWER(LEFT($A6,LEN($A6)-3)),Adjustments!$I$2:$I$139,0)),""),IFERROR(IF(INDEX(CF_summary!$H$2:$H$769,MATCH(About!$B$2&"|"&LOWER(LEFT($A6,LEN($A6)-3)),CF_summary!$N$2:$N$769,0))="",Keys!$C$2,INDEX(CF_summary!$H$2:$H$769,MATCH(About!$B$2&"|"&LOWER(LEFT($A6,LEN($A6)-3)),CF_summary!$N$2:$N$769,0))*IFERROR(INDEX(Adjustments!$F$2:$F$139,MATCH(About!$B$2&"|"&LOWER(LEFT($A6,LEN($A6)-3)),Adjustments!$I$2:$I$139,0)),1)),Keys!$C$2)) -> 1.0546249 | C6: =Keys!$C$2 -> 1 | D6: =Keys!$C$2 -> 1 | E6: =Keys!$C$2 -> 1 | F6: =Keys!$C$2 -> 1 | G6: =Keys!$C$2 -> 1 | H6: =Keys!$C$2 -> 1 | I6: =Keys!$C$2 -> 1 | J6: =Keys!$C$2 -> 1 | ... AA6: =Keys!$C$2 -> 1
A7: onshore wind es | B7: =IF(IFERROR(INDEX(Adjustments!$G$2:$G$139,MATCH(About!$B$2&"|"&LOWER(LEFT($A7,LEN($A7)-3)),Adjustments!$I$2:$I$139,0)),"")<>"",IFERROR(INDEX(Adjustments!$G$2:$G$139,MATCH(About!$B$2&"|"&LOWER(LEFT($A7,LEN($A7)-3)),Adjustments!$I$2:$I$139,0)),""),IFERROR(IF(INDEX(CF_summary!$H$2:$H$769,MATCH(About!$B$2&"|"&LOWER(LEFT($A7,LEN($A7)-3)),CF_summary!$N$2:$N$769,0))="",Keys!$C$2,INDEX(CF_summary!$H$2:$H$769,MATCH(About!$B$2&"|"&LOWER(LEFT($A7,LEN($A7)-3)),CF_summary!$N$2:$N$769,0))*IFERROR(INDEX(Adjustments!$F$2:$F$139,MATCH(About!$B$2&"|"&LOWER(LEFT($A7,LEN($A7)-3)),Adjustments!$I$2:$I$139,0)),1)),Keys!$C$2)) -> 1.073084 | C7: =Keys!$C$2 -> 1 | D7: =Keys!$C$2 -> 1 | E7: =Keys!$C$2 -> 1 | F7: =Keys!$C$2 -> 1 | G7: =Keys!$C$2 -> 1 | H7: =Keys!$C$2 -> 1 | I7: =Keys!$C$2 -> 1 | J7: =Keys!$C$2 -> 1 | ... AA7: =Keys!$C$2 -> 1
A8: solar PV es | B8: =IF(IFERROR(INDEX(Adjustments!$G$2:$G$139,MATCH(About!$B$2&"|"&LOWER(LEFT($A8,LEN($A8)-3)),Adjustments!$I$2:$I$139,0)),"")<>"",IFERROR(INDEX(Adjustments!$G$2:$G$139,MATCH(About!$B$2&"|"&LOWER(LEFT($A8,LEN($A8)-3)),Adjustments!$I$2:$I$139,0)),""),IFERROR(IF(INDEX(CF_summary!$H$2:$H$769,MATCH(About!$B$2&"|"&LOWER(LEFT($A8,LEN($A8)-3)),CF_summary!$N$2:$N$769,0))="",Keys!$C$2,INDEX(CF_summary!$H$2:$H$769,MATCH(About!$B$2&"|"&LOWER(LEFT($A8,LEN($A8)-3)),CF_summary!$N$2:$N$769,0))*IFERROR(INDEX(Adjustments!$F$2:$F$139,MATCH(About!$B$2&"|"&LOWER(LEFT($A8,LEN($A8)-3)),Adjustments!$I$2:$I$139,0)),1)),Keys!$C$2)) -> 1.356136 | C8: =Keys!$C$2 -> 1 | D8: =Keys!$C$2 -> 1 | E8: =Keys!$C$2 -> 1 | F8: =Keys!$C$2 -> 1 | G8: =Keys!$C$2 -> 1 | H8: =Keys!$C$2 -> 1 | I8: =Keys!$C$2 -> 1 | J8: =Keys!$C$2 -> 1 | ... AA8: =Keys!$C$2 -> 1
A9: solar thermal es | B9: =IF(IFERROR(INDEX(Adjustments!$G$2:$G$139,MATCH(About!$B$2&"|"&LOWER(LEFT($A9,LEN($A9)-3)),Adjustments!$I$2:$I$139,0)),"")<>"",IFERROR(INDEX(Adjustments!$G$2:$G$139,MATCH(About!$B$2&"|"&LOWER(LEFT($A9,LEN($A9)-3)),Adjustments!$I$2:$I$139,0)),""),IFERROR(IF(INDEX(CF_summary!$H$2:$H$769,MATCH(About!$B$2&"|"&LOWER(LEFT($A9,LEN($A9)-3)),CF_summary!$N$2:$N$769,0))="",Keys!$C$2,INDEX(CF_summary!$H$2:$H$769,MATCH(About!$B$2&"|"&LOWER(LEFT($A9,LEN($A9)-3)),CF_summary!$N$2:$N$769,0))*IFERROR(INDEX(Adjustments!$F$2:$F$139,MATCH(About!$B$2&"|"&LOWER(LEFT($A9,LEN($A9)-3)),Adjustments!$I$2:$I$139,0)),1)),Keys!$C$2)) -> 1 | C9: =Keys!$C$2 -> 1 | D9: =Keys!$C$2 -> 1 | E9: =Keys!$C$2 -> 1 | F9: =Keys!$C$2 -> 1 | G9: =Keys!$C$2 -> 1 | H9: =Keys!$C$2 -> 1 | I9: =Keys!$C$2 -> 1 | J9: =Keys!$C$2 -> 1 | ... AA9: =Keys!$C$2 -> 1
A10: biomass es | B10: =IF(IFERROR(INDEX(Adjustments!$G$2:$G$139,MATCH(About!$B$2&"|"&LOWER(LEFT($A10,LEN($A10)-3)),Adjustments!$I$2:$I$139,0)),"")<>"",IFERROR(INDEX(Adjustments!$G$2:$G$139,MATCH(About!$B$2&"|"&LOWER(LEFT($A10,LEN($A10)-3)),Adjustments!$I$2:$I$139,0)),""),IFERROR(IF(INDEX(CF_summary!$H$2:$H$769,MATCH(About!$B$2&"|"&LOWER(LEFT($A10,LEN($A10)-3)),CF_summary!$N$2:$N$769,0))="",Keys!$C$2,INDEX(CF_summary!$H$2:$H$769,MATCH(About!$B$2&"|"&LOWER(LEFT($A10,LEN($A10)-3)),CF_summary!$N$2:$N$769,0))*IFERROR(INDEX(Adjustments!$F$2:$F$139,MATCH(About!$B$2&"|"&LOWER(LEFT($A10,LEN($A10)-3)),Adjustments!$I$2:$I$139,0)),1)),Keys!$C$2)) -> 1.9391327 | C10: =Keys!$C$2 -> 1 | D10: =Keys!$C$2 -> 1 | E10: =Keys!$C$2 -> 1 | F10: =Keys!$C$2 -> 1 | G10: =Keys!$C$2 -> 1 | H10: =Keys!$C$2 -> 1 | I10: =Keys!$C$2 -> 1 | J10: =Keys!$C$2 -> 1 | ... AA10: =Keys!$C$2 -> 1
A11: geothermal es | B11: =IF(IFERROR(INDEX(Adjustments!$G$2:$G$139,MATCH(About!$B$2&"|"&LOWER(LEFT($A11,LEN($A11)-3)),Adjustments!$I$2:$I$139,0)),"")<>"",IFERROR(INDEX(Adjustments!$G$2:$G$139,MATCH(About!$B$2&"|"&LOWER(LEFT($A11,LEN($A11)-3)),Adjustments!$I$2:$I$139,0)),""),IFERROR(IF(INDEX(CF_summary!$H$2:$H$769,MATCH(About!$B$2&"|"&LOWER(LEFT($A11,LEN($A11)-3)),CF_summary!$N$2:$N$769,0))="",Keys!$C$2,INDEX(CF_summary!$H$2:$H$769,MATCH(About!$B$2&"|"&LOWER(LEFT($A11,LEN($A11)-3)),CF_summary!$N$2:$N$769,0))*IFERROR(INDEX(Adjustments!$F$2:$F$139,MATCH(About!$B$2&"|"&LOWER(LEFT($A11,LEN($A11)-3)),Adjustments!$I$2:$I$139,0)),1)),Keys!$C$2)) -> 1 | C11: =Keys!$C$2 -> 1 | D11: =Keys!$C$2 -> 1 | E11: =Keys!$C$2 -> 1 | F11: =Keys!$C$2 -> 1 | G11: =Keys!$C$2 -> 1 | H11: =Keys!$C$2 -> 1 | I11: =Keys!$C$2 -> 1 | J11: =Keys!$C$2 -> 1 | ... AA11: =Keys!$C$2 -> 1
A12: petroleum es | B12: =IF(IFERROR(INDEX(Adjustments!$G$2:$G$139,MATCH(About!$B$2&"|"&LOWER(LEFT($A12,LEN($A12)-3)),Adjustments!$I$2:$I$139,0)),"")<>"",IFERROR(INDEX(Adjustments!$G$2:$G$139,MATCH(About!$B$2&"|"&LOWER(LEFT($A12,LEN($A12)-3)),Adjustments!$I$2:$I$139,0)),""),IFERROR(IF(INDEX(CF_summary!$H$2:$H$769,MATCH(About!$B$2&"|"&LOWER(LEFT($A12,LEN($A12)-3)),CF_summary!$N$2:$N$769,0))="",Keys!$C$2,INDEX(CF_summary!$H$2:$H$769,MATCH(About!$B$2&"|"&LOWER(LEFT($A12,LEN($A12)-3)),CF_summary!$N$2:$N$769,0))*IFERROR(INDEX(Adjustments!$F$2:$F$139,MATCH(About!$B$2&"|"&LOWER(LEFT($A12,LEN($A12)-3)),Adjustments!$I$2:$I$139,0)),1)),Keys!$C$2)) -> 1 | C12: =Keys!$C$2 -> 1 | D12: =Keys!$C$2 -> 1 | E12: =Keys!$C$2 -> 1 | F12: =Keys!$C$2 -> 1 | G12: =Keys!$C$2 -> 1 | H12: =Keys!$C$2 -> 1 | I12: =Keys!$C$2 -> 1 | J12: =Keys!$C$2 -> 1 | ... AA12: =Keys!$C$2 -> 1
A13: natural gas peaker es | B13: =IF(IFERROR(INDEX(Adjustments!$G$2:$G$139,MATCH(About!$B$2&"|"&LOWER(LEFT($A13,LEN($A13)-3)),Adjustments!$I$2:$I$139,0)),"")<>"",IFERROR(INDEX(Adjustments!$G$2:$G$139,MATCH(About!$B$2&"|"&LOWER(LEFT($A13,LEN($A13)-3)),Adjustments!$I$2:$I$139,0)),""),IFERROR(IF(INDEX(CF_summary!$H$2:$H$769,MATCH(About!$B$2&"|"&LOWER(LEFT($A13,LEN($A13)-3)),CF_summary!$N$2:$N$769,0))="",Keys!$C$2,INDEX(CF_summary!$H$2:$H$769,MATCH(About!$B$2&"|"&LOWER(LEFT($A13,LEN($A13)-3)),CF_summary!$N$2:$N$769,0))*IFERROR(INDEX(Adjustments!$F$2:$F$139,MATCH(About!$B$2&"|"&LOWER(LEFT($A13,LEN($A13)-3)),Adjustments!$I$2:$I$139,0)),1)),Keys!$C$2)) -> 0.96273599 | C13: =Keys!$C$2 -> 1 | D13: =Keys!$C$2 -> 1 | E13: =Keys!$C$2 -> 1 | F13: =Keys!$C$2 -> 1 | G13: =Keys!$C$2 -> 1 | H13: =Keys!$C$2 -> 1 | I13: =Keys!$C$2 -> 1 | J13: =Keys!$C$2 -> 1 | ... AA13: =Keys!$C$2 -> 1
... A25: hydrogen combined cycle es | B25: =IF(IFERROR(INDEX(Adjustments!$G$2:$G$139,MATCH(About!$B$2&"|"&LOWER(LEFT($A25,LEN($A25)-3)),Adjustments!$I$2:$I$139,0)),"")<>"",IFERROR(INDEX(Adjustments!$G$2:$G$139,MATCH(About!$B$2&"|"&LOWER(LEFT($A25,LEN($A25)-3)),Adjustments!$I$2:$I$139,0)),""),IFERROR(IF(INDEX(CF_summary!$H$2:$H$769,MATCH(About!$B$2&"|"&LOWER(LEFT($A25,LEN($A25)-3)),CF_summary!$N$2:$N$769,0))="",Keys!$C$2,INDEX(CF_summary!$H$2:$H$769,MATCH(About!$B$2&"|"&LOWER(LEFT($A25,LEN($A25)-3)),CF_summary!$N$2:$N$769,0))*IFERROR(INDEX(Adjustments!$F$2:$F$139,MATCH(About!$B$2&"|"&LOWER(LEFT($A25,LEN($A25)-3)),Adjustments!$I$2:$I$139,0)),1)),Keys!$C$2)) -> 1 | C25: =Keys!$C$2 -> 1 | D25: =Keys!$C$2 -> 1 | E25: =Keys!$C$2 -> 1 | F25: =Keys!$C$2 -> 1 | G25: =Keys!$C$2 -> 1 | H25: =Keys!$C$2 -> 1 | I25: =Keys!$C$2 -> 1 | J25: =Keys!$C$2 -> 1 | ... AA25: =Keys!$C$2 -> 1
A26: -> electricity source within all fuels | B26: 1 | C26: 1 | D26: 1 | E26: 1 | F26: 1 | G26: 1 | H26: 1 | I26: 1 | J26: 1 | K26: 1 | L26: 1 | M26: 1 | N26: 1 | O26: 1 | P26: 1 | Q26: 1 | R26: 1 | S26: 1 | T26: 1 | U26: 1 | V26: 1 | W26: 1 | X26: 1 | Y26: 1 | Z26: 1 | AA26: 1
